[Fri Dec 02 16:03:37.290222 2016] [wsgi:error] [pid 12:tid 140612633900800] [remote 128.211.233.228:6124] mod_wsgi (pid=12): Exception occurred processing WSGI script '/srv/www/app/apache/apache.wsgi'.
[Fri Dec 02 16:03:37.295199 2016] [wsgi:error] [pid 12:tid 140612633900800] [remote 128.211.233.228:6124] Traceback (most recent call last):
[Fri Dec 02 16:03:37.296042 2016] [wsgi:error] [pid 12:tid 140612633900800] [remote 128.211.233.228:6124]   File "/usr/local/lib/python2.7/dist-packages/flask/app.py", line 2000, in __call__
[Fri Dec 02 16:03:37.298533 2016] [wsgi:error] [pid 12:tid 140612633900800] [remote 128.211.233.228:6124]     return self.wsgi_app(environ, start_response)
[Fri Dec 02 16:03:37.298623 2016] [wsgi:error] [pid 12:tid 140612633900800] [remote 128.211.233.228:6124]   File "/usr/local/lib/python2.7/dist-packages/flask/app.py", line 1991, in wsgi_app
[Fri Dec 02 16:03:37.298689 2016] [wsgi:error] [pid 12:tid 140612633900800] [remote 128.211.233.228:6124]     response = self.make_response(self.handle_exception(e))
[Fri Dec 02 16:03:37.298723 2016] [wsgi:error] [pid 12:tid 140612633900800] [remote 128.211.233.228:6124]   File "/usr/local/lib/python2.7/dist-packages/flask_restful/__init__.py", line 271, in error_router
[Fri Dec 02 16:03:37.299437 2016] [wsgi:error] [pid 12:tid 140612633900800] [remote 128.211.233.228:6124]     return original_handler(e)
[Fri Dec 02 16:03:37.299487 2016] [wsgi:error] [pid 12:tid 140612633900800] [remote 128.211.233.228:6124]   File "/usr/local/lib/python2.7/dist-packages/flask_cors/extension.py", line 161, in wrapped_function
[Fri Dec 02 16:03:37.300281 2016] [wsgi:error] [pid 12:tid 140612633900800] [remote 128.211.233.228:6124]     return cors_after_request(app.make_response(f(*args, **kwargs)))
[Fri Dec 02 16:03:37.300330 2016] [wsgi:error] [pid 12:tid 140612633900800] [remote 128.211.233.228:6124]   File "/usr/local/lib/python2.7/dist-packages/flask/app.py", line 1567, in handle_exception
[Fri Dec 02 16:03:37.300378 2016] [wsgi:error] [pid 12:tid 140612633900800] [remote 128.211.233.228:6124]     reraise(exc_type, exc_value, tb)
[Fri Dec 02 16:03:37.300411 2016] [wsgi:error] [pid 12:tid 140612633900800] [remote 128.211.233.228:6124]   File "/usr/local/lib/python2.7/dist-packages/flask_restful/__init__.py", line 268, in error_router
[Fri Dec 02 16:03:37.300450 2016] [wsgi:error] [pid 12:tid 140612633900800] [remote 128.211.233.228:6124]     return self.handle_error(e)
[Fri Dec 02 16:03:37.300481 2016] [wsgi:error] [pid 12:tid 140612633900800] [remote 128.211.233.228:6124]   File "/usr/local/lib/python2.7/dist-packages/flask/app.py", line 1988, in wsgi_app
[Fri Dec 02 16:03:37.300518 2016] [wsgi:error] [pid 12:tid 140612633900800] [remote 128.211.233.228:6124]     response = self.full_dispatch_request()
[Fri Dec 02 16:03:37.300548 2016] [wsgi:error] [pid 12:tid 140612633900800] [remote 128.211.233.228:6124]   File "/usr/local/lib/python2.7/dist-packages/flask/app.py", line 1641, in full_dispatch_request
[Fri Dec 02 16:03:37.300585 2016] [wsgi:error] [pid 12:tid 140612633900800] [remote 128.211.233.228:6124]     rv = self.handle_user_exception(e)
[Fri Dec 02 16:03:37.300614 2016] [wsgi:error] [pid 12:tid 140612633900800] [remote 128.211.233.228:6124]   File "/usr/local/lib/python2.7/dist-packages/flask_restful/__init__.py", line 271, in error_router
[Fri Dec 02 16:03:37.300651 2016] [wsgi:error] [pid 12:tid 140612633900800] [remote 128.211.233.228:6124]     return original_handler(e)
[Fri Dec 02 16:03:37.300680 2016] [wsgi:error] [pid 12:tid 140612633900800] [remote 128.211.233.228:6124]   File "/usr/local/lib/python2.7/dist-packages/flask_cors/extension.py", line 161, in wrapped_function
[Fri Dec 02 16:03:37.300716 2016] [wsgi:error] [pid 12:tid 140612633900800] [remote 128.211.233.228:6124]     return cors_after_request(app.make_response(f(*args, **kwargs)))
[Fri Dec 02 16:03:37.300746 2016] [wsgi:error] [pid 12:tid 140612633900800] [remote 128.211.233.228:6124]   File "/usr/local/lib/python2.7/dist-packages/flask/app.py", line 1544, in handle_user_exception
[Fri Dec 02 16:03:37.300782 2016] [wsgi:error] [pid 12:tid 140612633900800] [remote 128.211.233.228:6124]     reraise(exc_type, exc_value, tb)
[Fri Dec 02 16:03:37.300836 2016] [wsgi:error] [pid 12:tid 140612633900800] [remote 128.211.233.228:6124]   File "/usr/local/lib/python2.7/dist-packages/flask_restful/__init__.py", line 268, in error_router
[Fri Dec 02 16:03:37.300877 2016] [wsgi:error] [pid 12:tid 140612633900800] [remote 128.211.233.228:6124]     return self.handle_error(e)
[Fri Dec 02 16:03:37.300907 2016] [wsgi:error] [pid 12:tid 140612633900800] [remote 128.211.233.228:6124]   File "/usr/local/lib/python2.7/dist-packages/flask/app.py", line 1639, in full_dispatch_request
[Fri Dec 02 16:03:37.300944 2016] [wsgi:error] [pid 12:tid 140612633900800] [remote 128.211.233.228:6124]     rv = self.dispatch_request()
[Fri Dec 02 16:03:37.300974 2016] [wsgi:error] [pid 12:tid 140612633900800] [remote 128.211.233.228:6124]   File "/usr/local/lib/python2.7/dist-packages/flask/app.py", line 1625, in dispatch_request
[Fri Dec 02 16:03:37.301010 2016] [wsgi:error] [pid 12:tid 140612633900800] [remote 128.211.233.228:6124]     return self.view_functions[rule.endpoint](**req.view_args)
[Fri Dec 02 16:03:37.301040 2016] [wsgi:error] [pid 12:tid 140612633900800] [remote 128.211.233.228:6124]   File "/usr/local/lib/python2.7/dist-packages/flask_restful/__init__.py", line 477, in wrapper
[Fri Dec 02 16:03:37.301077 2016] [wsgi:error] [pid 12:tid 140612633900800] [remote 128.211.233.228:6124]     resp = resource(*args, **kwargs)
[Fri Dec 02 16:03:37.301108 2016] [wsgi:error] [pid 12:tid 140612633900800] [remote 128.211.233.228:6124]   File "/usr/local/lib/python2.7/dist-packages/flask/views.py", line 84, in view
[Fri Dec 02 16:03:37.301294 2016] [wsgi:error] [pid 12:tid 140612633900800] [remote 128.211.233.228:6124]     return self.dispatch_request(*args, **kwargs)
[Fri Dec 02 16:03:37.301332 2016] [wsgi:error] [pid 12:tid 140612633900800] [remote 128.211.233.228:6124]   File "/usr/local/lib/python2.7/dist-packages/flask_restful/__init__.py", line 587, in dispatch_request
[Fri Dec 02 16:03:37.301373 2016] [wsgi:error] [pid 12:tid 140612633900800] [remote 128.211.233.228:6124]     resp = meth(*args, **kwargs)
[Fri Dec 02 16:03:37.301404 2016] [wsgi:error] [pid 12:tid 140612633900800] [remote 128.211.233.228:6124]   File "/srv/www/app/main.py", line 213, in put
[Fri Dec 02 16:03:37.301972 2016] [wsgi:error] [pid 12:tid 140612633900800] [remote 128.211.233.228:6124]     batch = Batch()
[Fri Dec 02 16:03:37.302083 2016] [wsgi:error] [pid 12:tid 140612633900800] [remote 128.211.233.228:6124]   File "/srv/www/app/main.py", line 40, in __init__
[Fri Dec 02 16:03:37.302181 2016] [wsgi:error] [pid 12:tid 140612633900800] [remote 128.211.233.228:6124]     self.batches = loadJsonFileToData('batch', "/static/data/")
[Fri Dec 02 16:03:37.302245 2016] [wsgi:error] [pid 12:tid 140612633900800] [remote 128.211.233.228:6124]   File "/srv/www/app/main.py", line 32, in loadJsonFileToData
[Fri Dec 02 16:03:37.302320 2016] [wsgi:error] [pid 12:tid 140612633900800] [remote 128.211.233.228:6124]     return json.load(jsonData)
[Fri Dec 02 16:03:37.302378 2016] [wsgi:error] [pid 12:tid 140612633900800] [remote 128.211.233.228:6124]   File "/usr/lib/python2.7/json/__init__.py", line 291, in load
[Fri Dec 02 16:03:37.303029 2016] [wsgi:error] [pid 12:tid 140612633900800] [remote 128.211.233.228:6124]     **kw)
[Fri Dec 02 16:03:37.303110 2016] [wsgi:error] [pid 12:tid 140612633900800] [remote 128.211.233.228:6124]   File "/usr/lib/python2.7/json/__init__.py", line 339, in loads
[Fri Dec 02 16:03:37.303194 2016] [wsgi:error] [pid 12:tid 140612633900800] [remote 128.211.233.228:6124]     return _default_decoder.decode(s)
[Fri Dec 02 16:03:37.303256 2016] [wsgi:error] [pid 12:tid 140612633900800] [remote 128.211.233.228:6124]   File "/usr/lib/python2.7/json/decoder.py", line 364, in decode
[Fri Dec 02 16:03:37.303801 2016] [wsgi:error] [pid 12:tid 140612633900800] [remote 128.211.233.228:6124]     obj, end = self.raw_decode(s, idx=_w(s, 0).end())
[Fri Dec 02 16:03:37.303880 2016] [wsgi:error] [pid 12:tid 140612633900800] [remote 128.211.233.228:6124]   File "/usr/lib/python2.7/json/decoder.py", line 382, in raw_decode
[Fri Dec 02 16:03:37.304001 2016] [wsgi:error] [pid 12:tid 140612633900800] [remote 128.211.233.228:6124]     raise ValueError("No JSON object could be decoded")
[Fri Dec 02 16:03:37.304138 2016] [wsgi:error] [pid 12:tid 140612633900800] [remote 128.211.233.228:6124] ValueError: No JSON object could be decoded
[Fri Dec 02 16:03:37.368792 2016] [wsgi:error] [pid 12:tid 140612625491712] [remote 128.211.233.228:45561] mod_wsgi (pid=12): Exception occurred processing WSGI script '/srv/www/app/apache/apache.wsgi'.
[Fri Dec 02 16:03:37.372058 2016] [wsgi:error] [pid 12:tid 140612633900800] [remote 128.211.233.228:45561] mod_wsgi (pid=12): Exception occurred processing WSGI script '/srv/www/app/apache/apache.wsgi'.
[Fri Dec 02 16:03:37.372176 2016] [wsgi:error] [pid 12:tid 140612625491712] [remote 128.211.233.228:45561] Traceback (most recent call last):
[Fri Dec 02 16:03:37.372279 2016] [wsgi:error] [pid 12:tid 140612625491712] [remote 128.211.233.228:45561]   File "/usr/local/lib/python2.7/dist-packages/flask/app.py", line 2000, in __call__
[Fri Dec 02 16:03:37.372719 2016] [wsgi:error] [pid 12:tid 140612625491712] [remote 128.211.233.228:45561]     return self.wsgi_app(environ, start_response)
[Fri Dec 02 16:03:37.372812 2016] [wsgi:error] [pid 12:tid 140612633900800] [remote 128.211.233.228:45561] Traceback (most recent call last):
[Fri Dec 02 16:03:37.372888 2016] [wsgi:error] [pid 12:tid 140612625491712] [remote 128.211.233.228:45561]   File "/usr/local/lib/python2.7/dist-packages/flask/app.py", line 1991, in wsgi_app
[Fri Dec 02 16:03:37.372960 2016] [wsgi:error] [pid 12:tid 140612633900800] [remote 128.211.233.228:45561]   File "/usr/local/lib/python2.7/dist-packages/flask/app.py", line 2000, in __call__
[Fri Dec 02 16:03:37.373058 2016] [wsgi:error] [pid 12:tid 140612625491712] [remote 128.211.233.228:45561]     response = self.make_response(self.handle_exception(e))
[Fri Dec 02 16:03:37.373150 2016] [wsgi:error] [pid 12:tid 140612633900800] [remote 128.211.233.228:45561]     return self.wsgi_app(environ, start_response)
[Fri Dec 02 16:03:37.373221 2016] [wsgi:error] [pid 12:tid 140612625491712] [remote 128.211.233.228:45561]   File "/usr/local/lib/python2.7/dist-packages/flask_restful/__init__.py", line 271, in error_router
[Fri Dec 02 16:03:37.373283 2016] [wsgi:error] [pid 12:tid 140612633900800] [remote 128.211.233.228:45561]   File "/usr/local/lib/python2.7/dist-packages/flask/app.py", line 1991, in wsgi_app
[Fri Dec 02 16:03:37.373371 2016] [wsgi:error] [pid 12:tid 140612625491712] [remote 128.211.233.228:45561]     return original_handler(e)
[Fri Dec 02 16:03:37.373459 2016] [wsgi:error] [pid 12:tid 140612633900800] [remote 128.211.233.228:45561]     response = self.make_response(self.handle_exception(e))
[Fri Dec 02 16:03:37.373528 2016] [wsgi:error] [pid 12:tid 140612625491712] [remote 128.211.233.228:45561]   File "/usr/local/lib/python2.7/dist-packages/flask_cors/extension.py", line 161, in wrapped_function
[Fri Dec 02 16:03:37.373589 2016] [wsgi:error] [pid 12:tid 140612633900800] [remote 128.211.233.228:45561]   File "/usr/local/lib/python2.7/dist-packages/flask_restful/__init__.py", line 271, in error_router
[Fri Dec 02 16:03:37.373673 2016] [wsgi:error] [pid 12:tid 140612633900800] [remote 128.211.233.228:45561]     return original_handler(e)
[Fri Dec 02 16:03:37.373764 2016] [wsgi:error] [pid 12:tid 140612625491712] [remote 128.211.233.228:45561]     return cors_after_request(app.make_response(f(*args, **kwargs)))
[Fri Dec 02 16:03:37.373831 2016] [wsgi:error] [pid 12:tid 140612633900800] [remote 128.211.233.228:45561]   File "/usr/local/lib/python2.7/dist-packages/flask_cors/extension.py", line 161, in wrapped_function
[Fri Dec 02 16:03:37.373892 2016] [wsgi:error] [pid 12:tid 140612625491712] [remote 128.211.233.228:45561]   File "/usr/local/lib/python2.7/dist-packages/flask/app.py", line 1567, in handle_exception
[Fri Dec 02 16:03:37.373975 2016] [wsgi:error] [pid 12:tid 140612633900800] [remote 128.211.233.228:45561]     return cors_after_request(app.make_response(f(*args, **kwargs)))
[Fri Dec 02 16:03:37.374086 2016] [wsgi:error] [pid 12:tid 140612625491712] [remote 128.211.233.228:45561]     reraise(exc_type, exc_value, tb)
[Fri Dec 02 16:03:37.374157 2016] [wsgi:error] [pid 12:tid 140612633900800] [remote 128.211.233.228:45561]   File "/usr/local/lib/python2.7/dist-packages/flask/app.py", line 1567, in handle_exception
[Fri Dec 02 16:03:37.374221 2016] [wsgi:error] [pid 12:tid 140612625491712] [remote 128.211.233.228:45561]   File "/usr/local/lib/python2.7/dist-packages/flask_restful/__init__.py", line 268, in error_router
[Fri Dec 02 16:03:37.374304 2016] [wsgi:error] [pid 12:tid 140612633900800] [remote 128.211.233.228:45561]     reraise(exc_type, exc_value, tb)
[Fri Dec 02 16:03:37.374391 2016] [wsgi:error] [pid 12:tid 140612625491712] [remote 128.211.233.228:45561]     return self.handle_error(e)
[Fri Dec 02 16:03:37.374483 2016] [wsgi:error] [pid 12:tid 140612633900800] [remote 128.211.233.228:45561]   File "/usr/local/lib/python2.7/dist-packages/flask_restful/__init__.py", line 268, in error_router
[Fri Dec 02 16:03:37.374549 2016] [wsgi:error] [pid 12:tid 140612625491712] [remote 128.211.233.228:45561]   File "/usr/local/lib/python2.7/dist-packages/flask/app.py", line 1988, in wsgi_app
[Fri Dec 02 16:03:37.374635 2016] [wsgi:error] [pid 12:tid 140612625491712] [remote 128.211.233.228:45561]     response = self.full_dispatch_request()
[Fri Dec 02 16:03:37.374722 2016] [wsgi:error] [pid 12:tid 140612633900800] [remote 128.211.233.228:45561]     return self.handle_error(e)
[Fri Dec 02 16:03:37.374790 2016] [wsgi:error] [pid 12:tid 140612625491712] [remote 128.211.233.228:45561]   File "/usr/local/lib/python2.7/dist-packages/flask/app.py", line 1641, in full_dispatch_request
[Fri Dec 02 16:03:37.374923 2016] [wsgi:error] [pid 12:tid 140612633900800] [remote 128.211.233.228:45561]   File "/usr/local/lib/python2.7/dist-packages/flask/app.py", line 1988, in wsgi_app
[Fri Dec 02 16:03:37.375026 2016] [wsgi:error] [pid 12:tid 140612625491712] [remote 128.211.233.228:45561]     rv = self.handle_user_exception(e)
[Fri Dec 02 16:03:37.375117 2016] [wsgi:error] [pid 12:tid 140612633900800] [remote 128.211.233.228:45561]     response = self.full_dispatch_request()
[Fri Dec 02 16:03:37.375186 2016] [wsgi:error] [pid 12:tid 140612625491712] [remote 128.211.233.228:45561]   File "/usr/local/lib/python2.7/dist-packages/flask_restful/__init__.py", line 271, in error_router
[Fri Dec 02 16:03:37.375248 2016] [wsgi:error] [pid 12:tid 140612633900800] [remote 128.211.233.228:45561]   File "/usr/local/lib/python2.7/dist-packages/flask/app.py", line 1641, in full_dispatch_request
[Fri Dec 02 16:03:37.375333 2016] [wsgi:error] [pid 12:tid 140612625491712] [remote 128.211.233.228:45561]     return original_handler(e)
[Fri Dec 02 16:03:37.375418 2016] [wsgi:error] [pid 12:tid 140612633900800] [remote 128.211.233.228:45561]     rv = self.handle_user_exception(e)
[Fri Dec 02 16:03:37.375485 2016] [wsgi:error] [pid 12:tid 140612625491712] [remote 128.211.233.228:45561]   File "/usr/local/lib/python2.7/dist-packages/flask_cors/extension.py", line 161, in wrapped_function
[Fri Dec 02 16:03:37.375546 2016] [wsgi:error] [pid 12:tid 140612633900800] [remote 128.211.233.228:45561]   File "/usr/local/lib/python2.7/dist-packages/flask_restful/__init__.py", line 271, in error_router
[Fri Dec 02 16:03:37.375630 2016] [wsgi:error] [pid 12:tid 140612625491712] [remote 128.211.233.228:45561]     return cors_after_request(app.make_response(f(*args, **kwargs)))
[Fri Dec 02 16:03:37.375717 2016] [wsgi:error] [pid 12:tid 140612633900800] [remote 128.211.233.228:45561]     return original_handler(e)
[Fri Dec 02 16:03:37.377532 2016] [wsgi:error] [pid 12:tid 140612625491712] [remote 128.211.233.228:45561]   File "/usr/local/lib/python2.7/dist-packages/flask/app.py", line 1544, in handle_user_exception
[Fri Dec 02 16:03:37.377619 2016] [wsgi:error] [pid 12:tid 140612633900800] [remote 128.211.233.228:45561]   File "/usr/local/lib/python2.7/dist-packages/flask_cors/extension.py", line 161, in wrapped_function
[Fri Dec 02 16:03:37.377761 2016] [wsgi:error] [pid 12:tid 140612633900800] [remote 128.211.233.228:45561]     return cors_after_request(app.make_response(f(*args, **kwargs)))
[Fri Dec 02 16:03:37.377860 2016] [wsgi:error] [pid 12:tid 140612625491712] [remote 128.211.233.228:45561]     reraise(exc_type, exc_value, tb)
[Fri Dec 02 16:03:37.377929 2016] [wsgi:error] [pid 12:tid 140612625491712] [remote 128.211.233.228:45561]   File "/usr/local/lib/python2.7/dist-packages/flask_restful/__init__.py", line 268, in error_router
[Fri Dec 02 16:03:37.377990 2016] [wsgi:error] [pid 12:tid 140612633900800] [remote 128.211.233.228:45561]   File "/usr/local/lib/python2.7/dist-packages/flask/app.py", line 1544, in handle_user_exception
[Fri Dec 02 16:03:37.378076 2016] [wsgi:error] [pid 12:tid 140612625491712] [remote 128.211.233.228:45561]     return self.handle_error(e)
[Fri Dec 02 16:03:37.378163 2016] [wsgi:error] [pid 12:tid 140612633900800] [remote 128.211.233.228:45561]     reraise(exc_type, exc_value, tb)
[Fri Dec 02 16:03:37.378232 2016] [wsgi:error] [pid 12:tid 140612625491712] [remote 128.211.233.228:45561]   File "/usr/local/lib/python2.7/dist-packages/flask/app.py", line 1639, in full_dispatch_request
[Fri Dec 02 16:03:37.378294 2016] [wsgi:error] [pid 12:tid 140612633900800] [remote 128.211.233.228:45561]   File "/usr/local/lib/python2.7/dist-packages/flask_restful/__init__.py", line 268, in error_router
[Fri Dec 02 16:03:37.378378 2016] [wsgi:error] [pid 12:tid 140612625491712] [remote 128.211.233.228:45561]     rv = self.dispatch_request()
[Fri Dec 02 16:03:37.378491 2016] [wsgi:error] [pid 12:tid 140612633900800] [remote 128.211.233.228:45561]     return self.handle_error(e)
[Fri Dec 02 16:03:37.378565 2016] [wsgi:error] [pid 12:tid 140612625491712] [remote 128.211.233.228:45561]   File "/usr/local/lib/python2.7/dist-packages/flask/app.py", line 1625, in dispatch_request
[Fri Dec 02 16:03:37.378626 2016] [wsgi:error] [pid 12:tid 140612633900800] [remote 128.211.233.228:45561]   File "/usr/local/lib/python2.7/dist-packages/flask/app.py", line 1639, in full_dispatch_request
[Fri Dec 02 16:03:37.378713 2016] [wsgi:error] [pid 12:tid 140612625491712] [remote 128.211.233.228:45561]     return self.view_functions[rule.endpoint](**req.view_args)
[Fri Dec 02 16:03:37.378800 2016] [wsgi:error] [pid 12:tid 140612633900800] [remote 128.211.233.228:45561]     rv = self.dispatch_request()
[Fri Dec 02 16:03:37.378924 2016] [wsgi:error] [pid 12:tid 140612633900800] [remote 128.211.233.228:45561]   File "/usr/local/lib/python2.7/dist-packages/flask/app.py", line 1625, in dispatch_request
[Fri Dec 02 16:03:37.379003 2016] [wsgi:error] [pid 12:tid 140612625491712] [remote 128.211.233.228:45561]   File "/usr/local/lib/python2.7/dist-packages/flask_restful/__init__.py", line 477, in wrapper
[Fri Dec 02 16:03:37.379093 2016] [wsgi:error] [pid 12:tid 140612633900800] [remote 128.211.233.228:45561]     return self.view_functions[rule.endpoint](**req.view_args)
[Fri Dec 02 16:03:37.379182 2016] [wsgi:error] [pid 12:tid 140612625491712] [remote 128.211.233.228:45561]     resp = resource(*args, **kwargs)
[Fri Dec 02 16:03:37.379250 2016] [wsgi:error] [pid 12:tid 140612633900800] [remote 128.211.233.228:45561]   File "/usr/local/lib/python2.7/dist-packages/flask_restful/__init__.py", line 477, in wrapper
[Fri Dec 02 16:03:37.379312 2016] [wsgi:error] [pid 12:tid 140612625491712] [remote 128.211.233.228:45561]   File "/usr/local/lib/python2.7/dist-packages/flask/views.py", line 84, in view
[Fri Dec 02 16:03:37.379395 2016] [wsgi:error] [pid 12:tid 140612633900800] [remote 128.211.233.228:45561]     resp = resource(*args, **kwargs)
[Fri Dec 02 16:03:37.379484 2016] [wsgi:error] [pid 12:tid 140612625491712] [remote 128.211.233.228:45561]     return self.dispatch_request(*args, **kwargs)
[Fri Dec 02 16:03:37.379552 2016] [wsgi:error] [pid 12:tid 140612633900800] [remote 128.211.233.228:45561]   File "/usr/local/lib/python2.7/dist-packages/flask/views.py", line 84, in view
[Fri Dec 02 16:03:37.379651 2016] [wsgi:error] [pid 12:tid 140612625491712] [remote 128.211.233.228:45561]   File "/usr/local/lib/python2.7/dist-packages/flask_restful/__init__.py", line 587, in dispatch_request
[Fri Dec 02 16:03:37.379745 2016] [wsgi:error] [pid 12:tid 140612633900800] [remote 128.211.233.228:45561]     return self.dispatch_request(*args, **kwargs)
[Fri Dec 02 16:03:37.379834 2016] [wsgi:error] [pid 12:tid 140612625491712] [remote 128.211.233.228:45561]     resp = meth(*args, **kwargs)
[Fri Dec 02 16:03:37.379901 2016] [wsgi:error] [pid 12:tid 140612633900800] [remote 128.211.233.228:45561]   File "/usr/local/lib/python2.7/dist-packages/flask_restful/__init__.py", line 587, in dispatch_request
[Fri Dec 02 16:03:37.379963 2016] [wsgi:error] [pid 12:tid 140612625491712] [remote 128.211.233.228:45561]   File "/srv/www/app/main.py", line 213, in put
[Fri Dec 02 16:03:37.380045 2016] [wsgi:error] [pid 12:tid 140612633900800] [remote 128.211.233.228:45561]     resp = meth(*args, **kwargs)
[Fri Dec 02 16:03:37.380135 2016] [wsgi:error] [pid 12:tid 140612625491712] [remote 128.211.233.228:45561]     batch = Batch()
[Fri Dec 02 16:03:37.380202 2016] [wsgi:error] [pid 12:tid 140612633900800] [remote 128.211.233.228:45561]   File "/srv/www/app/main.py", line 136, in get
[Fri Dec 02 16:03:37.380262 2016] [wsgi:error] [pid 12:tid 140612625491712] [remote 128.211.233.228:45561]   File "/srv/www/app/main.py", line 40, in __init__
[Fri Dec 02 16:03:37.380345 2016] [wsgi:error] [pid 12:tid 140612633900800] [remote 128.211.233.228:45561]     batch = Batch()
[Fri Dec 02 16:03:37.380432 2016] [wsgi:error] [pid 12:tid 140612625491712] [remote 128.211.233.228:45561]     self.batches = loadJsonFileToData('batch', "/static/data/")
[Fri Dec 02 16:03:37.380498 2016] [wsgi:error] [pid 12:tid 140612633900800] [remote 128.211.233.228:45561]   File "/srv/www/app/main.py", line 40, in __init__
[Fri Dec 02 16:03:37.380559 2016] [wsgi:error] [pid 12:tid 140612625491712] [remote 128.211.233.228:45561]   File "/srv/www/app/main.py", line 32, in loadJsonFileToData
[Fri Dec 02 16:03:37.380640 2016] [wsgi:error] [pid 12:tid 140612633900800] [remote 128.211.233.228:45561]     self.batches = loadJsonFileToData('batch', "/static/data/")
[Fri Dec 02 16:03:37.380726 2016] [wsgi:error] [pid 12:tid 140612625491712] [remote 128.211.233.228:45561]     return json.load(jsonData)
[Fri Dec 02 16:03:37.380792 2016] [wsgi:error] [pid 12:tid 140612633900800] [remote 128.211.233.228:45561]   File "/srv/www/app/main.py", line 32, in loadJsonFileToData
[Fri Dec 02 16:03:37.380852 2016] [wsgi:error] [pid 12:tid 140612625491712] [remote 128.211.233.228:45561]   File "/usr/lib/python2.7/json/__init__.py", line 291, in load
[Fri Dec 02 16:03:37.380932 2016] [wsgi:error] [pid 12:tid 140612633900800] [remote 128.211.233.228:45561]     return json.load(jsonData)
[Fri Dec 02 16:03:37.381021 2016] [wsgi:error] [pid 12:tid 140612625491712] [remote 128.211.233.228:45561]     **kw)
[Fri Dec 02 16:03:37.381087 2016] [wsgi:error] [pid 12:tid 140612633900800] [remote 128.211.233.228:45561]   File "/usr/lib/python2.7/json/__init__.py", line 291, in load
[Fri Dec 02 16:03:37.381147 2016] [wsgi:error] [pid 12:tid 140612625491712] [remote 128.211.233.228:45561]   File "/usr/lib/python2.7/json/__init__.py", line 339, in loads
[Fri Dec 02 16:03:37.381229 2016] [wsgi:error] [pid 12:tid 140612633900800] [remote 128.211.233.228:45561]     **kw)
[Fri Dec 02 16:03:37.381316 2016] [wsgi:error] [pid 12:tid 140612625491712] [remote 128.211.233.228:45561]     return _default_decoder.decode(s)
[Fri Dec 02 16:03:37.381382 2016] [wsgi:error] [pid 12:tid 140612633900800] [remote 128.211.233.228:45561]   File "/usr/lib/python2.7/json/__init__.py", line 339, in loads
[Fri Dec 02 16:03:37.381443 2016] [wsgi:error] [pid 12:tid 140612625491712] [remote 128.211.233.228:45561]   File "/usr/lib/python2.7/json/decoder.py", line 364, in decode
[Fri Dec 02 16:03:37.381525 2016] [wsgi:error] [pid 12:tid 140612633900800] [remote 128.211.233.228:45561]     return _default_decoder.decode(s)
[Fri Dec 02 16:03:37.381649 2016] [wsgi:error] [pid 12:tid 140612625491712] [remote 128.211.233.228:45561]     obj, end = self.raw_decode(s, idx=_w(s, 0).end())
[Fri Dec 02 16:03:37.381720 2016] [wsgi:error] [pid 12:tid 140612633900800] [remote 128.211.233.228:45561]   File "/usr/lib/python2.7/json/decoder.py", line 364, in decode
[Fri Dec 02 16:03:37.381782 2016] [wsgi:error] [pid 12:tid 140612625491712] [remote 128.211.233.228:45561]   File "/usr/lib/python2.7/json/decoder.py", line 382, in raw_decode
[Fri Dec 02 16:03:37.381865 2016] [wsgi:error] [pid 12:tid 140612633900800] [remote 128.211.233.228:45561]     obj, end = self.raw_decode(s, idx=_w(s, 0).end())
[Fri Dec 02 16:03:37.381951 2016] [wsgi:error] [pid 12:tid 140612625491712] [remote 128.211.233.228:45561]     raise ValueError("No JSON object could be decoded")
[Fri Dec 02 16:03:37.382018 2016] [wsgi:error] [pid 12:tid 140612633900800] [remote 128.211.233.228:45561]   File "/usr/lib/python2.7/json/decoder.py", line 382, in raw_decode
[Fri Dec 02 16:03:37.382095 2016] [wsgi:error] [pid 12:tid 140612625491712] [remote 128.211.233.228:45561] ValueError: No JSON object could be decoded
[Fri Dec 02 16:03:37.382184 2016] [wsgi:error] [pid 12:tid 140612633900800] [remote 128.211.233.228:45561]     raise ValueError("No JSON object could be decoded")
[Fri Dec 02 16:03:37.383005 2016] [wsgi:error] [pid 12:tid 140612633900800] [remote 128.211.233.228:45561] ValueError: No JSON object could be decoded
[Fri Dec 02 16:07:09.793188 2016] [wsgi:error] [pid 12:tid 140612617090816] [remote 128.211.233.228:6124] mod_wsgi (pid=12): Exception occurred processing WSGI script '/srv/www/app/apache/apache.wsgi'.
[Fri Dec 02 16:07:09.793430 2016] [wsgi:error] [pid 12:tid 140612617090816] [remote 128.211.233.228:6124] Traceback (most recent call last):
[Fri Dec 02 16:07:09.793472 2016] [wsgi:error] [pid 12:tid 140612617090816] [remote 128.211.233.228:6124]   File "/usr/local/lib/python2.7/dist-packages/flask/app.py", line 2000, in __call__
[Fri Dec 02 16:07:09.793564 2016] [wsgi:error] [pid 12:tid 140612617090816] [remote 128.211.233.228:6124]     return self.wsgi_app(environ, start_response)
[Fri Dec 02 16:07:09.793578 2016] [wsgi:error] [pid 12:tid 140612617090816] [remote 128.211.233.228:6124]   File "/usr/local/lib/python2.7/dist-packages/flask/app.py", line 1991, in wsgi_app
[Fri Dec 02 16:07:09.793605 2016] [wsgi:error] [pid 12:tid 140612617090816] [remote 128.211.233.228:6124]     response = self.make_response(self.handle_exception(e))
[Fri Dec 02 16:07:09.793617 2016] [wsgi:error] [pid 12:tid 140612617090816] [remote 128.211.233.228:6124]   File "/usr/local/lib/python2.7/dist-packages/flask_restful/__init__.py", line 271, in error_router
[Fri Dec 02 16:07:09.793649 2016] [wsgi:error] [pid 12:tid 140612617090816] [remote 128.211.233.228:6124]     return original_handler(e)
[Fri Dec 02 16:07:09.793660 2016] [wsgi:error] [pid 12:tid 140612617090816] [remote 128.211.233.228:6124]   File "/usr/local/lib/python2.7/dist-packages/flask_cors/extension.py", line 161, in wrapped_function
[Fri Dec 02 16:07:09.793696 2016] [wsgi:error] [pid 12:tid 140612617090816] [remote 128.211.233.228:6124]     return cors_after_request(app.make_response(f(*args, **kwargs)))
[Fri Dec 02 16:07:09.793708 2016] [wsgi:error] [pid 12:tid 140612617090816] [remote 128.211.233.228:6124]   File "/usr/local/lib/python2.7/dist-packages/flask/app.py", line 1567, in handle_exception
[Fri Dec 02 16:07:09.793736 2016] [wsgi:error] [pid 12:tid 140612617090816] [remote 128.211.233.228:6124]     reraise(exc_type, exc_value, tb)
[Fri Dec 02 16:07:09.793747 2016] [wsgi:error] [pid 12:tid 140612617090816] [remote 128.211.233.228:6124]   File "/usr/local/lib/python2.7/dist-packages/flask_restful/__init__.py", line 268, in error_router
[Fri Dec 02 16:07:09.793772 2016] [wsgi:error] [pid 12:tid 140612617090816] [remote 128.211.233.228:6124]     return self.handle_error(e)
[Fri Dec 02 16:07:09.793783 2016] [wsgi:error] [pid 12:tid 140612617090816] [remote 128.211.233.228:6124]   File "/usr/local/lib/python2.7/dist-packages/flask/app.py", line 1988, in wsgi_app
[Fri Dec 02 16:07:09.793803 2016] [wsgi:error] [pid 12:tid 140612617090816] [remote 128.211.233.228:6124]     response = self.full_dispatch_request()
[Fri Dec 02 16:07:09.793813 2016] [wsgi:error] [pid 12:tid 140612617090816] [remote 128.211.233.228:6124]   File "/usr/local/lib/python2.7/dist-packages/flask/app.py", line 1641, in full_dispatch_request
[Fri Dec 02 16:07:09.793830 2016] [wsgi:error] [pid 12:tid 140612617090816] [remote 128.211.233.228:6124]     rv = self.handle_user_exception(e)
[Fri Dec 02 16:07:09.793840 2016] [wsgi:error] [pid 12:tid 140612617090816] [remote 128.211.233.228:6124]   File "/usr/local/lib/python2.7/dist-packages/flask_restful/__init__.py", line 271, in error_router
[Fri Dec 02 16:07:09.793857 2016] [wsgi:error] [pid 12:tid 140612617090816] [remote 128.211.233.228:6124]     return original_handler(e)
[Fri Dec 02 16:07:09.793867 2016] [wsgi:error] [pid 12:tid 140612617090816] [remote 128.211.233.228:6124]   File "/usr/local/lib/python2.7/dist-packages/flask_cors/extension.py", line 161, in wrapped_function
[Fri Dec 02 16:07:09.793885 2016] [wsgi:error] [pid 12:tid 140612617090816] [remote 128.211.233.228:6124]     return cors_after_request(app.make_response(f(*args, **kwargs)))
[Fri Dec 02 16:07:09.793894 2016] [wsgi:error] [pid 12:tid 140612617090816] [remote 128.211.233.228:6124]   File "/usr/local/lib/python2.7/dist-packages/flask/app.py", line 1544, in handle_user_exception
[Fri Dec 02 16:07:09.793912 2016] [wsgi:error] [pid 12:tid 140612617090816] [remote 128.211.233.228:6124]     reraise(exc_type, exc_value, tb)
[Fri Dec 02 16:07:09.793921 2016] [wsgi:error] [pid 12:tid 140612617090816] [remote 128.211.233.228:6124]   File "/usr/local/lib/python2.7/dist-packages/flask_restful/__init__.py", line 268, in error_router
[Fri Dec 02 16:07:09.793950 2016] [wsgi:error] [pid 12:tid 140612617090816] [remote 128.211.233.228:6124]     return self.handle_error(e)
[Fri Dec 02 16:07:09.793961 2016] [wsgi:error] [pid 12:tid 140612617090816] [remote 128.211.233.228:6124]   File "/usr/local/lib/python2.7/dist-packages/flask/app.py", line 1639, in full_dispatch_request
[Fri Dec 02 16:07:09.793978 2016] [wsgi:error] [pid 12:tid 140612617090816] [remote 128.211.233.228:6124]     rv = self.dispatch_request()
[Fri Dec 02 16:07:09.793988 2016] [wsgi:error] [pid 12:tid 140612617090816] [remote 128.211.233.228:6124]   File "/usr/local/lib/python2.7/dist-packages/flask/app.py", line 1625, in dispatch_request
[Fri Dec 02 16:07:09.794011 2016] [wsgi:error] [pid 12:tid 140612617090816] [remote 128.211.233.228:6124]     return self.view_functions[rule.endpoint](**req.view_args)
[Fri Dec 02 16:07:09.794023 2016] [wsgi:error] [pid 12:tid 140612617090816] [remote 128.211.233.228:6124]   File "/usr/local/lib/python2.7/dist-packages/flask_restful/__init__.py", line 477, in wrapper
[Fri Dec 02 16:07:09.794048 2016] [wsgi:error] [pid 12:tid 140612617090816] [remote 128.211.233.228:6124]     resp = resource(*args, **kwargs)
[Fri Dec 02 16:07:09.794068 2016] [wsgi:error] [pid 12:tid 140612617090816] [remote 128.211.233.228:6124]   File "/usr/local/lib/python2.7/dist-packages/flask/views.py", line 84, in view
[Fri Dec 02 16:07:09.794098 2016] [wsgi:error] [pid 12:tid 140612617090816] [remote 128.211.233.228:6124]     return self.dispatch_request(*args, **kwargs)
[Fri Dec 02 16:07:09.794109 2016] [wsgi:error] [pid 12:tid 140612617090816] [remote 128.211.233.228:6124]   File "/usr/local/lib/python2.7/dist-packages/flask_restful/__init__.py", line 587, in dispatch_request
[Fri Dec 02 16:07:09.794134 2016] [wsgi:error] [pid 12:tid 140612617090816] [remote 128.211.233.228:6124]     resp = meth(*args, **kwargs)
[Fri Dec 02 16:07:09.794145 2016] [wsgi:error] [pid 12:tid 140612617090816] [remote 128.211.233.228:6124]   File "/srv/www/app/main.py", line 136, in get
[Fri Dec 02 16:07:09.794183 2016] [wsgi:error] [pid 12:tid 140612617090816] [remote 128.211.233.228:6124]     batch = Batch()
[Fri Dec 02 16:07:09.794195 2016] [wsgi:error] [pid 12:tid 140612617090816] [remote 128.211.233.228:6124]   File "/srv/www/app/main.py", line 40, in __init__
[Fri Dec 02 16:07:09.794219 2016] [wsgi:error] [pid 12:tid 140612617090816] [remote 128.211.233.228:6124]     self.batches = loadJsonFileToData('batch', "/static/data/")
[Fri Dec 02 16:07:09.794231 2016] [wsgi:error] [pid 12:tid 140612617090816] [remote 128.211.233.228:6124]   File "/srv/www/app/main.py", line 32, in loadJsonFileToData
[Fri Dec 02 16:07:09.794255 2016] [wsgi:error] [pid 12:tid 140612617090816] [remote 128.211.233.228:6124]     return json.load(jsonData)
[Fri Dec 02 16:07:09.794266 2016] [wsgi:error] [pid 12:tid 140612617090816] [remote 128.211.233.228:6124]   File "/usr/lib/python2.7/json/__init__.py", line 291, in load
[Fri Dec 02 16:07:09.794310 2016] [wsgi:error] [pid 12:tid 140612617090816] [remote 128.211.233.228:6124]     **kw)
[Fri Dec 02 16:07:09.794321 2016] [wsgi:error] [pid 12:tid 140612617090816] [remote 128.211.233.228:6124]   File "/usr/lib/python2.7/json/__init__.py", line 339, in loads
[Fri Dec 02 16:07:09.794345 2016] [wsgi:error] [pid 12:tid 140612617090816] [remote 128.211.233.228:6124]     return _default_decoder.decode(s)
[Fri Dec 02 16:07:09.794356 2016] [wsgi:error] [pid 12:tid 140612617090816] [remote 128.211.233.228:6124]   File "/usr/lib/python2.7/json/decoder.py", line 364, in decode
[Fri Dec 02 16:07:09.794391 2016] [wsgi:error] [pid 12:tid 140612617090816] [remote 128.211.233.228:6124]     obj, end = self.raw_decode(s, idx=_w(s, 0).end())
[Fri Dec 02 16:07:09.794403 2016] [wsgi:error] [pid 12:tid 140612617090816] [remote 128.211.233.228:6124]   File "/usr/lib/python2.7/json/decoder.py", line 382, in raw_decode
[Fri Dec 02 16:07:09.794432 2016] [wsgi:error] [pid 12:tid 140612617090816] [remote 128.211.233.228:6124]     raise ValueError("No JSON object could be decoded")
[Fri Dec 02 16:07:09.794479 2016] [wsgi:error] [pid 12:tid 140612617090816] [remote 128.211.233.228:6124] ValueError: No JSON object could be decoded
[Sat Dec 03 15:44:33.748105 2016] [wsgi:error] [pid 12:tid 140612726286080] [remote 128.211.233.228:45305] mod_wsgi (pid=12): Exception occurred processing WSGI script '/srv/www/app/apache/apache.wsgi'.
[Sat Dec 03 15:44:33.748692 2016] [wsgi:error] [pid 12:tid 140612726286080] [remote 128.211.233.228:45305] Traceback (most recent call last):
[Sat Dec 03 15:44:33.748784 2016] [wsgi:error] [pid 12:tid 140612726286080] [remote 128.211.233.228:45305]   File "/usr/local/lib/python2.7/dist-packages/flask/app.py", line 2000, in __call__
[Sat Dec 03 15:44:33.750413 2016] [wsgi:error] [pid 12:tid 140612726286080] [remote 128.211.233.228:45305]     return self.wsgi_app(environ, start_response)
[Sat Dec 03 15:44:33.750522 2016] [wsgi:error] [pid 12:tid 140612726286080] [remote 128.211.233.228:45305]   File "/usr/local/lib/python2.7/dist-packages/flask/app.py", line 1991, in wsgi_app
[Sat Dec 03 15:44:33.750642 2016] [wsgi:error] [pid 12:tid 140612726286080] [remote 128.211.233.228:45305]     response = self.make_response(self.handle_exception(e))
[Sat Dec 03 15:44:33.750721 2016] [wsgi:error] [pid 12:tid 140612726286080] [remote 128.211.233.228:45305]   File "/usr/local/lib/python2.7/dist-packages/flask_restful/__init__.py", line 271, in error_router
[Sat Dec 03 15:44:33.751779 2016] [wsgi:error] [pid 12:tid 140612726286080] [remote 128.211.233.228:45305]     return original_handler(e)
[Sat Dec 03 15:44:33.751888 2016] [wsgi:error] [pid 12:tid 140612726286080] [remote 128.211.233.228:45305]   File "/usr/local/lib/python2.7/dist-packages/flask_cors/extension.py", line 161, in wrapped_function
[Sat Dec 03 15:44:33.752098 2016] [wsgi:error] [pid 12:tid 140612726286080] [remote 128.211.233.228:45305]     return cors_after_request(app.make_response(f(*args, **kwargs)))
[Sat Dec 03 15:44:33.752183 2016] [wsgi:error] [pid 12:tid 140612726286080] [remote 128.211.233.228:45305]   File "/usr/local/lib/python2.7/dist-packages/flask/app.py", line 1567, in handle_exception
[Sat Dec 03 15:44:33.752302 2016] [wsgi:error] [pid 12:tid 140612726286080] [remote 128.211.233.228:45305]     reraise(exc_type, exc_value, tb)
[Sat Dec 03 15:44:33.752377 2016] [wsgi:error] [pid 12:tid 140612726286080] [remote 128.211.233.228:45305]   File "/usr/local/lib/python2.7/dist-packages/flask_restful/__init__.py", line 268, in error_router
[Sat Dec 03 15:44:33.752512 2016] [wsgi:error] [pid 12:tid 140612726286080] [remote 128.211.233.228:45305]     return self.handle_error(e)
[Sat Dec 03 15:44:33.752586 2016] [wsgi:error] [pid 12:tid 140612726286080] [remote 128.211.233.228:45305]   File "/usr/local/lib/python2.7/dist-packages/flask/app.py", line 1988, in wsgi_app
[Sat Dec 03 15:44:33.752670 2016] [wsgi:error] [pid 12:tid 140612726286080] [remote 128.211.233.228:45305]     response = self.full_dispatch_request()
[Sat Dec 03 15:44:33.752736 2016] [wsgi:error] [pid 12:tid 140612726286080] [remote 128.211.233.228:45305]   File "/usr/local/lib/python2.7/dist-packages/flask/app.py", line 1641, in full_dispatch_request
[Sat Dec 03 15:44:33.752818 2016] [wsgi:error] [pid 12:tid 140612726286080] [remote 128.211.233.228:45305]     rv = self.handle_user_exception(e)
[Sat Dec 03 15:44:33.752883 2016] [wsgi:error] [pid 12:tid 140612726286080] [remote 128.211.233.228:45305]   File "/usr/local/lib/python2.7/dist-packages/flask_restful/__init__.py", line 271, in error_router
[Sat Dec 03 15:44:33.752963 2016] [wsgi:error] [pid 12:tid 140612726286080] [remote 128.211.233.228:45305]     return original_handler(e)
[Sat Dec 03 15:44:33.753028 2016] [wsgi:error] [pid 12:tid 140612726286080] [remote 128.211.233.228:45305]   File "/usr/local/lib/python2.7/dist-packages/flask_cors/extension.py", line 161, in wrapped_function
[Sat Dec 03 15:44:33.753109 2016] [wsgi:error] [pid 12:tid 140612726286080] [remote 128.211.233.228:45305]     return cors_after_request(app.make_response(f(*args, **kwargs)))
[Sat Dec 03 15:44:33.753175 2016] [wsgi:error] [pid 12:tid 140612726286080] [remote 128.211.233.228:45305]   File "/usr/local/lib/python2.7/dist-packages/flask/app.py", line 1544, in handle_user_exception
[Sat Dec 03 15:44:33.753310 2016] [wsgi:error] [pid 12:tid 140612726286080] [remote 128.211.233.228:45305]     reraise(exc_type, exc_value, tb)
[Sat Dec 03 15:44:33.753388 2016] [wsgi:error] [pid 12:tid 140612726286080] [remote 128.211.233.228:45305]   File "/usr/local/lib/python2.7/dist-packages/flask_restful/__init__.py", line 268, in error_router
[Sat Dec 03 15:44:33.753472 2016] [wsgi:error] [pid 12:tid 140612726286080] [remote 128.211.233.228:45305]     return self.handle_error(e)
[Sat Dec 03 15:44:33.753538 2016] [wsgi:error] [pid 12:tid 140612726286080] [remote 128.211.233.228:45305]   File "/usr/local/lib/python2.7/dist-packages/flask/app.py", line 1639, in full_dispatch_request
[Sat Dec 03 15:44:33.753619 2016] [wsgi:error] [pid 12:tid 140612726286080] [remote 128.211.233.228:45305]     rv = self.dispatch_request()
[Sat Dec 03 15:44:33.753683 2016] [wsgi:error] [pid 12:tid 140612726286080] [remote 128.211.233.228:45305]   File "/usr/local/lib/python2.7/dist-packages/flask/app.py", line 1625, in dispatch_request
[Sat Dec 03 15:44:33.753780 2016] [wsgi:error] [pid 12:tid 140612726286080] [remote 128.211.233.228:45305]     return self.view_functions[rule.endpoint](**req.view_args)
[Sat Dec 03 15:44:33.753852 2016] [wsgi:error] [pid 12:tid 140612726286080] [remote 128.211.233.228:45305]   File "/usr/local/lib/python2.7/dist-packages/flask_restful/__init__.py", line 477, in wrapper
[Sat Dec 03 15:44:33.753951 2016] [wsgi:error] [pid 12:tid 140612726286080] [remote 128.211.233.228:45305]     resp = resource(*args, **kwargs)
[Sat Dec 03 15:44:33.754036 2016] [wsgi:error] [pid 12:tid 140612726286080] [remote 128.211.233.228:45305]   File "/usr/local/lib/python2.7/dist-packages/flask/views.py", line 84, in view
[Sat Dec 03 15:44:33.754169 2016] [wsgi:error] [pid 12:tid 140612726286080] [remote 128.211.233.228:45305]     return self.dispatch_request(*args, **kwargs)
[Sat Dec 03 15:44:33.754246 2016] [wsgi:error] [pid 12:tid 140612726286080] [remote 128.211.233.228:45305]   File "/usr/local/lib/python2.7/dist-packages/flask_restful/__init__.py", line 587, in dispatch_request
[Sat Dec 03 15:44:33.754354 2016] [wsgi:error] [pid 12:tid 140612726286080] [remote 128.211.233.228:45305]     resp = meth(*args, **kwargs)
[Sat Dec 03 15:44:33.754452 2016] [wsgi:error] [pid 12:tid 140612726286080] [remote 128.211.233.228:45305]   File "/srv/www/app/main.py", line 171, in put
[Sat Dec 03 15:44:33.754635 2016] [wsgi:error] [pid 12:tid 140612726286080] [remote 128.211.233.228:45305]     for idx, val in enumerate(dataOld):
[Sat Dec 03 15:44:33.754827 2016] [wsgi:error] [pid 12:tid 140612726286080] [remote 128.211.233.228:45305] TypeError: 'NoneType' object is not iterable
[Sat Dec 03 15:44:38.100808 2016] [wsgi:error] [pid 12:tid 140612726286080] [remote 128.211.233.228:45305] mod_wsgi (pid=12): Exception occurred processing WSGI script '/srv/www/app/apache/apache.wsgi'.
[Sat Dec 03 15:44:38.100982 2016] [wsgi:error] [pid 12:tid 140612726286080] [remote 128.211.233.228:45305] Traceback (most recent call last):
[Sat Dec 03 15:44:38.101076 2016] [wsgi:error] [pid 12:tid 140612726286080] [remote 128.211.233.228:45305]   File "/usr/local/lib/python2.7/dist-packages/flask/app.py", line 2000, in __call__
[Sat Dec 03 15:44:38.101191 2016] [wsgi:error] [pid 12:tid 140612726286080] [remote 128.211.233.228:45305]     return self.wsgi_app(environ, start_response)
[Sat Dec 03 15:44:38.101306 2016] [wsgi:error] [pid 12:tid 140612726286080] [remote 128.211.233.228:45305]   File "/usr/local/lib/python2.7/dist-packages/flask/app.py", line 1991, in wsgi_app
[Sat Dec 03 15:44:38.101410 2016] [wsgi:error] [pid 12:tid 140612726286080] [remote 128.211.233.228:45305]     response = self.make_response(self.handle_exception(e))
[Sat Dec 03 15:44:38.101481 2016] [wsgi:error] [pid 12:tid 140612726286080] [remote 128.211.233.228:45305]   File "/usr/local/lib/python2.7/dist-packages/flask_restful/__init__.py", line 271, in error_router
[Sat Dec 03 15:44:38.101567 2016] [wsgi:error] [pid 12:tid 140612726286080] [remote 128.211.233.228:45305]     return original_handler(e)
[Sat Dec 03 15:44:38.101634 2016] [wsgi:error] [pid 12:tid 140612726286080] [remote 128.211.233.228:45305]   File "/usr/local/lib/python2.7/dist-packages/flask_cors/extension.py", line 161, in wrapped_function
[Sat Dec 03 15:44:38.101720 2016] [wsgi:error] [pid 12:tid 140612726286080] [remote 128.211.233.228:45305]     return cors_after_request(app.make_response(f(*args, **kwargs)))
[Sat Dec 03 15:44:38.101785 2016] [wsgi:error] [pid 12:tid 140612726286080] [remote 128.211.233.228:45305]   File "/usr/local/lib/python2.7/dist-packages/flask/app.py", line 1567, in handle_exception
[Sat Dec 03 15:44:38.101868 2016] [wsgi:error] [pid 12:tid 140612726286080] [remote 128.211.233.228:45305]     reraise(exc_type, exc_value, tb)
[Sat Dec 03 15:44:38.101933 2016] [wsgi:error] [pid 12:tid 140612726286080] [remote 128.211.233.228:45305]   File "/usr/local/lib/python2.7/dist-packages/flask_restful/__init__.py", line 268, in error_router
[Sat Dec 03 15:44:38.102014 2016] [wsgi:error] [pid 12:tid 140612726286080] [remote 128.211.233.228:45305]     return self.handle_error(e)
[Sat Dec 03 15:44:38.102080 2016] [wsgi:error] [pid 12:tid 140612726286080] [remote 128.211.233.228:45305]   File "/usr/local/lib/python2.7/dist-packages/flask/app.py", line 1988, in wsgi_app
[Sat Dec 03 15:44:38.102162 2016] [wsgi:error] [pid 12:tid 140612726286080] [remote 128.211.233.228:45305]     response = self.full_dispatch_request()
[Sat Dec 03 15:44:38.102227 2016] [wsgi:error] [pid 12:tid 140612726286080] [remote 128.211.233.228:45305]   File "/usr/local/lib/python2.7/dist-packages/flask/app.py", line 1641, in full_dispatch_request
[Sat Dec 03 15:44:38.102312 2016] [wsgi:error] [pid 12:tid 140612726286080] [remote 128.211.233.228:45305]     rv = self.handle_user_exception(e)
[Sat Dec 03 15:44:38.102378 2016] [wsgi:error] [pid 12:tid 140612726286080] [remote 128.211.233.228:45305]   File "/usr/local/lib/python2.7/dist-packages/flask_restful/__init__.py", line 271, in error_router
[Sat Dec 03 15:44:38.102468 2016] [wsgi:error] [pid 12:tid 140612726286080] [remote 128.211.233.228:45305]     return original_handler(e)
[Sat Dec 03 15:44:38.102535 2016] [wsgi:error] [pid 12:tid 140612726286080] [remote 128.211.233.228:45305]   File "/usr/local/lib/python2.7/dist-packages/flask_cors/extension.py", line 161, in wrapped_function
[Sat Dec 03 15:44:38.102650 2016] [wsgi:error] [pid 12:tid 140612726286080] [remote 128.211.233.228:45305]     return cors_after_request(app.make_response(f(*args, **kwargs)))
[Sat Dec 03 15:44:38.102720 2016] [wsgi:error] [pid 12:tid 140612726286080] [remote 128.211.233.228:45305]   File "/usr/local/lib/python2.7/dist-packages/flask/app.py", line 1544, in handle_user_exception
[Sat Dec 03 15:44:38.102802 2016] [wsgi:error] [pid 12:tid 140612726286080] [remote 128.211.233.228:45305]     reraise(exc_type, exc_value, tb)
[Sat Dec 03 15:44:38.102922 2016] [wsgi:error] [pid 12:tid 140612726286080] [remote 128.211.233.228:45305]   File "/usr/local/lib/python2.7/dist-packages/flask_restful/__init__.py", line 268, in error_router
[Sat Dec 03 15:44:38.103025 2016] [wsgi:error] [pid 12:tid 140612726286080] [remote 128.211.233.228:45305]     return self.handle_error(e)
[Sat Dec 03 15:44:38.103093 2016] [wsgi:error] [pid 12:tid 140612726286080] [remote 128.211.233.228:45305]   File "/usr/local/lib/python2.7/dist-packages/flask/app.py", line 1639, in full_dispatch_request
[Sat Dec 03 15:44:38.103233 2016] [wsgi:error] [pid 12:tid 140612726286080] [remote 128.211.233.228:45305]     rv = self.dispatch_request()
[Sat Dec 03 15:44:38.103352 2016] [wsgi:error] [pid 12:tid 140612726286080] [remote 128.211.233.228:45305]   File "/usr/local/lib/python2.7/dist-packages/flask/app.py", line 1625, in dispatch_request
[Sat Dec 03 15:44:38.103502 2016] [wsgi:error] [pid 12:tid 140612726286080] [remote 128.211.233.228:45305]     return self.view_functions[rule.endpoint](**req.view_args)
[Sat Dec 03 15:44:38.103618 2016] [wsgi:error] [pid 12:tid 140612726286080] [remote 128.211.233.228:45305]   File "/usr/local/lib/python2.7/dist-packages/flask_restful/__init__.py", line 477, in wrapper
[Sat Dec 03 15:44:38.103771 2016] [wsgi:error] [pid 12:tid 140612726286080] [remote 128.211.233.228:45305]     resp = resource(*args, **kwargs)
[Sat Dec 03 15:44:38.103889 2016] [wsgi:error] [pid 12:tid 140612726286080] [remote 128.211.233.228:45305]   File "/usr/local/lib/python2.7/dist-packages/flask/views.py", line 84, in view
[Sat Dec 03 15:44:38.104038 2016] [wsgi:error] [pid 12:tid 140612726286080] [remote 128.211.233.228:45305]     return self.dispatch_request(*args, **kwargs)
[Sat Dec 03 15:44:38.104152 2016] [wsgi:error] [pid 12:tid 140612726286080] [remote 128.211.233.228:45305]   File "/usr/local/lib/python2.7/dist-packages/flask_restful/__init__.py", line 587, in dispatch_request
[Sat Dec 03 15:44:38.104309 2016] [wsgi:error] [pid 12:tid 140612726286080] [remote 128.211.233.228:45305]     resp = meth(*args, **kwargs)
[Sat Dec 03 15:44:38.104423 2016] [wsgi:error] [pid 12:tid 140612726286080] [remote 128.211.233.228:45305]   File "/srv/www/app/main.py", line 171, in put
[Sat Dec 03 15:44:38.104577 2016] [wsgi:error] [pid 12:tid 140612726286080] [remote 128.211.233.228:45305]     for idx, val in enumerate(dataOld):
[Sat Dec 03 15:44:38.104709 2016] [wsgi:error] [pid 12:tid 140612726286080] [remote 128.211.233.228:45305] TypeError: 'NoneType' object is not iterable
[Sat Dec 03 15:44:47.237034 2016] [wsgi:error] [pid 12:tid 140612726286080] [remote 128.211.233.228:45561] mod_wsgi (pid=12): Exception occurred processing WSGI script '/srv/www/app/apache/apache.wsgi'.
[Sat Dec 03 15:44:47.237143 2016] [wsgi:error] [pid 12:tid 140612726286080] [remote 128.211.233.228:45561] Traceback (most recent call last):
[Sat Dec 03 15:44:47.237201 2016] [wsgi:error] [pid 12:tid 140612726286080] [remote 128.211.233.228:45561]   File "/usr/local/lib/python2.7/dist-packages/flask/app.py", line 2000, in __call__
[Sat Dec 03 15:44:47.237286 2016] [wsgi:error] [pid 12:tid 140612726286080] [remote 128.211.233.228:45561]     return self.wsgi_app(environ, start_response)
[Sat Dec 03 15:44:47.237334 2016] [wsgi:error] [pid 12:tid 140612726286080] [remote 128.211.233.228:45561]   File "/usr/local/lib/python2.7/dist-packages/flask/app.py", line 1991, in wsgi_app
[Sat Dec 03 15:44:47.237420 2016] [wsgi:error] [pid 12:tid 140612726286080] [remote 128.211.233.228:45561]     response = self.make_response(self.handle_exception(e))
[Sat Dec 03 15:44:47.237460 2016] [wsgi:error] [pid 12:tid 140612726286080] [remote 128.211.233.228:45561]   File "/usr/local/lib/python2.7/dist-packages/flask_restful/__init__.py", line 271, in error_router
[Sat Dec 03 15:44:47.237502 2016] [wsgi:error] [pid 12:tid 140612726286080] [remote 128.211.233.228:45561]     return original_handler(e)
[Sat Dec 03 15:44:47.237533 2016] [wsgi:error] [pid 12:tid 140612726286080] [remote 128.211.233.228:45561]   File "/usr/local/lib/python2.7/dist-packages/flask_cors/extension.py", line 161, in wrapped_function
[Sat Dec 03 15:44:47.237587 2016] [wsgi:error] [pid 12:tid 140612726286080] [remote 128.211.233.228:45561]     return cors_after_request(app.make_response(f(*args, **kwargs)))
[Sat Dec 03 15:44:47.237619 2016] [wsgi:error] [pid 12:tid 140612726286080] [remote 128.211.233.228:45561]   File "/usr/local/lib/python2.7/dist-packages/flask/app.py", line 1567, in handle_exception
[Sat Dec 03 15:44:47.237658 2016] [wsgi:error] [pid 12:tid 140612726286080] [remote 128.211.233.228:45561]     reraise(exc_type, exc_value, tb)
[Sat Dec 03 15:44:47.237688 2016] [wsgi:error] [pid 12:tid 140612726286080] [remote 128.211.233.228:45561]   File "/usr/local/lib/python2.7/dist-packages/flask_restful/__init__.py", line 268, in error_router
[Sat Dec 03 15:44:47.237725 2016] [wsgi:error] [pid 12:tid 140612726286080] [remote 128.211.233.228:45561]     return self.handle_error(e)
[Sat Dec 03 15:44:47.237755 2016] [wsgi:error] [pid 12:tid 140612726286080] [remote 128.211.233.228:45561]   File "/usr/local/lib/python2.7/dist-packages/flask/app.py", line 1988, in wsgi_app
[Sat Dec 03 15:44:47.237793 2016] [wsgi:error] [pid 12:tid 140612726286080] [remote 128.211.233.228:45561]     response = self.full_dispatch_request()
[Sat Dec 03 15:44:47.237822 2016] [wsgi:error] [pid 12:tid 140612726286080] [remote 128.211.233.228:45561]   File "/usr/local/lib/python2.7/dist-packages/flask/app.py", line 1641, in full_dispatch_request
[Sat Dec 03 15:44:47.237860 2016] [wsgi:error] [pid 12:tid 140612726286080] [remote 128.211.233.228:45561]     rv = self.handle_user_exception(e)
[Sat Dec 03 15:44:47.237890 2016] [wsgi:error] [pid 12:tid 140612726286080] [remote 128.211.233.228:45561]   File "/usr/local/lib/python2.7/dist-packages/flask_restful/__init__.py", line 271, in error_router
[Sat Dec 03 15:44:47.237927 2016] [wsgi:error] [pid 12:tid 140612726286080] [remote 128.211.233.228:45561]     return original_handler(e)
[Sat Dec 03 15:44:47.237957 2016] [wsgi:error] [pid 12:tid 140612726286080] [remote 128.211.233.228:45561]   File "/usr/local/lib/python2.7/dist-packages/flask_cors/extension.py", line 161, in wrapped_function
[Sat Dec 03 15:44:47.237994 2016] [wsgi:error] [pid 12:tid 140612726286080] [remote 128.211.233.228:45561]     return cors_after_request(app.make_response(f(*args, **kwargs)))
[Sat Dec 03 15:44:47.238024 2016] [wsgi:error] [pid 12:tid 140612726286080] [remote 128.211.233.228:45561]   File "/usr/local/lib/python2.7/dist-packages/flask/app.py", line 1544, in handle_user_exception
[Sat Dec 03 15:44:47.238062 2016] [wsgi:error] [pid 12:tid 140612726286080] [remote 128.211.233.228:45561]     reraise(exc_type, exc_value, tb)
[Sat Dec 03 15:44:47.238092 2016] [wsgi:error] [pid 12:tid 140612726286080] [remote 128.211.233.228:45561]   File "/usr/local/lib/python2.7/dist-packages/flask_restful/__init__.py", line 268, in error_router
[Sat Dec 03 15:44:47.238129 2016] [wsgi:error] [pid 12:tid 140612726286080] [remote 128.211.233.228:45561]     return self.handle_error(e)
[Sat Dec 03 15:44:47.238159 2016] [wsgi:error] [pid 12:tid 140612726286080] [remote 128.211.233.228:45561]   File "/usr/local/lib/python2.7/dist-packages/flask/app.py", line 1639, in full_dispatch_request
[Sat Dec 03 15:44:47.238197 2016] [wsgi:error] [pid 12:tid 140612726286080] [remote 128.211.233.228:45561]     rv = self.dispatch_request()
[Sat Dec 03 15:44:47.238235 2016] [wsgi:error] [pid 12:tid 140612726286080] [remote 128.211.233.228:45561]   File "/usr/local/lib/python2.7/dist-packages/flask/app.py", line 1625, in dispatch_request
[Sat Dec 03 15:44:47.238275 2016] [wsgi:error] [pid 12:tid 140612726286080] [remote 128.211.233.228:45561]     return self.view_functions[rule.endpoint](**req.view_args)
[Sat Dec 03 15:44:47.238305 2016] [wsgi:error] [pid 12:tid 140612726286080] [remote 128.211.233.228:45561]   File "/usr/local/lib/python2.7/dist-packages/flask_restful/__init__.py", line 477, in wrapper
[Sat Dec 03 15:44:47.238343 2016] [wsgi:error] [pid 12:tid 140612726286080] [remote 128.211.233.228:45561]     resp = resource(*args, **kwargs)
[Sat Dec 03 15:44:47.238374 2016] [wsgi:error] [pid 12:tid 140612726286080] [remote 128.211.233.228:45561]   File "/usr/local/lib/python2.7/dist-packages/flask/views.py", line 84, in view
[Sat Dec 03 15:44:47.238413 2016] [wsgi:error] [pid 12:tid 140612726286080] [remote 128.211.233.228:45561]     return self.dispatch_request(*args, **kwargs)
[Sat Dec 03 15:44:47.238443 2016] [wsgi:error] [pid 12:tid 140612726286080] [remote 128.211.233.228:45561]   File "/usr/local/lib/python2.7/dist-packages/flask_restful/__init__.py", line 587, in dispatch_request
[Sat Dec 03 15:44:47.238481 2016] [wsgi:error] [pid 12:tid 140612726286080] [remote 128.211.233.228:45561]     resp = meth(*args, **kwargs)
[Sat Dec 03 15:44:47.238511 2016] [wsgi:error] [pid 12:tid 140612726286080] [remote 128.211.233.228:45561]   File "/srv/www/app/main.py", line 171, in put
[Sat Dec 03 15:44:47.238550 2016] [wsgi:error] [pid 12:tid 140612726286080] [remote 128.211.233.228:45561]     for idx, val in enumerate(dataOld):
[Sat Dec 03 15:44:47.238590 2016] [wsgi:error] [pid 12:tid 140612726286080] [remote 128.211.233.228:45561] TypeError: 'NoneType' object is not iterable
[Sat Dec 03 15:44:54.535383 2016] [wsgi:error] [pid 12:tid 140612625491712] [remote 128.211.233.228:45305] mod_wsgi (pid=12): Exception occurred processing WSGI script '/srv/www/app/apache/apache.wsgi'.
[Sat Dec 03 15:44:54.535564 2016] [wsgi:error] [pid 12:tid 140612625491712] [remote 128.211.233.228:45305] Traceback (most recent call last):
[Sat Dec 03 15:44:54.535656 2016] [wsgi:error] [pid 12:tid 140612625491712] [remote 128.211.233.228:45305]   File "/usr/local/lib/python2.7/dist-packages/flask/app.py", line 2000, in __call__
[Sat Dec 03 15:44:54.535771 2016] [wsgi:error] [pid 12:tid 140612625491712] [remote 128.211.233.228:45305]     return self.wsgi_app(environ, start_response)
[Sat Dec 03 15:44:54.535844 2016] [wsgi:error] [pid 12:tid 140612625491712] [remote 128.211.233.228:45305]   File "/usr/local/lib/python2.7/dist-packages/flask/app.py", line 1991, in wsgi_app
[Sat Dec 03 15:44:54.535931 2016] [wsgi:error] [pid 12:tid 140612625491712] [remote 128.211.233.228:45305]     response = self.make_response(self.handle_exception(e))
[Sat Dec 03 15:44:54.535999 2016] [wsgi:error] [pid 12:tid 140612625491712] [remote 128.211.233.228:45305]   File "/usr/local/lib/python2.7/dist-packages/flask_restful/__init__.py", line 271, in error_router
[Sat Dec 03 15:44:54.536085 2016] [wsgi:error] [pid 12:tid 140612625491712] [remote 128.211.233.228:45305]     return original_handler(e)
[Sat Dec 03 15:44:54.536151 2016] [wsgi:error] [pid 12:tid 140612625491712] [remote 128.211.233.228:45305]   File "/usr/local/lib/python2.7/dist-packages/flask_cors/extension.py", line 161, in wrapped_function
[Sat Dec 03 15:44:54.536235 2016] [wsgi:error] [pid 12:tid 140612625491712] [remote 128.211.233.228:45305]     return cors_after_request(app.make_response(f(*args, **kwargs)))
[Sat Dec 03 15:44:54.536301 2016] [wsgi:error] [pid 12:tid 140612625491712] [remote 128.211.233.228:45305]   File "/usr/local/lib/python2.7/dist-packages/flask/app.py", line 1567, in handle_exception
[Sat Dec 03 15:44:54.536382 2016] [wsgi:error] [pid 12:tid 140612625491712] [remote 128.211.233.228:45305]     reraise(exc_type, exc_value, tb)
[Sat Dec 03 15:44:54.536447 2016] [wsgi:error] [pid 12:tid 140612625491712] [remote 128.211.233.228:45305]   File "/usr/local/lib/python2.7/dist-packages/flask_restful/__init__.py", line 268, in error_router
[Sat Dec 03 15:44:54.536564 2016] [wsgi:error] [pid 12:tid 140612625491712] [remote 128.211.233.228:45305]     return self.handle_error(e)
[Sat Dec 03 15:44:54.536633 2016] [wsgi:error] [pid 12:tid 140612625491712] [remote 128.211.233.228:45305]   File "/usr/local/lib/python2.7/dist-packages/flask/app.py", line 1988, in wsgi_app
[Sat Dec 03 15:44:54.536716 2016] [wsgi:error] [pid 12:tid 140612625491712] [remote 128.211.233.228:45305]     response = self.full_dispatch_request()
[Sat Dec 03 15:44:54.536781 2016] [wsgi:error] [pid 12:tid 140612625491712] [remote 128.211.233.228:45305]   File "/usr/local/lib/python2.7/dist-packages/flask/app.py", line 1641, in full_dispatch_request
[Sat Dec 03 15:44:54.536863 2016] [wsgi:error] [pid 12:tid 140612625491712] [remote 128.211.233.228:45305]     rv = self.handle_user_exception(e)
[Sat Dec 03 15:44:54.536928 2016] [wsgi:error] [pid 12:tid 140612625491712] [remote 128.211.233.228:45305]   File "/usr/local/lib/python2.7/dist-packages/flask_restful/__init__.py", line 271, in error_router
[Sat Dec 03 15:44:54.537009 2016] [wsgi:error] [pid 12:tid 140612625491712] [remote 128.211.233.228:45305]     return original_handler(e)
[Sat Dec 03 15:44:54.537073 2016] [wsgi:error] [pid 12:tid 140612625491712] [remote 128.211.233.228:45305]   File "/usr/local/lib/python2.7/dist-packages/flask_cors/extension.py", line 161, in wrapped_function
[Sat Dec 03 15:44:54.537155 2016] [wsgi:error] [pid 12:tid 140612625491712] [remote 128.211.233.228:45305]     return cors_after_request(app.make_response(f(*args, **kwargs)))
[Sat Dec 03 15:44:54.537219 2016] [wsgi:error] [pid 12:tid 140612625491712] [remote 128.211.233.228:45305]   File "/usr/local/lib/python2.7/dist-packages/flask/app.py", line 1544, in handle_user_exception
[Sat Dec 03 15:44:54.537329 2016] [wsgi:error] [pid 12:tid 140612625491712] [remote 128.211.233.228:45305]     reraise(exc_type, exc_value, tb)
[Sat Dec 03 15:44:54.537402 2016] [wsgi:error] [pid 12:tid 140612625491712] [remote 128.211.233.228:45305]   File "/usr/local/lib/python2.7/dist-packages/flask_restful/__init__.py", line 268, in error_router
[Sat Dec 03 15:44:54.537513 2016] [wsgi:error] [pid 12:tid 140612625491712] [remote 128.211.233.228:45305]     return self.handle_error(e)
[Sat Dec 03 15:44:54.537587 2016] [wsgi:error] [pid 12:tid 140612625491712] [remote 128.211.233.228:45305]   File "/usr/local/lib/python2.7/dist-packages/flask/app.py", line 1639, in full_dispatch_request
[Sat Dec 03 15:44:54.537671 2016] [wsgi:error] [pid 12:tid 140612625491712] [remote 128.211.233.228:45305]     rv = self.dispatch_request()
[Sat Dec 03 15:44:54.537736 2016] [wsgi:error] [pid 12:tid 140612625491712] [remote 128.211.233.228:45305]   File "/usr/local/lib/python2.7/dist-packages/flask/app.py", line 1625, in dispatch_request
[Sat Dec 03 15:44:54.537818 2016] [wsgi:error] [pid 12:tid 140612625491712] [remote 128.211.233.228:45305]     return self.view_functions[rule.endpoint](**req.view_args)
[Sat Dec 03 15:44:54.537884 2016] [wsgi:error] [pid 12:tid 140612625491712] [remote 128.211.233.228:45305]   File "/usr/local/lib/python2.7/dist-packages/flask_restful/__init__.py", line 477, in wrapper
[Sat Dec 03 15:44:54.537967 2016] [wsgi:error] [pid 12:tid 140612625491712] [remote 128.211.233.228:45305]     resp = resource(*args, **kwargs)
[Sat Dec 03 15:44:54.538033 2016] [wsgi:error] [pid 12:tid 140612625491712] [remote 128.211.233.228:45305]   File "/usr/local/lib/python2.7/dist-packages/flask/views.py", line 84, in view
[Sat Dec 03 15:44:54.538129 2016] [wsgi:error] [pid 12:tid 140612625491712] [remote 128.211.233.228:45305]     return self.dispatch_request(*args, **kwargs)
[Sat Dec 03 15:44:54.538235 2016] [wsgi:error] [pid 12:tid 140612625491712] [remote 128.211.233.228:45305]   File "/usr/local/lib/python2.7/dist-packages/flask_restful/__init__.py", line 587, in dispatch_request
[Sat Dec 03 15:44:54.538528 2016] [wsgi:error] [pid 12:tid 140612625491712] [remote 128.211.233.228:45305]     resp = meth(*args, **kwargs)
[Sat Dec 03 15:44:54.538643 2016] [wsgi:error] [pid 12:tid 140612625491712] [remote 128.211.233.228:45305]   File "/srv/www/app/main.py", line 171, in put
[Sat Dec 03 15:44:54.538737 2016] [wsgi:error] [pid 12:tid 140612625491712] [remote 128.211.233.228:45305]     for idx, val in enumerate(dataOld):
[Sat Dec 03 15:44:54.538821 2016] [wsgi:error] [pid 12:tid 140612625491712] [remote 128.211.233.228:45305] TypeError: 'NoneType' object is not iterable
[Sat Dec 03 15:46:56.284412 2016] [wsgi:error] [pid 12:tid 140612642301696] [remote 128.211.233.228:45305] mod_wsgi (pid=12): Exception occurred processing WSGI script '/srv/www/app/apache/apache.wsgi'.
[Sat Dec 03 15:46:56.284875 2016] [wsgi:error] [pid 12:tid 140612642301696] [remote 128.211.233.228:45305] Traceback (most recent call last):
[Sat Dec 03 15:46:56.285019 2016] [wsgi:error] [pid 12:tid 140612642301696] [remote 128.211.233.228:45305]   File "/usr/local/lib/python2.7/dist-packages/flask/app.py", line 2000, in __call__
[Sat Dec 03 15:46:56.285294 2016] [wsgi:error] [pid 12:tid 140612642301696] [remote 128.211.233.228:45305]     return self.wsgi_app(environ, start_response)
[Sat Dec 03 15:46:56.285373 2016] [wsgi:error] [pid 12:tid 140612642301696] [remote 128.211.233.228:45305]   File "/usr/local/lib/python2.7/dist-packages/flask/app.py", line 1991, in wsgi_app
[Sat Dec 03 15:46:56.285479 2016] [wsgi:error] [pid 12:tid 140612642301696] [remote 128.211.233.228:45305]     response = self.make_response(self.handle_exception(e))
[Sat Dec 03 15:46:56.285578 2016] [wsgi:error] [pid 12:tid 140612642301696] [remote 128.211.233.228:45305]   File "/usr/local/lib/python2.7/dist-packages/flask_restful/__init__.py", line 271, in error_router
[Sat Dec 03 15:46:56.285705 2016] [wsgi:error] [pid 12:tid 140612642301696] [remote 128.211.233.228:45305]     return original_handler(e)
[Sat Dec 03 15:46:56.285778 2016] [wsgi:error] [pid 12:tid 140612642301696] [remote 128.211.233.228:45305]   File "/usr/local/lib/python2.7/dist-packages/flask_cors/extension.py", line 161, in wrapped_function
[Sat Dec 03 15:46:56.285907 2016] [wsgi:error] [pid 12:tid 140612642301696] [remote 128.211.233.228:45305]     return cors_after_request(app.make_response(f(*args, **kwargs)))
[Sat Dec 03 15:46:56.285979 2016] [wsgi:error] [pid 12:tid 140612642301696] [remote 128.211.233.228:45305]   File "/usr/local/lib/python2.7/dist-packages/flask/app.py", line 1567, in handle_exception
[Sat Dec 03 15:46:56.286083 2016] [wsgi:error] [pid 12:tid 140612642301696] [remote 128.211.233.228:45305]     reraise(exc_type, exc_value, tb)
[Sat Dec 03 15:46:56.286155 2016] [wsgi:error] [pid 12:tid 140612642301696] [remote 128.211.233.228:45305]   File "/usr/local/lib/python2.7/dist-packages/flask_restful/__init__.py", line 268, in error_router
[Sat Dec 03 15:46:56.286254 2016] [wsgi:error] [pid 12:tid 140612642301696] [remote 128.211.233.228:45305]     return self.handle_error(e)
[Sat Dec 03 15:46:56.286325 2016] [wsgi:error] [pid 12:tid 140612642301696] [remote 128.211.233.228:45305]   File "/usr/local/lib/python2.7/dist-packages/flask/app.py", line 1988, in wsgi_app
[Sat Dec 03 15:46:56.286410 2016] [wsgi:error] [pid 12:tid 140612642301696] [remote 128.211.233.228:45305]     response = self.full_dispatch_request()
[Sat Dec 03 15:46:56.286476 2016] [wsgi:error] [pid 12:tid 140612642301696] [remote 128.211.233.228:45305]   File "/usr/local/lib/python2.7/dist-packages/flask/app.py", line 1641, in full_dispatch_request
[Sat Dec 03 15:46:56.286559 2016] [wsgi:error] [pid 12:tid 140612642301696] [remote 128.211.233.228:45305]     rv = self.handle_user_exception(e)
[Sat Dec 03 15:46:56.286624 2016] [wsgi:error] [pid 12:tid 140612642301696] [remote 128.211.233.228:45305]   File "/usr/local/lib/python2.7/dist-packages/flask_restful/__init__.py", line 271, in error_router
[Sat Dec 03 15:46:56.286706 2016] [wsgi:error] [pid 12:tid 140612642301696] [remote 128.211.233.228:45305]     return original_handler(e)
[Sat Dec 03 15:46:56.286771 2016] [wsgi:error] [pid 12:tid 140612642301696] [remote 128.211.233.228:45305]   File "/usr/local/lib/python2.7/dist-packages/flask_cors/extension.py", line 161, in wrapped_function
[Sat Dec 03 15:46:56.286957 2016] [wsgi:error] [pid 12:tid 140612642301696] [remote 128.211.233.228:45305]     return cors_after_request(app.make_response(f(*args, **kwargs)))
[Sat Dec 03 15:46:56.287036 2016] [wsgi:error] [pid 12:tid 140612642301696] [remote 128.211.233.228:45305]   File "/usr/local/lib/python2.7/dist-packages/flask/app.py", line 1544, in handle_user_exception
[Sat Dec 03 15:46:56.287122 2016] [wsgi:error] [pid 12:tid 140612642301696] [remote 128.211.233.228:45305]     reraise(exc_type, exc_value, tb)
[Sat Dec 03 15:46:56.287188 2016] [wsgi:error] [pid 12:tid 140612642301696] [remote 128.211.233.228:45305]   File "/usr/local/lib/python2.7/dist-packages/flask_restful/__init__.py", line 268, in error_router
[Sat Dec 03 15:46:56.287268 2016] [wsgi:error] [pid 12:tid 140612642301696] [remote 128.211.233.228:45305]     return self.handle_error(e)
[Sat Dec 03 15:46:56.287334 2016] [wsgi:error] [pid 12:tid 140612642301696] [remote 128.211.233.228:45305]   File "/usr/local/lib/python2.7/dist-packages/flask/app.py", line 1639, in full_dispatch_request
[Sat Dec 03 15:46:56.287414 2016] [wsgi:error] [pid 12:tid 140612642301696] [remote 128.211.233.228:45305]     rv = self.dispatch_request()
[Sat Dec 03 15:46:56.287480 2016] [wsgi:error] [pid 12:tid 140612642301696] [remote 128.211.233.228:45305]   File "/usr/local/lib/python2.7/dist-packages/flask/app.py", line 1625, in dispatch_request
[Sat Dec 03 15:46:56.287578 2016] [wsgi:error] [pid 12:tid 140612642301696] [remote 128.211.233.228:45305]     return self.view_functions[rule.endpoint](**req.view_args)
[Sat Dec 03 15:46:56.287677 2016] [wsgi:error] [pid 12:tid 140612642301696] [remote 128.211.233.228:45305]   File "/usr/local/lib/python2.7/dist-packages/flask_restful/__init__.py", line 477, in wrapper
[Sat Dec 03 15:46:56.287782 2016] [wsgi:error] [pid 12:tid 140612642301696] [remote 128.211.233.228:45305]     resp = resource(*args, **kwargs)
[Sat Dec 03 15:46:56.287866 2016] [wsgi:error] [pid 12:tid 140612642301696] [remote 128.211.233.228:45305]   File "/usr/local/lib/python2.7/dist-packages/flask/views.py", line 84, in view
[Sat Dec 03 15:46:56.287983 2016] [wsgi:error] [pid 12:tid 140612642301696] [remote 128.211.233.228:45305]     return self.dispatch_request(*args, **kwargs)
[Sat Dec 03 15:46:56.288054 2016] [wsgi:error] [pid 12:tid 140612642301696] [remote 128.211.233.228:45305]   File "/usr/local/lib/python2.7/dist-packages/flask_restful/__init__.py", line 587, in dispatch_request
[Sat Dec 03 15:46:56.288152 2016] [wsgi:error] [pid 12:tid 140612642301696] [remote 128.211.233.228:45305]     resp = meth(*args, **kwargs)
[Sat Dec 03 15:46:56.288224 2016] [wsgi:error] [pid 12:tid 140612642301696] [remote 128.211.233.228:45305]   File "/srv/www/app/main.py", line 171, in put
[Sat Dec 03 15:46:56.288391 2016] [wsgi:error] [pid 12:tid 140612642301696] [remote 128.211.233.228:45305]     for idx, val in enumerate(dataOld):
[Sat Dec 03 15:46:56.288555 2016] [wsgi:error] [pid 12:tid 140612642301696] [remote 128.211.233.228:45305] TypeError: 'NoneType' object is not iterable
[Sat Dec 03 15:46:57.771742 2016] [wsgi:error] [pid 12:tid 140612625491712] [remote 128.211.233.228:45561] mod_wsgi (pid=12): Exception occurred processing WSGI script '/srv/www/app/apache/apache.wsgi'.
[Sat Dec 03 15:46:57.771924 2016] [wsgi:error] [pid 12:tid 140612625491712] [remote 128.211.233.228:45561] Traceback (most recent call last):
[Sat Dec 03 15:46:57.772017 2016] [wsgi:error] [pid 12:tid 140612625491712] [remote 128.211.233.228:45561]   File "/usr/local/lib/python2.7/dist-packages/flask/app.py", line 2000, in __call__
[Sat Dec 03 15:46:57.772129 2016] [wsgi:error] [pid 12:tid 140612625491712] [remote 128.211.233.228:45561]     return self.wsgi_app(environ, start_response)
[Sat Dec 03 15:46:57.772200 2016] [wsgi:error] [pid 12:tid 140612625491712] [remote 128.211.233.228:45561]   File "/usr/local/lib/python2.7/dist-packages/flask/app.py", line 1991, in wsgi_app
[Sat Dec 03 15:46:57.772321 2016] [wsgi:error] [pid 12:tid 140612625491712] [remote 128.211.233.228:45561]     response = self.make_response(self.handle_exception(e))
[Sat Dec 03 15:46:57.772393 2016] [wsgi:error] [pid 12:tid 140612625491712] [remote 128.211.233.228:45561]   File "/usr/local/lib/python2.7/dist-packages/flask_restful/__init__.py", line 271, in error_router
[Sat Dec 03 15:46:57.772480 2016] [wsgi:error] [pid 12:tid 140612625491712] [remote 128.211.233.228:45561]     return original_handler(e)
[Sat Dec 03 15:46:57.772576 2016] [wsgi:error] [pid 12:tid 140612625491712] [remote 128.211.233.228:45561]   File "/usr/local/lib/python2.7/dist-packages/flask_cors/extension.py", line 161, in wrapped_function
[Sat Dec 03 15:46:57.772669 2016] [wsgi:error] [pid 12:tid 140612625491712] [remote 128.211.233.228:45561]     return cors_after_request(app.make_response(f(*args, **kwargs)))
[Sat Dec 03 15:46:57.772735 2016] [wsgi:error] [pid 12:tid 140612625491712] [remote 128.211.233.228:45561]   File "/usr/local/lib/python2.7/dist-packages/flask/app.py", line 1567, in handle_exception
[Sat Dec 03 15:46:57.772816 2016] [wsgi:error] [pid 12:tid 140612625491712] [remote 128.211.233.228:45561]     reraise(exc_type, exc_value, tb)
[Sat Dec 03 15:46:57.772881 2016] [wsgi:error] [pid 12:tid 140612625491712] [remote 128.211.233.228:45561]   File "/usr/local/lib/python2.7/dist-packages/flask_restful/__init__.py", line 268, in error_router
[Sat Dec 03 15:46:57.772962 2016] [wsgi:error] [pid 12:tid 140612625491712] [remote 128.211.233.228:45561]     return self.handle_error(e)
[Sat Dec 03 15:46:57.773027 2016] [wsgi:error] [pid 12:tid 140612625491712] [remote 128.211.233.228:45561]   File "/usr/local/lib/python2.7/dist-packages/flask/app.py", line 1988, in wsgi_app
[Sat Dec 03 15:46:57.773109 2016] [wsgi:error] [pid 12:tid 140612625491712] [remote 128.211.233.228:45561]     response = self.full_dispatch_request()
[Sat Dec 03 15:46:57.773183 2016] [wsgi:error] [pid 12:tid 140612625491712] [remote 128.211.233.228:45561]   File "/usr/local/lib/python2.7/dist-packages/flask/app.py", line 1641, in full_dispatch_request
[Sat Dec 03 15:46:57.773289 2016] [wsgi:error] [pid 12:tid 140612625491712] [remote 128.211.233.228:45561]     rv = self.handle_user_exception(e)
[Sat Dec 03 15:46:57.773355 2016] [wsgi:error] [pid 12:tid 140612625491712] [remote 128.211.233.228:45561]   File "/usr/local/lib/python2.7/dist-packages/flask_restful/__init__.py", line 271, in error_router
[Sat Dec 03 15:46:57.773437 2016] [wsgi:error] [pid 12:tid 140612625491712] [remote 128.211.233.228:45561]     return original_handler(e)
[Sat Dec 03 15:46:57.773523 2016] [wsgi:error] [pid 12:tid 140612625491712] [remote 128.211.233.228:45561]   File "/usr/local/lib/python2.7/dist-packages/flask_cors/extension.py", line 161, in wrapped_function
[Sat Dec 03 15:46:57.773615 2016] [wsgi:error] [pid 12:tid 140612625491712] [remote 128.211.233.228:45561]     return cors_after_request(app.make_response(f(*args, **kwargs)))
[Sat Dec 03 15:46:57.773682 2016] [wsgi:error] [pid 12:tid 140612625491712] [remote 128.211.233.228:45561]   File "/usr/local/lib/python2.7/dist-packages/flask/app.py", line 1544, in handle_user_exception
[Sat Dec 03 15:46:57.773764 2016] [wsgi:error] [pid 12:tid 140612625491712] [remote 128.211.233.228:45561]     reraise(exc_type, exc_value, tb)
[Sat Dec 03 15:46:57.773829 2016] [wsgi:error] [pid 12:tid 140612625491712] [remote 128.211.233.228:45561]   File "/usr/local/lib/python2.7/dist-packages/flask_restful/__init__.py", line 268, in error_router
[Sat Dec 03 15:46:57.773911 2016] [wsgi:error] [pid 12:tid 140612625491712] [remote 128.211.233.228:45561]     return self.handle_error(e)
[Sat Dec 03 15:46:57.773976 2016] [wsgi:error] [pid 12:tid 140612625491712] [remote 128.211.233.228:45561]   File "/usr/local/lib/python2.7/dist-packages/flask/app.py", line 1639, in full_dispatch_request
[Sat Dec 03 15:46:57.774058 2016] [wsgi:error] [pid 12:tid 140612625491712] [remote 128.211.233.228:45561]     rv = self.dispatch_request()
[Sat Dec 03 15:46:57.774123 2016] [wsgi:error] [pid 12:tid 140612625491712] [remote 128.211.233.228:45561]   File "/usr/local/lib/python2.7/dist-packages/flask/app.py", line 1625, in dispatch_request
[Sat Dec 03 15:46:57.774255 2016] [wsgi:error] [pid 12:tid 140612625491712] [remote 128.211.233.228:45561]     return self.view_functions[rule.endpoint](**req.view_args)
[Sat Dec 03 15:46:57.774326 2016] [wsgi:error] [pid 12:tid 140612625491712] [remote 128.211.233.228:45561]   File "/usr/local/lib/python2.7/dist-packages/flask_restful/__init__.py", line 477, in wrapper
[Sat Dec 03 15:46:57.774410 2016] [wsgi:error] [pid 12:tid 140612625491712] [remote 128.211.233.228:45561]     resp = resource(*args, **kwargs)
[Sat Dec 03 15:46:57.774476 2016] [wsgi:error] [pid 12:tid 140612625491712] [remote 128.211.233.228:45561]   File "/usr/local/lib/python2.7/dist-packages/flask/views.py", line 84, in view
[Sat Dec 03 15:46:57.774558 2016] [wsgi:error] [pid 12:tid 140612625491712] [remote 128.211.233.228:45561]     return self.dispatch_request(*args, **kwargs)
[Sat Dec 03 15:46:57.774624 2016] [wsgi:error] [pid 12:tid 140612625491712] [remote 128.211.233.228:45561]   File "/usr/local/lib/python2.7/dist-packages/flask_restful/__init__.py", line 587, in dispatch_request
[Sat Dec 03 15:46:57.774706 2016] [wsgi:error] [pid 12:tid 140612625491712] [remote 128.211.233.228:45561]     resp = meth(*args, **kwargs)
[Sat Dec 03 15:46:57.774772 2016] [wsgi:error] [pid 12:tid 140612625491712] [remote 128.211.233.228:45561]   File "/srv/www/app/main.py", line 171, in put
[Sat Dec 03 15:46:57.774900 2016] [wsgi:error] [pid 12:tid 140612625491712] [remote 128.211.233.228:45561]     for idx, val in enumerate(dataOld):
[Sat Dec 03 15:46:57.774995 2016] [wsgi:error] [pid 12:tid 140612625491712] [remote 128.211.233.228:45561] TypeError: 'NoneType' object is not iterable
[Sat Dec 03 15:46:59.038941 2016] [wsgi:error] [pid 12:tid 140612642301696] [remote 128.211.233.228:45817] mod_wsgi (pid=12): Exception occurred processing WSGI script '/srv/www/app/apache/apache.wsgi'.
[Sat Dec 03 15:46:59.039138 2016] [wsgi:error] [pid 12:tid 140612642301696] [remote 128.211.233.228:45817] Traceback (most recent call last):
[Sat Dec 03 15:46:59.039236 2016] [wsgi:error] [pid 12:tid 140612642301696] [remote 128.211.233.228:45817]   File "/usr/local/lib/python2.7/dist-packages/flask/app.py", line 2000, in __call__
[Sat Dec 03 15:46:59.039352 2016] [wsgi:error] [pid 12:tid 140612642301696] [remote 128.211.233.228:45817]     return self.wsgi_app(environ, start_response)
[Sat Dec 03 15:46:59.039424 2016] [wsgi:error] [pid 12:tid 140612642301696] [remote 128.211.233.228:45817]   File "/usr/local/lib/python2.7/dist-packages/flask/app.py", line 1991, in wsgi_app
[Sat Dec 03 15:46:59.039512 2016] [wsgi:error] [pid 12:tid 140612642301696] [remote 128.211.233.228:45817]     response = self.make_response(self.handle_exception(e))
[Sat Dec 03 15:46:59.039580 2016] [wsgi:error] [pid 12:tid 140612642301696] [remote 128.211.233.228:45817]   File "/usr/local/lib/python2.7/dist-packages/flask_restful/__init__.py", line 271, in error_router
[Sat Dec 03 15:46:59.039667 2016] [wsgi:error] [pid 12:tid 140612642301696] [remote 128.211.233.228:45817]     return original_handler(e)
[Sat Dec 03 15:46:59.039732 2016] [wsgi:error] [pid 12:tid 140612642301696] [remote 128.211.233.228:45817]   File "/usr/local/lib/python2.7/dist-packages/flask_cors/extension.py", line 161, in wrapped_function
[Sat Dec 03 15:46:59.039816 2016] [wsgi:error] [pid 12:tid 140612642301696] [remote 128.211.233.228:45817]     return cors_after_request(app.make_response(f(*args, **kwargs)))
[Sat Dec 03 15:46:59.039882 2016] [wsgi:error] [pid 12:tid 140612642301696] [remote 128.211.233.228:45817]   File "/usr/local/lib/python2.7/dist-packages/flask/app.py", line 1567, in handle_exception
[Sat Dec 03 15:46:59.039964 2016] [wsgi:error] [pid 12:tid 140612642301696] [remote 128.211.233.228:45817]     reraise(exc_type, exc_value, tb)
[Sat Dec 03 15:46:59.040028 2016] [wsgi:error] [pid 12:tid 140612642301696] [remote 128.211.233.228:45817]   File "/usr/local/lib/python2.7/dist-packages/flask_restful/__init__.py", line 268, in error_router
[Sat Dec 03 15:46:59.040165 2016] [wsgi:error] [pid 12:tid 140612642301696] [remote 128.211.233.228:45817]     return self.handle_error(e)
[Sat Dec 03 15:46:59.040236 2016] [wsgi:error] [pid 12:tid 140612642301696] [remote 128.211.233.228:45817]   File "/usr/local/lib/python2.7/dist-packages/flask/app.py", line 1988, in wsgi_app
[Sat Dec 03 15:46:59.040320 2016] [wsgi:error] [pid 12:tid 140612642301696] [remote 128.211.233.228:45817]     response = self.full_dispatch_request()
[Sat Dec 03 15:46:59.040385 2016] [wsgi:error] [pid 12:tid 140612642301696] [remote 128.211.233.228:45817]   File "/usr/local/lib/python2.7/dist-packages/flask/app.py", line 1641, in full_dispatch_request
[Sat Dec 03 15:46:59.040468 2016] [wsgi:error] [pid 12:tid 140612642301696] [remote 128.211.233.228:45817]     rv = self.handle_user_exception(e)
[Sat Dec 03 15:46:59.040533 2016] [wsgi:error] [pid 12:tid 140612642301696] [remote 128.211.233.228:45817]   File "/usr/local/lib/python2.7/dist-packages/flask_restful/__init__.py", line 271, in error_router
[Sat Dec 03 15:46:59.040614 2016] [wsgi:error] [pid 12:tid 140612642301696] [remote 128.211.233.228:45817]     return original_handler(e)
[Sat Dec 03 15:46:59.040700 2016] [wsgi:error] [pid 12:tid 140612642301696] [remote 128.211.233.228:45817]   File "/usr/local/lib/python2.7/dist-packages/flask_cors/extension.py", line 161, in wrapped_function
[Sat Dec 03 15:46:59.040800 2016] [wsgi:error] [pid 12:tid 140612642301696] [remote 128.211.233.228:45817]     return cors_after_request(app.make_response(f(*args, **kwargs)))
[Sat Dec 03 15:46:59.040868 2016] [wsgi:error] [pid 12:tid 140612642301696] [remote 128.211.233.228:45817]   File "/usr/local/lib/python2.7/dist-packages/flask/app.py", line 1544, in handle_user_exception
[Sat Dec 03 15:46:59.040950 2016] [wsgi:error] [pid 12:tid 140612642301696] [remote 128.211.233.228:45817]     reraise(exc_type, exc_value, tb)
[Sat Dec 03 15:46:59.041015 2016] [wsgi:error] [pid 12:tid 140612642301696] [remote 128.211.233.228:45817]   File "/usr/local/lib/python2.7/dist-packages/flask_restful/__init__.py", line 268, in error_router
[Sat Dec 03 15:46:59.041097 2016] [wsgi:error] [pid 12:tid 140612642301696] [remote 128.211.233.228:45817]     return self.handle_error(e)
[Sat Dec 03 15:46:59.041162 2016] [wsgi:error] [pid 12:tid 140612642301696] [remote 128.211.233.228:45817]   File "/usr/local/lib/python2.7/dist-packages/flask/app.py", line 1639, in full_dispatch_request
[Sat Dec 03 15:46:59.041313 2016] [wsgi:error] [pid 12:tid 140612642301696] [remote 128.211.233.228:45817]     rv = self.dispatch_request()
[Sat Dec 03 15:46:59.041384 2016] [wsgi:error] [pid 12:tid 140612642301696] [remote 128.211.233.228:45817]   File "/usr/local/lib/python2.7/dist-packages/flask/app.py", line 1625, in dispatch_request
[Sat Dec 03 15:46:59.041469 2016] [wsgi:error] [pid 12:tid 140612642301696] [remote 128.211.233.228:45817]     return self.view_functions[rule.endpoint](**req.view_args)
[Sat Dec 03 15:46:59.041564 2016] [wsgi:error] [pid 12:tid 140612642301696] [remote 128.211.233.228:45817]   File "/usr/local/lib/python2.7/dist-packages/flask_restful/__init__.py", line 477, in wrapper
[Sat Dec 03 15:46:59.041653 2016] [wsgi:error] [pid 12:tid 140612642301696] [remote 128.211.233.228:45817]     resp = resource(*args, **kwargs)
[Sat Dec 03 15:46:59.041720 2016] [wsgi:error] [pid 12:tid 140612642301696] [remote 128.211.233.228:45817]   File "/usr/local/lib/python2.7/dist-packages/flask/views.py", line 84, in view
[Sat Dec 03 15:46:59.041805 2016] [wsgi:error] [pid 12:tid 140612642301696] [remote 128.211.233.228:45817]     return self.dispatch_request(*args, **kwargs)
[Sat Dec 03 15:46:59.041871 2016] [wsgi:error] [pid 12:tid 140612642301696] [remote 128.211.233.228:45817]   File "/usr/local/lib/python2.7/dist-packages/flask_restful/__init__.py", line 587, in dispatch_request
[Sat Dec 03 15:46:59.041955 2016] [wsgi:error] [pid 12:tid 140612642301696] [remote 128.211.233.228:45817]     resp = meth(*args, **kwargs)
[Sat Dec 03 15:46:59.042091 2016] [wsgi:error] [pid 12:tid 140612642301696] [remote 128.211.233.228:45817]   File "/srv/www/app/main.py", line 171, in put
[Sat Dec 03 15:46:59.042184 2016] [wsgi:error] [pid 12:tid 140612642301696] [remote 128.211.233.228:45817]     for idx, val in enumerate(dataOld):
[Sat Dec 03 15:46:59.042267 2016] [wsgi:error] [pid 12:tid 140612642301696] [remote 128.211.233.228:45817] TypeError: 'NoneType' object is not iterable
[Sat Dec 03 15:47:00.427008 2016] [wsgi:error] [pid 12:tid 140612625491712] [remote 128.211.233.228:45305] mod_wsgi (pid=12): Exception occurred processing WSGI script '/srv/www/app/apache/apache.wsgi'.
[Sat Dec 03 15:47:00.427166 2016] [wsgi:error] [pid 12:tid 140612625491712] [remote 128.211.233.228:45305] Traceback (most recent call last):
[Sat Dec 03 15:47:00.427260 2016] [wsgi:error] [pid 12:tid 140612625491712] [remote 128.211.233.228:45305]   File "/usr/local/lib/python2.7/dist-packages/flask/app.py", line 2000, in __call__
[Sat Dec 03 15:47:00.427376 2016] [wsgi:error] [pid 12:tid 140612625491712] [remote 128.211.233.228:45305]     return self.wsgi_app(environ, start_response)
[Sat Dec 03 15:47:00.427447 2016] [wsgi:error] [pid 12:tid 140612625491712] [remote 128.211.233.228:45305]   File "/usr/local/lib/python2.7/dist-packages/flask/app.py", line 1991, in wsgi_app
[Sat Dec 03 15:47:00.427531 2016] [wsgi:error] [pid 12:tid 140612625491712] [remote 128.211.233.228:45305]     response = self.make_response(self.handle_exception(e))
[Sat Dec 03 15:47:00.427599 2016] [wsgi:error] [pid 12:tid 140612625491712] [remote 128.211.233.228:45305]   File "/usr/local/lib/python2.7/dist-packages/flask_restful/__init__.py", line 271, in error_router
[Sat Dec 03 15:47:00.427717 2016] [wsgi:error] [pid 12:tid 140612625491712] [remote 128.211.233.228:45305]     return original_handler(e)
[Sat Dec 03 15:47:00.427788 2016] [wsgi:error] [pid 12:tid 140612625491712] [remote 128.211.233.228:45305]   File "/usr/local/lib/python2.7/dist-packages/flask_cors/extension.py", line 161, in wrapped_function
[Sat Dec 03 15:47:00.427874 2016] [wsgi:error] [pid 12:tid 140612625491712] [remote 128.211.233.228:45305]     return cors_after_request(app.make_response(f(*args, **kwargs)))
[Sat Dec 03 15:47:00.427940 2016] [wsgi:error] [pid 12:tid 140612625491712] [remote 128.211.233.228:45305]   File "/usr/local/lib/python2.7/dist-packages/flask/app.py", line 1567, in handle_exception
[Sat Dec 03 15:47:00.428021 2016] [wsgi:error] [pid 12:tid 140612625491712] [remote 128.211.233.228:45305]     reraise(exc_type, exc_value, tb)
[Sat Dec 03 15:47:00.428087 2016] [wsgi:error] [pid 12:tid 140612625491712] [remote 128.211.233.228:45305]   File "/usr/local/lib/python2.7/dist-packages/flask_restful/__init__.py", line 268, in error_router
[Sat Dec 03 15:47:00.428169 2016] [wsgi:error] [pid 12:tid 140612625491712] [remote 128.211.233.228:45305]     return self.handle_error(e)
[Sat Dec 03 15:47:00.428261 2016] [wsgi:error] [pid 12:tid 140612625491712] [remote 128.211.233.228:45305]   File "/usr/local/lib/python2.7/dist-packages/flask/app.py", line 1988, in wsgi_app
[Sat Dec 03 15:47:00.428356 2016] [wsgi:error] [pid 12:tid 140612625491712] [remote 128.211.233.228:45305]     response = self.full_dispatch_request()
[Sat Dec 03 15:47:00.428422 2016] [wsgi:error] [pid 12:tid 140612625491712] [remote 128.211.233.228:45305]   File "/usr/local/lib/python2.7/dist-packages/flask/app.py", line 1641, in full_dispatch_request
[Sat Dec 03 15:47:00.428504 2016] [wsgi:error] [pid 12:tid 140612625491712] [remote 128.211.233.228:45305]     rv = self.handle_user_exception(e)
[Sat Dec 03 15:47:00.428569 2016] [wsgi:error] [pid 12:tid 140612625491712] [remote 128.211.233.228:45305]   File "/usr/local/lib/python2.7/dist-packages/flask_restful/__init__.py", line 271, in error_router
[Sat Dec 03 15:47:00.428649 2016] [wsgi:error] [pid 12:tid 140612625491712] [remote 128.211.233.228:45305]     return original_handler(e)
[Sat Dec 03 15:47:00.428715 2016] [wsgi:error] [pid 12:tid 140612625491712] [remote 128.211.233.228:45305]   File "/usr/local/lib/python2.7/dist-packages/flask_cors/extension.py", line 161, in wrapped_function
[Sat Dec 03 15:47:00.428828 2016] [wsgi:error] [pid 12:tid 140612625491712] [remote 128.211.233.228:45305]     return cors_after_request(app.make_response(f(*args, **kwargs)))
[Sat Dec 03 15:47:00.428898 2016] [wsgi:error] [pid 12:tid 140612625491712] [remote 128.211.233.228:45305]   File "/usr/local/lib/python2.7/dist-packages/flask/app.py", line 1544, in handle_user_exception
[Sat Dec 03 15:47:00.428981 2016] [wsgi:error] [pid 12:tid 140612625491712] [remote 128.211.233.228:45305]     reraise(exc_type, exc_value, tb)
[Sat Dec 03 15:47:00.429046 2016] [wsgi:error] [pid 12:tid 140612625491712] [remote 128.211.233.228:45305]   File "/usr/local/lib/python2.7/dist-packages/flask_restful/__init__.py", line 268, in error_router
[Sat Dec 03 15:47:00.429129 2016] [wsgi:error] [pid 12:tid 140612625491712] [remote 128.211.233.228:45305]     return self.handle_error(e)
[Sat Dec 03 15:47:00.429194 2016] [wsgi:error] [pid 12:tid 140612625491712] [remote 128.211.233.228:45305]   File "/usr/local/lib/python2.7/dist-packages/flask/app.py", line 1639, in full_dispatch_request
[Sat Dec 03 15:47:00.429274 2016] [wsgi:error] [pid 12:tid 140612625491712] [remote 128.211.233.228:45305]     rv = self.dispatch_request()
[Sat Dec 03 15:47:00.429340 2016] [wsgi:error] [pid 12:tid 140612625491712] [remote 128.211.233.228:45305]   File "/usr/local/lib/python2.7/dist-packages/flask/app.py", line 1625, in dispatch_request
[Sat Dec 03 15:47:00.429422 2016] [wsgi:error] [pid 12:tid 140612625491712] [remote 128.211.233.228:45305]     return self.view_functions[rule.endpoint](**req.view_args)
[Sat Dec 03 15:47:00.429488 2016] [wsgi:error] [pid 12:tid 140612625491712] [remote 128.211.233.228:45305]   File "/usr/local/lib/python2.7/dist-packages/flask_restful/__init__.py", line 477, in wrapper
[Sat Dec 03 15:47:00.429603 2016] [wsgi:error] [pid 12:tid 140612625491712] [remote 128.211.233.228:45305]     resp = resource(*args, **kwargs)
[Sat Dec 03 15:47:00.429672 2016] [wsgi:error] [pid 12:tid 140612625491712] [remote 128.211.233.228:45305]   File "/usr/local/lib/python2.7/dist-packages/flask/views.py", line 84, in view
[Sat Dec 03 15:47:00.429757 2016] [wsgi:error] [pid 12:tid 140612625491712] [remote 128.211.233.228:45305]     return self.dispatch_request(*args, **kwargs)
[Sat Dec 03 15:47:00.429824 2016] [wsgi:error] [pid 12:tid 140612625491712] [remote 128.211.233.228:45305]   File "/usr/local/lib/python2.7/dist-packages/flask_restful/__init__.py", line 587, in dispatch_request
[Sat Dec 03 15:47:00.429908 2016] [wsgi:error] [pid 12:tid 140612625491712] [remote 128.211.233.228:45305]     resp = meth(*args, **kwargs)
[Sat Dec 03 15:47:00.429974 2016] [wsgi:error] [pid 12:tid 140612625491712] [remote 128.211.233.228:45305]   File "/srv/www/app/main.py", line 171, in put
[Sat Dec 03 15:47:00.430074 2016] [wsgi:error] [pid 12:tid 140612625491712] [remote 128.211.233.228:45305]     for idx, val in enumerate(dataOld):
[Sat Dec 03 15:47:00.430168 2016] [wsgi:error] [pid 12:tid 140612625491712] [remote 128.211.233.228:45305] TypeError: 'NoneType' object is not iterable
[Sat Dec 03 15:49:55.523019 2016] [wsgi:error] [pid 12:tid 140612625491712] [remote 128.211.233.228:45305] mod_wsgi (pid=12): Exception occurred processing WSGI script '/srv/www/app/apache/apache.wsgi'.
[Sat Dec 03 15:49:55.523411 2016] [wsgi:error] [pid 12:tid 140612625491712] [remote 128.211.233.228:45305] Traceback (most recent call last):
[Sat Dec 03 15:49:55.523549 2016] [wsgi:error] [pid 12:tid 140612625491712] [remote 128.211.233.228:45305]   File "/usr/local/lib/python2.7/dist-packages/flask/app.py", line 2000, in __call__
[Sat Dec 03 15:49:55.523987 2016] [wsgi:error] [pid 12:tid 140612625491712] [remote 128.211.233.228:45305]     return self.wsgi_app(environ, start_response)
[Sat Dec 03 15:49:55.524085 2016] [wsgi:error] [pid 12:tid 140612625491712] [remote 128.211.233.228:45305]   File "/usr/local/lib/python2.7/dist-packages/flask/app.py", line 1991, in wsgi_app
[Sat Dec 03 15:49:55.524200 2016] [wsgi:error] [pid 12:tid 140612625491712] [remote 128.211.233.228:45305]     response = self.make_response(self.handle_exception(e))
[Sat Dec 03 15:49:55.524311 2016] [wsgi:error] [pid 12:tid 140612625491712] [remote 128.211.233.228:45305]   File "/usr/local/lib/python2.7/dist-packages/flask_restful/__init__.py", line 271, in error_router
[Sat Dec 03 15:49:55.524437 2016] [wsgi:error] [pid 12:tid 140612625491712] [remote 128.211.233.228:45305]     return original_handler(e)
[Sat Dec 03 15:49:55.524510 2016] [wsgi:error] [pid 12:tid 140612625491712] [remote 128.211.233.228:45305]   File "/usr/local/lib/python2.7/dist-packages/flask_cors/extension.py", line 161, in wrapped_function
[Sat Dec 03 15:49:55.524632 2016] [wsgi:error] [pid 12:tid 140612625491712] [remote 128.211.233.228:45305]     return cors_after_request(app.make_response(f(*args, **kwargs)))
[Sat Dec 03 15:49:55.524704 2016] [wsgi:error] [pid 12:tid 140612625491712] [remote 128.211.233.228:45305]   File "/usr/local/lib/python2.7/dist-packages/flask/app.py", line 1567, in handle_exception
[Sat Dec 03 15:49:55.524809 2016] [wsgi:error] [pid 12:tid 140612625491712] [remote 128.211.233.228:45305]     reraise(exc_type, exc_value, tb)
[Sat Dec 03 15:49:55.524880 2016] [wsgi:error] [pid 12:tid 140612625491712] [remote 128.211.233.228:45305]   File "/usr/local/lib/python2.7/dist-packages/flask_restful/__init__.py", line 268, in error_router
[Sat Dec 03 15:49:55.524980 2016] [wsgi:error] [pid 12:tid 140612625491712] [remote 128.211.233.228:45305]     return self.handle_error(e)
[Sat Dec 03 15:49:55.525052 2016] [wsgi:error] [pid 12:tid 140612625491712] [remote 128.211.233.228:45305]   File "/usr/local/lib/python2.7/dist-packages/flask/app.py", line 1988, in wsgi_app
[Sat Dec 03 15:49:55.525138 2016] [wsgi:error] [pid 12:tid 140612625491712] [remote 128.211.233.228:45305]     response = self.full_dispatch_request()
[Sat Dec 03 15:49:55.525205 2016] [wsgi:error] [pid 12:tid 140612625491712] [remote 128.211.233.228:45305]   File "/usr/local/lib/python2.7/dist-packages/flask/app.py", line 1641, in full_dispatch_request
[Sat Dec 03 15:49:55.525288 2016] [wsgi:error] [pid 12:tid 140612625491712] [remote 128.211.233.228:45305]     rv = self.handle_user_exception(e)
[Sat Dec 03 15:49:55.525354 2016] [wsgi:error] [pid 12:tid 140612625491712] [remote 128.211.233.228:45305]   File "/usr/local/lib/python2.7/dist-packages/flask_restful/__init__.py", line 271, in error_router
[Sat Dec 03 15:49:55.525435 2016] [wsgi:error] [pid 12:tid 140612625491712] [remote 128.211.233.228:45305]     return original_handler(e)
[Sat Dec 03 15:49:55.525501 2016] [wsgi:error] [pid 12:tid 140612625491712] [remote 128.211.233.228:45305]   File "/usr/local/lib/python2.7/dist-packages/flask_cors/extension.py", line 161, in wrapped_function
[Sat Dec 03 15:49:55.525583 2016] [wsgi:error] [pid 12:tid 140612625491712] [remote 128.211.233.228:45305]     return cors_after_request(app.make_response(f(*args, **kwargs)))
[Sat Dec 03 15:49:55.525648 2016] [wsgi:error] [pid 12:tid 140612625491712] [remote 128.211.233.228:45305]   File "/usr/local/lib/python2.7/dist-packages/flask/app.py", line 1544, in handle_user_exception
[Sat Dec 03 15:49:55.525754 2016] [wsgi:error] [pid 12:tid 140612625491712] [remote 128.211.233.228:45305]     reraise(exc_type, exc_value, tb)
[Sat Dec 03 15:49:55.525827 2016] [wsgi:error] [pid 12:tid 140612625491712] [remote 128.211.233.228:45305]   File "/usr/local/lib/python2.7/dist-packages/flask_restful/__init__.py", line 268, in error_router
[Sat Dec 03 15:49:55.525912 2016] [wsgi:error] [pid 12:tid 140612625491712] [remote 128.211.233.228:45305]     return self.handle_error(e)
[Sat Dec 03 15:49:55.525977 2016] [wsgi:error] [pid 12:tid 140612625491712] [remote 128.211.233.228:45305]   File "/usr/local/lib/python2.7/dist-packages/flask/app.py", line 1639, in full_dispatch_request
[Sat Dec 03 15:49:55.526061 2016] [wsgi:error] [pid 12:tid 140612625491712] [remote 128.211.233.228:45305]     rv = self.dispatch_request()
[Sat Dec 03 15:49:55.526127 2016] [wsgi:error] [pid 12:tid 140612625491712] [remote 128.211.233.228:45305]   File "/usr/local/lib/python2.7/dist-packages/flask/app.py", line 1625, in dispatch_request
[Sat Dec 03 15:49:55.526245 2016] [wsgi:error] [pid 12:tid 140612625491712] [remote 128.211.233.228:45305]     return self.view_functions[rule.endpoint](**req.view_args)
[Sat Dec 03 15:49:55.526319 2016] [wsgi:error] [pid 12:tid 140612625491712] [remote 128.211.233.228:45305]   File "/usr/local/lib/python2.7/dist-packages/flask_restful/__init__.py", line 477, in wrapper
[Sat Dec 03 15:49:55.526418 2016] [wsgi:error] [pid 12:tid 140612625491712] [remote 128.211.233.228:45305]     resp = resource(*args, **kwargs)
[Sat Dec 03 15:49:55.526502 2016] [wsgi:error] [pid 12:tid 140612625491712] [remote 128.211.233.228:45305]   File "/usr/local/lib/python2.7/dist-packages/flask/views.py", line 84, in view
[Sat Dec 03 15:49:55.526623 2016] [wsgi:error] [pid 12:tid 140612625491712] [remote 128.211.233.228:45305]     return self.dispatch_request(*args, **kwargs)
[Sat Dec 03 15:49:55.526697 2016] [wsgi:error] [pid 12:tid 140612625491712] [remote 128.211.233.228:45305]   File "/usr/local/lib/python2.7/dist-packages/flask_restful/__init__.py", line 587, in dispatch_request
[Sat Dec 03 15:49:55.526796 2016] [wsgi:error] [pid 12:tid 140612625491712] [remote 128.211.233.228:45305]     resp = meth(*args, **kwargs)
[Sat Dec 03 15:49:55.526922 2016] [wsgi:error] [pid 12:tid 140612625491712] [remote 128.211.233.228:45305]   File "/srv/www/app/main.py", line 171, in put
[Sat Dec 03 15:49:55.527051 2016] [wsgi:error] [pid 12:tid 140612625491712] [remote 128.211.233.228:45305]     for idx, val in enumerate(dataOld):
[Sat Dec 03 15:49:55.527203 2016] [wsgi:error] [pid 12:tid 140612625491712] [remote 128.211.233.228:45305] TypeError: 'NoneType' object is not iterable
[Sat Dec 03 15:49:56.596744 2016] [wsgi:error] [pid 12:tid 140612642301696] [remote 128.211.233.228:45561] mod_wsgi (pid=12): Exception occurred processing WSGI script '/srv/www/app/apache/apache.wsgi'.
[Sat Dec 03 15:49:56.596925 2016] [wsgi:error] [pid 12:tid 140612642301696] [remote 128.211.233.228:45561] Traceback (most recent call last):
[Sat Dec 03 15:49:56.597018 2016] [wsgi:error] [pid 12:tid 140612642301696] [remote 128.211.233.228:45561]   File "/usr/local/lib/python2.7/dist-packages/flask/app.py", line 2000, in __call__
[Sat Dec 03 15:49:56.597134 2016] [wsgi:error] [pid 12:tid 140612642301696] [remote 128.211.233.228:45561]     return self.wsgi_app(environ, start_response)
[Sat Dec 03 15:49:56.597206 2016] [wsgi:error] [pid 12:tid 140612642301696] [remote 128.211.233.228:45561]   File "/usr/local/lib/python2.7/dist-packages/flask/app.py", line 1991, in wsgi_app
[Sat Dec 03 15:49:56.597295 2016] [wsgi:error] [pid 12:tid 140612642301696] [remote 128.211.233.228:45561]     response = self.make_response(self.handle_exception(e))
[Sat Dec 03 15:49:56.597363 2016] [wsgi:error] [pid 12:tid 140612642301696] [remote 128.211.233.228:45561]   File "/usr/local/lib/python2.7/dist-packages/flask_restful/__init__.py", line 271, in error_router
[Sat Dec 03 15:49:56.597450 2016] [wsgi:error] [pid 12:tid 140612642301696] [remote 128.211.233.228:45561]     return original_handler(e)
[Sat Dec 03 15:49:56.597517 2016] [wsgi:error] [pid 12:tid 140612642301696] [remote 128.211.233.228:45561]   File "/usr/local/lib/python2.7/dist-packages/flask_cors/extension.py", line 161, in wrapped_function
[Sat Dec 03 15:49:56.597633 2016] [wsgi:error] [pid 12:tid 140612642301696] [remote 128.211.233.228:45561]     return cors_after_request(app.make_response(f(*args, **kwargs)))
[Sat Dec 03 15:49:56.597703 2016] [wsgi:error] [pid 12:tid 140612642301696] [remote 128.211.233.228:45561]   File "/usr/local/lib/python2.7/dist-packages/flask/app.py", line 1567, in handle_exception
[Sat Dec 03 15:49:56.597816 2016] [wsgi:error] [pid 12:tid 140612642301696] [remote 128.211.233.228:45561]     reraise(exc_type, exc_value, tb)
[Sat Dec 03 15:49:56.597885 2016] [wsgi:error] [pid 12:tid 140612642301696] [remote 128.211.233.228:45561]   File "/usr/local/lib/python2.7/dist-packages/flask_restful/__init__.py", line 268, in error_router
[Sat Dec 03 15:49:56.597999 2016] [wsgi:error] [pid 12:tid 140612642301696] [remote 128.211.233.228:45561]     return self.handle_error(e)
[Sat Dec 03 15:49:56.598067 2016] [wsgi:error] [pid 12:tid 140612642301696] [remote 128.211.233.228:45561]   File "/usr/local/lib/python2.7/dist-packages/flask/app.py", line 1988, in wsgi_app
[Sat Dec 03 15:49:56.598148 2016] [wsgi:error] [pid 12:tid 140612642301696] [remote 128.211.233.228:45561]     response = self.full_dispatch_request()
[Sat Dec 03 15:49:56.598214 2016] [wsgi:error] [pid 12:tid 140612642301696] [remote 128.211.233.228:45561]   File "/usr/local/lib/python2.7/dist-packages/flask/app.py", line 1641, in full_dispatch_request
[Sat Dec 03 15:49:56.598296 2016] [wsgi:error] [pid 12:tid 140612642301696] [remote 128.211.233.228:45561]     rv = self.handle_user_exception(e)
[Sat Dec 03 15:49:56.598360 2016] [wsgi:error] [pid 12:tid 140612642301696] [remote 128.211.233.228:45561]   File "/usr/local/lib/python2.7/dist-packages/flask_restful/__init__.py", line 271, in error_router
[Sat Dec 03 15:49:56.598441 2016] [wsgi:error] [pid 12:tid 140612642301696] [remote 128.211.233.228:45561]     return original_handler(e)
[Sat Dec 03 15:49:56.598505 2016] [wsgi:error] [pid 12:tid 140612642301696] [remote 128.211.233.228:45561]   File "/usr/local/lib/python2.7/dist-packages/flask_cors/extension.py", line 161, in wrapped_function
[Sat Dec 03 15:49:56.598586 2016] [wsgi:error] [pid 12:tid 140612642301696] [remote 128.211.233.228:45561]     return cors_after_request(app.make_response(f(*args, **kwargs)))
[Sat Dec 03 15:49:56.598650 2016] [wsgi:error] [pid 12:tid 140612642301696] [remote 128.211.233.228:45561]   File "/usr/local/lib/python2.7/dist-packages/flask/app.py", line 1544, in handle_user_exception
[Sat Dec 03 15:49:56.598731 2016] [wsgi:error] [pid 12:tid 140612642301696] [remote 128.211.233.228:45561]     reraise(exc_type, exc_value, tb)
[Sat Dec 03 15:49:56.598795 2016] [wsgi:error] [pid 12:tid 140612642301696] [remote 128.211.233.228:45561]   File "/usr/local/lib/python2.7/dist-packages/flask_restful/__init__.py", line 268, in error_router
[Sat Dec 03 15:49:56.598971 2016] [wsgi:error] [pid 12:tid 140612642301696] [remote 128.211.233.228:45561]     return self.handle_error(e)
[Sat Dec 03 15:49:56.599064 2016] [wsgi:error] [pid 12:tid 140612642301696] [remote 128.211.233.228:45561]   File "/usr/local/lib/python2.7/dist-packages/flask/app.py", line 1639, in full_dispatch_request
[Sat Dec 03 15:49:56.599153 2016] [wsgi:error] [pid 12:tid 140612642301696] [remote 128.211.233.228:45561]     rv = self.dispatch_request()
[Sat Dec 03 15:49:56.599219 2016] [wsgi:error] [pid 12:tid 140612642301696] [remote 128.211.233.228:45561]   File "/usr/local/lib/python2.7/dist-packages/flask/app.py", line 1625, in dispatch_request
[Sat Dec 03 15:49:56.599304 2016] [wsgi:error] [pid 12:tid 140612642301696] [remote 128.211.233.228:45561]     return self.view_functions[rule.endpoint](**req.view_args)
[Sat Dec 03 15:49:56.599372 2016] [wsgi:error] [pid 12:tid 140612642301696] [remote 128.211.233.228:45561]   File "/usr/local/lib/python2.7/dist-packages/flask_restful/__init__.py", line 477, in wrapper
[Sat Dec 03 15:49:56.599453 2016] [wsgi:error] [pid 12:tid 140612642301696] [remote 128.211.233.228:45561]     resp = resource(*args, **kwargs)
[Sat Dec 03 15:49:56.599519 2016] [wsgi:error] [pid 12:tid 140612642301696] [remote 128.211.233.228:45561]   File "/usr/local/lib/python2.7/dist-packages/flask/views.py", line 84, in view
[Sat Dec 03 15:49:56.599602 2016] [wsgi:error] [pid 12:tid 140612642301696] [remote 128.211.233.228:45561]     return self.dispatch_request(*args, **kwargs)
[Sat Dec 03 15:49:56.599666 2016] [wsgi:error] [pid 12:tid 140612642301696] [remote 128.211.233.228:45561]   File "/usr/local/lib/python2.7/dist-packages/flask_restful/__init__.py", line 587, in dispatch_request
[Sat Dec 03 15:49:56.599748 2016] [wsgi:error] [pid 12:tid 140612642301696] [remote 128.211.233.228:45561]     resp = meth(*args, **kwargs)
[Sat Dec 03 15:49:56.599813 2016] [wsgi:error] [pid 12:tid 140612642301696] [remote 128.211.233.228:45561]   File "/srv/www/app/main.py", line 171, in put
[Sat Dec 03 15:49:56.599916 2016] [wsgi:error] [pid 12:tid 140612642301696] [remote 128.211.233.228:45561]     for idx, val in enumerate(dataOld):
[Sat Dec 03 15:49:56.600000 2016] [wsgi:error] [pid 12:tid 140612642301696] [remote 128.211.233.228:45561] TypeError: 'NoneType' object is not iterable
[Sat Dec 03 15:49:57.590166 2016] [wsgi:error] [pid 12:tid 140612625491712] [remote 128.211.233.228:45305] mod_wsgi (pid=12): Exception occurred processing WSGI script '/srv/www/app/apache/apache.wsgi'.
[Sat Dec 03 15:49:57.590369 2016] [wsgi:error] [pid 12:tid 140612625491712] [remote 128.211.233.228:45305] Traceback (most recent call last):
[Sat Dec 03 15:49:57.590466 2016] [wsgi:error] [pid 12:tid 140612625491712] [remote 128.211.233.228:45305]   File "/usr/local/lib/python2.7/dist-packages/flask/app.py", line 2000, in __call__
[Sat Dec 03 15:49:57.590582 2016] [wsgi:error] [pid 12:tid 140612625491712] [remote 128.211.233.228:45305]     return self.wsgi_app(environ, start_response)
[Sat Dec 03 15:49:57.590655 2016] [wsgi:error] [pid 12:tid 140612625491712] [remote 128.211.233.228:45305]   File "/usr/local/lib/python2.7/dist-packages/flask/app.py", line 1991, in wsgi_app
[Sat Dec 03 15:49:57.590742 2016] [wsgi:error] [pid 12:tid 140612625491712] [remote 128.211.233.228:45305]     response = self.make_response(self.handle_exception(e))
[Sat Dec 03 15:49:57.590810 2016] [wsgi:error] [pid 12:tid 140612625491712] [remote 128.211.233.228:45305]   File "/usr/local/lib/python2.7/dist-packages/flask_restful/__init__.py", line 271, in error_router
[Sat Dec 03 15:49:57.590952 2016] [wsgi:error] [pid 12:tid 140612625491712] [remote 128.211.233.228:45305]     return original_handler(e)
[Sat Dec 03 15:49:57.591030 2016] [wsgi:error] [pid 12:tid 140612625491712] [remote 128.211.233.228:45305]   File "/usr/local/lib/python2.7/dist-packages/flask_cors/extension.py", line 161, in wrapped_function
[Sat Dec 03 15:49:57.591118 2016] [wsgi:error] [pid 12:tid 140612625491712] [remote 128.211.233.228:45305]     return cors_after_request(app.make_response(f(*args, **kwargs)))
[Sat Dec 03 15:49:57.591184 2016] [wsgi:error] [pid 12:tid 140612625491712] [remote 128.211.233.228:45305]   File "/usr/local/lib/python2.7/dist-packages/flask/app.py", line 1567, in handle_exception
[Sat Dec 03 15:49:57.591268 2016] [wsgi:error] [pid 12:tid 140612625491712] [remote 128.211.233.228:45305]     reraise(exc_type, exc_value, tb)
[Sat Dec 03 15:49:57.591334 2016] [wsgi:error] [pid 12:tid 140612625491712] [remote 128.211.233.228:45305]   File "/usr/local/lib/python2.7/dist-packages/flask_restful/__init__.py", line 268, in error_router
[Sat Dec 03 15:49:57.591415 2016] [wsgi:error] [pid 12:tid 140612625491712] [remote 128.211.233.228:45305]     return self.handle_error(e)
[Sat Dec 03 15:49:57.591479 2016] [wsgi:error] [pid 12:tid 140612625491712] [remote 128.211.233.228:45305]   File "/usr/local/lib/python2.7/dist-packages/flask/app.py", line 1988, in wsgi_app
[Sat Dec 03 15:49:57.591562 2016] [wsgi:error] [pid 12:tid 140612625491712] [remote 128.211.233.228:45305]     response = self.full_dispatch_request()
[Sat Dec 03 15:49:57.591628 2016] [wsgi:error] [pid 12:tid 140612625491712] [remote 128.211.233.228:45305]   File "/usr/local/lib/python2.7/dist-packages/flask/app.py", line 1641, in full_dispatch_request
[Sat Dec 03 15:49:57.591711 2016] [wsgi:error] [pid 12:tid 140612625491712] [remote 128.211.233.228:45305]     rv = self.handle_user_exception(e)
[Sat Dec 03 15:49:57.591777 2016] [wsgi:error] [pid 12:tid 140612625491712] [remote 128.211.233.228:45305]   File "/usr/local/lib/python2.7/dist-packages/flask_restful/__init__.py", line 271, in error_router
[Sat Dec 03 15:49:57.591858 2016] [wsgi:error] [pid 12:tid 140612625491712] [remote 128.211.233.228:45305]     return original_handler(e)
[Sat Dec 03 15:49:57.591923 2016] [wsgi:error] [pid 12:tid 140612625491712] [remote 128.211.233.228:45305]   File "/usr/local/lib/python2.7/dist-packages/flask_cors/extension.py", line 161, in wrapped_function
[Sat Dec 03 15:49:57.592055 2016] [wsgi:error] [pid 12:tid 140612625491712] [remote 128.211.233.228:45305]     return cors_after_request(app.make_response(f(*args, **kwargs)))
[Sat Dec 03 15:49:57.592126 2016] [wsgi:error] [pid 12:tid 140612625491712] [remote 128.211.233.228:45305]   File "/usr/local/lib/python2.7/dist-packages/flask/app.py", line 1544, in handle_user_exception
[Sat Dec 03 15:49:57.592208 2016] [wsgi:error] [pid 12:tid 140612625491712] [remote 128.211.233.228:45305]     reraise(exc_type, exc_value, tb)
[Sat Dec 03 15:49:57.592282 2016] [wsgi:error] [pid 12:tid 140612625491712] [remote 128.211.233.228:45305]   File "/usr/local/lib/python2.7/dist-packages/flask_restful/__init__.py", line 268, in error_router
[Sat Dec 03 15:49:57.592367 2016] [wsgi:error] [pid 12:tid 140612625491712] [remote 128.211.233.228:45305]     return self.handle_error(e)
[Sat Dec 03 15:49:57.592433 2016] [wsgi:error] [pid 12:tid 140612625491712] [remote 128.211.233.228:45305]   File "/usr/local/lib/python2.7/dist-packages/flask/app.py", line 1639, in full_dispatch_request
[Sat Dec 03 15:49:57.592515 2016] [wsgi:error] [pid 12:tid 140612625491712] [remote 128.211.233.228:45305]     rv = self.dispatch_request()
[Sat Dec 03 15:49:57.592580 2016] [wsgi:error] [pid 12:tid 140612625491712] [remote 128.211.233.228:45305]   File "/usr/local/lib/python2.7/dist-packages/flask/app.py", line 1625, in dispatch_request
[Sat Dec 03 15:49:57.592662 2016] [wsgi:error] [pid 12:tid 140612625491712] [remote 128.211.233.228:45305]     return self.view_functions[rule.endpoint](**req.view_args)
[Sat Dec 03 15:49:57.592729 2016] [wsgi:error] [pid 12:tid 140612625491712] [remote 128.211.233.228:45305]   File "/usr/local/lib/python2.7/dist-packages/flask_restful/__init__.py", line 477, in wrapper
[Sat Dec 03 15:49:57.592811 2016] [wsgi:error] [pid 12:tid 140612625491712] [remote 128.211.233.228:45305]     resp = resource(*args, **kwargs)
[Sat Dec 03 15:49:57.592876 2016] [wsgi:error] [pid 12:tid 140612625491712] [remote 128.211.233.228:45305]   File "/usr/local/lib/python2.7/dist-packages/flask/views.py", line 84, in view
[Sat Dec 03 15:49:57.592959 2016] [wsgi:error] [pid 12:tid 140612625491712] [remote 128.211.233.228:45305]     return self.dispatch_request(*args, **kwargs)
[Sat Dec 03 15:49:57.593025 2016] [wsgi:error] [pid 12:tid 140612625491712] [remote 128.211.233.228:45305]   File "/usr/local/lib/python2.7/dist-packages/flask_restful/__init__.py", line 587, in dispatch_request
[Sat Dec 03 15:49:57.593109 2016] [wsgi:error] [pid 12:tid 140612625491712] [remote 128.211.233.228:45305]     resp = meth(*args, **kwargs)
[Sat Dec 03 15:49:57.593176 2016] [wsgi:error] [pid 12:tid 140612625491712] [remote 128.211.233.228:45305]   File "/srv/www/app/main.py", line 171, in put
[Sat Dec 03 15:49:57.593258 2016] [wsgi:error] [pid 12:tid 140612625491712] [remote 128.211.233.228:45305]     for idx, val in enumerate(dataOld):
[Sat Dec 03 15:49:57.593362 2016] [wsgi:error] [pid 12:tid 140612625491712] [remote 128.211.233.228:45305] TypeError: 'NoneType' object is not iterable
[Sat Dec 03 15:50:06.884280 2016] [wsgi:error] [pid 12:tid 140612625491712] [remote 128.211.233.228:45305] mod_wsgi (pid=12): Exception occurred processing WSGI script '/srv/www/app/apache/apache.wsgi'.
[Sat Dec 03 15:50:06.884495 2016] [wsgi:error] [pid 12:tid 140612625491712] [remote 128.211.233.228:45305] Traceback (most recent call last):
[Sat Dec 03 15:50:06.884606 2016] [wsgi:error] [pid 12:tid 140612625491712] [remote 128.211.233.228:45305]   File "/usr/local/lib/python2.7/dist-packages/flask/app.py", line 2000, in __call__
[Sat Dec 03 15:50:06.893829 2016] [wsgi:error] [pid 12:tid 140612625491712] [remote 128.211.233.228:45305]     return self.wsgi_app(environ, start_response)
[Sat Dec 03 15:50:06.893882 2016] [wsgi:error] [pid 12:tid 140612625491712] [remote 128.211.233.228:45305]   File "/usr/local/lib/python2.7/dist-packages/flask/app.py", line 1991, in wsgi_app
[Sat Dec 03 15:50:06.893943 2016] [wsgi:error] [pid 12:tid 140612625491712] [remote 128.211.233.228:45305]     response = self.make_response(self.handle_exception(e))
[Sat Dec 03 15:50:06.893969 2016] [wsgi:error] [pid 12:tid 140612625491712] [remote 128.211.233.228:45305]   File "/usr/local/lib/python2.7/dist-packages/flask_restful/__init__.py", line 271, in error_router
[Sat Dec 03 15:50:06.894013 2016] [wsgi:error] [pid 12:tid 140612625491712] [remote 128.211.233.228:45305]     return original_handler(e)
[Sat Dec 03 15:50:06.894033 2016] [wsgi:error] [pid 12:tid 140612625491712] [remote 128.211.233.228:45305]   File "/usr/local/lib/python2.7/dist-packages/flask_cors/extension.py", line 161, in wrapped_function
[Sat Dec 03 15:50:06.894071 2016] [wsgi:error] [pid 12:tid 140612625491712] [remote 128.211.233.228:45305]     return cors_after_request(app.make_response(f(*args, **kwargs)))
[Sat Dec 03 15:50:06.894091 2016] [wsgi:error] [pid 12:tid 140612625491712] [remote 128.211.233.228:45305]   File "/usr/local/lib/python2.7/dist-packages/flask/app.py", line 1567, in handle_exception
[Sat Dec 03 15:50:06.894125 2016] [wsgi:error] [pid 12:tid 140612625491712] [remote 128.211.233.228:45305]     reraise(exc_type, exc_value, tb)
[Sat Dec 03 15:50:06.894143 2016] [wsgi:error] [pid 12:tid 140612625491712] [remote 128.211.233.228:45305]   File "/usr/local/lib/python2.7/dist-packages/flask_restful/__init__.py", line 268, in error_router
[Sat Dec 03 15:50:06.894177 2016] [wsgi:error] [pid 12:tid 140612625491712] [remote 128.211.233.228:45305]     return self.handle_error(e)
[Sat Dec 03 15:50:06.894195 2016] [wsgi:error] [pid 12:tid 140612625491712] [remote 128.211.233.228:45305]   File "/usr/local/lib/python2.7/dist-packages/flask/app.py", line 1988, in wsgi_app
[Sat Dec 03 15:50:06.894228 2016] [wsgi:error] [pid 12:tid 140612625491712] [remote 128.211.233.228:45305]     response = self.full_dispatch_request()
[Sat Dec 03 15:50:06.894246 2016] [wsgi:error] [pid 12:tid 140612625491712] [remote 128.211.233.228:45305]   File "/usr/local/lib/python2.7/dist-packages/flask/app.py", line 1641, in full_dispatch_request
[Sat Dec 03 15:50:06.894280 2016] [wsgi:error] [pid 12:tid 140612625491712] [remote 128.211.233.228:45305]     rv = self.handle_user_exception(e)
[Sat Dec 03 15:50:06.894299 2016] [wsgi:error] [pid 12:tid 140612625491712] [remote 128.211.233.228:45305]   File "/usr/local/lib/python2.7/dist-packages/flask_restful/__init__.py", line 271, in error_router
[Sat Dec 03 15:50:06.894332 2016] [wsgi:error] [pid 12:tid 140612625491712] [remote 128.211.233.228:45305]     return original_handler(e)
[Sat Dec 03 15:50:06.894351 2016] [wsgi:error] [pid 12:tid 140612625491712] [remote 128.211.233.228:45305]   File "/usr/local/lib/python2.7/dist-packages/flask_cors/extension.py", line 161, in wrapped_function
[Sat Dec 03 15:50:06.894385 2016] [wsgi:error] [pid 12:tid 140612625491712] [remote 128.211.233.228:45305]     return cors_after_request(app.make_response(f(*args, **kwargs)))
[Sat Dec 03 15:50:06.894419 2016] [wsgi:error] [pid 12:tid 140612625491712] [remote 128.211.233.228:45305]   File "/usr/local/lib/python2.7/dist-packages/flask/app.py", line 1544, in handle_user_exception
[Sat Dec 03 15:50:06.894499 2016] [wsgi:error] [pid 12:tid 140612625491712] [remote 128.211.233.228:45305]     reraise(exc_type, exc_value, tb)
[Sat Dec 03 15:50:06.894546 2016] [wsgi:error] [pid 12:tid 140612625491712] [remote 128.211.233.228:45305]   File "/usr/local/lib/python2.7/dist-packages/flask_restful/__init__.py", line 268, in error_router
[Sat Dec 03 15:50:06.894631 2016] [wsgi:error] [pid 12:tid 140612625491712] [remote 128.211.233.228:45305]     return self.handle_error(e)
[Sat Dec 03 15:50:06.894674 2016] [wsgi:error] [pid 12:tid 140612625491712] [remote 128.211.233.228:45305]   File "/usr/local/lib/python2.7/dist-packages/flask/app.py", line 1639, in full_dispatch_request
[Sat Dec 03 15:50:06.894761 2016] [wsgi:error] [pid 12:tid 140612625491712] [remote 128.211.233.228:45305]     rv = self.dispatch_request()
[Sat Dec 03 15:50:06.894786 2016] [wsgi:error] [pid 12:tid 140612625491712] [remote 128.211.233.228:45305]   File "/usr/local/lib/python2.7/dist-packages/flask/app.py", line 1625, in dispatch_request
[Sat Dec 03 15:50:06.894820 2016] [wsgi:error] [pid 12:tid 140612625491712] [remote 128.211.233.228:45305]     return self.view_functions[rule.endpoint](**req.view_args)
[Sat Dec 03 15:50:06.894882 2016] [wsgi:error] [pid 12:tid 140612625491712] [remote 128.211.233.228:45305]   File "/usr/local/lib/python2.7/dist-packages/flask_restful/__init__.py", line 477, in wrapper
[Sat Dec 03 15:50:06.894938 2016] [wsgi:error] [pid 12:tid 140612625491712] [remote 128.211.233.228:45305]     resp = resource(*args, **kwargs)
[Sat Dec 03 15:50:06.894962 2016] [wsgi:error] [pid 12:tid 140612625491712] [remote 128.211.233.228:45305]   File "/usr/local/lib/python2.7/dist-packages/flask/views.py", line 84, in view
[Sat Dec 03 15:50:06.895014 2016] [wsgi:error] [pid 12:tid 140612625491712] [remote 128.211.233.228:45305]     return self.dispatch_request(*args, **kwargs)
[Sat Dec 03 15:50:06.895038 2016] [wsgi:error] [pid 12:tid 140612625491712] [remote 128.211.233.228:45305]   File "/usr/local/lib/python2.7/dist-packages/flask_restful/__init__.py", line 587, in dispatch_request
[Sat Dec 03 15:50:06.895077 2016] [wsgi:error] [pid 12:tid 140612625491712] [remote 128.211.233.228:45305]     resp = meth(*args, **kwargs)
[Sat Dec 03 15:50:06.895097 2016] [wsgi:error] [pid 12:tid 140612625491712] [remote 128.211.233.228:45305]   File "/srv/www/app/main.py", line 171, in put
[Sat Dec 03 15:50:06.895152 2016] [wsgi:error] [pid 12:tid 140612625491712] [remote 128.211.233.228:45305]     for idx, val in enumerate(dataOld):
[Sat Dec 03 15:50:06.895194 2016] [wsgi:error] [pid 12:tid 140612625491712] [remote 128.211.233.228:45305] TypeError: 'NoneType' object is not iterable
[Sat Dec 03 15:50:57.160035 2016] [wsgi:error] [pid 12:tid 140612625491712] [remote 128.211.233.228:45817] mod_wsgi (pid=12): Exception occurred processing WSGI script '/srv/www/app/apache/apache.wsgi'.
[Sat Dec 03 15:50:57.168005 2016] [wsgi:error] [pid 12:tid 140612625491712] [remote 128.211.233.228:45817] Traceback (most recent call last):
[Sat Dec 03 15:50:57.168093 2016] [wsgi:error] [pid 12:tid 140612625491712] [remote 128.211.233.228:45817]   File "/usr/local/lib/python2.7/dist-packages/flask/app.py", line 2000, in __call__
[Sat Dec 03 15:50:57.168289 2016] [wsgi:error] [pid 12:tid 140612625491712] [remote 128.211.233.228:45817]     return self.wsgi_app(environ, start_response)
[Sat Dec 03 15:50:57.168317 2016] [wsgi:error] [pid 12:tid 140612625491712] [remote 128.211.233.228:45817]   File "/usr/local/lib/python2.7/dist-packages/flask/app.py", line 1991, in wsgi_app
[Sat Dec 03 15:50:57.168359 2016] [wsgi:error] [pid 12:tid 140612625491712] [remote 128.211.233.228:45817]     response = self.make_response(self.handle_exception(e))
[Sat Dec 03 15:50:57.168381 2016] [wsgi:error] [pid 12:tid 140612625491712] [remote 128.211.233.228:45817]   File "/usr/local/lib/python2.7/dist-packages/flask_restful/__init__.py", line 271, in error_router
[Sat Dec 03 15:50:57.168448 2016] [wsgi:error] [pid 12:tid 140612625491712] [remote 128.211.233.228:45817]     return original_handler(e)
[Sat Dec 03 15:50:57.168473 2016] [wsgi:error] [pid 12:tid 140612625491712] [remote 128.211.233.228:45817]   File "/usr/local/lib/python2.7/dist-packages/flask_cors/extension.py", line 161, in wrapped_function
[Sat Dec 03 15:50:57.168565 2016] [wsgi:error] [pid 12:tid 140612625491712] [remote 128.211.233.228:45817]     return cors_after_request(app.make_response(f(*args, **kwargs)))
[Sat Dec 03 15:50:57.168591 2016] [wsgi:error] [pid 12:tid 140612625491712] [remote 128.211.233.228:45817]   File "/usr/local/lib/python2.7/dist-packages/flask/app.py", line 1567, in handle_exception
[Sat Dec 03 15:50:57.168655 2016] [wsgi:error] [pid 12:tid 140612625491712] [remote 128.211.233.228:45817]     reraise(exc_type, exc_value, tb)
[Sat Dec 03 15:50:57.168678 2016] [wsgi:error] [pid 12:tid 140612625491712] [remote 128.211.233.228:45817]   File "/usr/local/lib/python2.7/dist-packages/flask_restful/__init__.py", line 268, in error_router
[Sat Dec 03 15:50:57.168727 2016] [wsgi:error] [pid 12:tid 140612625491712] [remote 128.211.233.228:45817]     return self.handle_error(e)
[Sat Dec 03 15:50:57.168748 2016] [wsgi:error] [pid 12:tid 140612625491712] [remote 128.211.233.228:45817]   File "/usr/local/lib/python2.7/dist-packages/flask/app.py", line 1988, in wsgi_app
[Sat Dec 03 15:50:57.168785 2016] [wsgi:error] [pid 12:tid 140612625491712] [remote 128.211.233.228:45817]     response = self.full_dispatch_request()
[Sat Dec 03 15:50:57.168805 2016] [wsgi:error] [pid 12:tid 140612625491712] [remote 128.211.233.228:45817]   File "/usr/local/lib/python2.7/dist-packages/flask/app.py", line 1641, in full_dispatch_request
[Sat Dec 03 15:50:57.168839 2016] [wsgi:error] [pid 12:tid 140612625491712] [remote 128.211.233.228:45817]     rv = self.handle_user_exception(e)
[Sat Dec 03 15:50:57.168858 2016] [wsgi:error] [pid 12:tid 140612625491712] [remote 128.211.233.228:45817]   File "/usr/local/lib/python2.7/dist-packages/flask_restful/__init__.py", line 271, in error_router
[Sat Dec 03 15:50:57.168891 2016] [wsgi:error] [pid 12:tid 140612625491712] [remote 128.211.233.228:45817]     return original_handler(e)
[Sat Dec 03 15:50:57.168909 2016] [wsgi:error] [pid 12:tid 140612625491712] [remote 128.211.233.228:45817]   File "/usr/local/lib/python2.7/dist-packages/flask_cors/extension.py", line 161, in wrapped_function
[Sat Dec 03 15:50:57.168943 2016] [wsgi:error] [pid 12:tid 140612625491712] [remote 128.211.233.228:45817]     return cors_after_request(app.make_response(f(*args, **kwargs)))
[Sat Dec 03 15:50:57.168962 2016] [wsgi:error] [pid 12:tid 140612625491712] [remote 128.211.233.228:45817]   File "/usr/local/lib/python2.7/dist-packages/flask/app.py", line 1544, in handle_user_exception
[Sat Dec 03 15:50:57.168995 2016] [wsgi:error] [pid 12:tid 140612625491712] [remote 128.211.233.228:45817]     reraise(exc_type, exc_value, tb)
[Sat Dec 03 15:50:57.169013 2016] [wsgi:error] [pid 12:tid 140612625491712] [remote 128.211.233.228:45817]   File "/usr/local/lib/python2.7/dist-packages/flask_restful/__init__.py", line 268, in error_router
[Sat Dec 03 15:50:57.169053 2016] [wsgi:error] [pid 12:tid 140612625491712] [remote 128.211.233.228:45817]     return self.handle_error(e)
[Sat Dec 03 15:50:57.169072 2016] [wsgi:error] [pid 12:tid 140612625491712] [remote 128.211.233.228:45817]   File "/usr/local/lib/python2.7/dist-packages/flask/app.py", line 1639, in full_dispatch_request
[Sat Dec 03 15:50:57.169105 2016] [wsgi:error] [pid 12:tid 140612625491712] [remote 128.211.233.228:45817]     rv = self.dispatch_request()
[Sat Dec 03 15:50:57.169123 2016] [wsgi:error] [pid 12:tid 140612625491712] [remote 128.211.233.228:45817]   File "/usr/local/lib/python2.7/dist-packages/flask/app.py", line 1625, in dispatch_request
[Sat Dec 03 15:50:57.169169 2016] [wsgi:error] [pid 12:tid 140612625491712] [remote 128.211.233.228:45817]     return self.view_functions[rule.endpoint](**req.view_args)
[Sat Dec 03 15:50:57.169191 2016] [wsgi:error] [pid 12:tid 140612625491712] [remote 128.211.233.228:45817]   File "/usr/local/lib/python2.7/dist-packages/flask_restful/__init__.py", line 477, in wrapper
[Sat Dec 03 15:50:57.169239 2016] [wsgi:error] [pid 12:tid 140612625491712] [remote 128.211.233.228:45817]     resp = resource(*args, **kwargs)
[Sat Dec 03 15:50:57.169279 2016] [wsgi:error] [pid 12:tid 140612625491712] [remote 128.211.233.228:45817]   File "/usr/local/lib/python2.7/dist-packages/flask/views.py", line 84, in view
[Sat Dec 03 15:50:57.169345 2016] [wsgi:error] [pid 12:tid 140612625491712] [remote 128.211.233.228:45817]     return self.dispatch_request(*args, **kwargs)
[Sat Dec 03 15:50:57.169367 2016] [wsgi:error] [pid 12:tid 140612625491712] [remote 128.211.233.228:45817]   File "/usr/local/lib/python2.7/dist-packages/flask_restful/__init__.py", line 587, in dispatch_request
[Sat Dec 03 15:50:57.169414 2016] [wsgi:error] [pid 12:tid 140612625491712] [remote 128.211.233.228:45817]     resp = meth(*args, **kwargs)
[Sat Dec 03 15:50:57.169436 2016] [wsgi:error] [pid 12:tid 140612625491712] [remote 128.211.233.228:45817]   File "/srv/www/app/main.py", line 171, in put
[Sat Dec 03 15:50:57.169495 2016] [wsgi:error] [pid 12:tid 140612625491712] [remote 128.211.233.228:45817]     for idx, val in enumerate(dataOld):
[Sat Dec 03 15:50:57.169594 2016] [wsgi:error] [pid 12:tid 140612625491712] [remote 128.211.233.228:45817] TypeError: 'NoneType' object is not iterable
[Sat Dec 03 15:50:59.011628 2016] [wsgi:error] [pid 12:tid 140612726286080] [remote 128.211.233.228:45305] mod_wsgi (pid=12): Exception occurred processing WSGI script '/srv/www/app/apache/apache.wsgi'.
[Sat Dec 03 15:50:59.011843 2016] [wsgi:error] [pid 12:tid 140612726286080] [remote 128.211.233.228:45305] Traceback (most recent call last):
[Sat Dec 03 15:50:59.011938 2016] [wsgi:error] [pid 12:tid 140612726286080] [remote 128.211.233.228:45305]   File "/usr/local/lib/python2.7/dist-packages/flask/app.py", line 2000, in __call__
[Sat Dec 03 15:50:59.012055 2016] [wsgi:error] [pid 12:tid 140612726286080] [remote 128.211.233.228:45305]     return self.wsgi_app(environ, start_response)
[Sat Dec 03 15:50:59.012126 2016] [wsgi:error] [pid 12:tid 140612726286080] [remote 128.211.233.228:45305]   File "/usr/local/lib/python2.7/dist-packages/flask/app.py", line 1991, in wsgi_app
[Sat Dec 03 15:50:59.012213 2016] [wsgi:error] [pid 12:tid 140612726286080] [remote 128.211.233.228:45305]     response = self.make_response(self.handle_exception(e))
[Sat Dec 03 15:50:59.012280 2016] [wsgi:error] [pid 12:tid 140612726286080] [remote 128.211.233.228:45305]   File "/usr/local/lib/python2.7/dist-packages/flask_restful/__init__.py", line 271, in error_router
[Sat Dec 03 15:50:59.012395 2016] [wsgi:error] [pid 12:tid 140612726286080] [remote 128.211.233.228:45305]     return original_handler(e)
[Sat Dec 03 15:50:59.012465 2016] [wsgi:error] [pid 12:tid 140612726286080] [remote 128.211.233.228:45305]   File "/usr/local/lib/python2.7/dist-packages/flask_cors/extension.py", line 161, in wrapped_function
[Sat Dec 03 15:50:59.012551 2016] [wsgi:error] [pid 12:tid 140612726286080] [remote 128.211.233.228:45305]     return cors_after_request(app.make_response(f(*args, **kwargs)))
[Sat Dec 03 15:50:59.012617 2016] [wsgi:error] [pid 12:tid 140612726286080] [remote 128.211.233.228:45305]   File "/usr/local/lib/python2.7/dist-packages/flask/app.py", line 1567, in handle_exception
[Sat Dec 03 15:50:59.012698 2016] [wsgi:error] [pid 12:tid 140612726286080] [remote 128.211.233.228:45305]     reraise(exc_type, exc_value, tb)
[Sat Dec 03 15:50:59.012762 2016] [wsgi:error] [pid 12:tid 140612726286080] [remote 128.211.233.228:45305]   File "/usr/local/lib/python2.7/dist-packages/flask_restful/__init__.py", line 268, in error_router
[Sat Dec 03 15:50:59.012842 2016] [wsgi:error] [pid 12:tid 140612726286080] [remote 128.211.233.228:45305]     return self.handle_error(e)
[Sat Dec 03 15:50:59.012906 2016] [wsgi:error] [pid 12:tid 140612726286080] [remote 128.211.233.228:45305]   File "/usr/local/lib/python2.7/dist-packages/flask/app.py", line 1988, in wsgi_app
[Sat Dec 03 15:50:59.012987 2016] [wsgi:error] [pid 12:tid 140612726286080] [remote 128.211.233.228:45305]     response = self.full_dispatch_request()
[Sat Dec 03 15:50:59.013052 2016] [wsgi:error] [pid 12:tid 140612726286080] [remote 128.211.233.228:45305]   File "/usr/local/lib/python2.7/dist-packages/flask/app.py", line 1641, in full_dispatch_request
[Sat Dec 03 15:50:59.013133 2016] [wsgi:error] [pid 12:tid 140612726286080] [remote 128.211.233.228:45305]     rv = self.handle_user_exception(e)
[Sat Dec 03 15:50:59.013196 2016] [wsgi:error] [pid 12:tid 140612726286080] [remote 128.211.233.228:45305]   File "/usr/local/lib/python2.7/dist-packages/flask_restful/__init__.py", line 271, in error_router
[Sat Dec 03 15:50:59.013277 2016] [wsgi:error] [pid 12:tid 140612726286080] [remote 128.211.233.228:45305]     return original_handler(e)
[Sat Dec 03 15:50:59.013340 2016] [wsgi:error] [pid 12:tid 140612726286080] [remote 128.211.233.228:45305]   File "/usr/local/lib/python2.7/dist-packages/flask_cors/extension.py", line 161, in wrapped_function
[Sat Dec 03 15:50:59.013449 2016] [wsgi:error] [pid 12:tid 140612726286080] [remote 128.211.233.228:45305]     return cors_after_request(app.make_response(f(*args, **kwargs)))
[Sat Dec 03 15:50:59.013517 2016] [wsgi:error] [pid 12:tid 140612726286080] [remote 128.211.233.228:45305]   File "/usr/local/lib/python2.7/dist-packages/flask/app.py", line 1544, in handle_user_exception
[Sat Dec 03 15:50:59.013598 2016] [wsgi:error] [pid 12:tid 140612726286080] [remote 128.211.233.228:45305]     reraise(exc_type, exc_value, tb)
[Sat Dec 03 15:50:59.013662 2016] [wsgi:error] [pid 12:tid 140612726286080] [remote 128.211.233.228:45305]   File "/usr/local/lib/python2.7/dist-packages/flask_restful/__init__.py", line 268, in error_router
[Sat Dec 03 15:50:59.013743 2016] [wsgi:error] [pid 12:tid 140612726286080] [remote 128.211.233.228:45305]     return self.handle_error(e)
[Sat Dec 03 15:50:59.013832 2016] [wsgi:error] [pid 12:tid 140612726286080] [remote 128.211.233.228:45305]   File "/usr/local/lib/python2.7/dist-packages/flask/app.py", line 1639, in full_dispatch_request
[Sat Dec 03 15:50:59.013921 2016] [wsgi:error] [pid 12:tid 140612726286080] [remote 128.211.233.228:45305]     rv = self.dispatch_request()
[Sat Dec 03 15:50:59.013987 2016] [wsgi:error] [pid 12:tid 140612726286080] [remote 128.211.233.228:45305]   File "/usr/local/lib/python2.7/dist-packages/flask/app.py", line 1625, in dispatch_request
[Sat Dec 03 15:50:59.014069 2016] [wsgi:error] [pid 12:tid 140612726286080] [remote 128.211.233.228:45305]     return self.view_functions[rule.endpoint](**req.view_args)
[Sat Dec 03 15:50:59.014134 2016] [wsgi:error] [pid 12:tid 140612726286080] [remote 128.211.233.228:45305]   File "/usr/local/lib/python2.7/dist-packages/flask_restful/__init__.py", line 477, in wrapper
[Sat Dec 03 15:50:59.014215 2016] [wsgi:error] [pid 12:tid 140612726286080] [remote 128.211.233.228:45305]     resp = resource(*args, **kwargs)
[Sat Dec 03 15:50:59.014279 2016] [wsgi:error] [pid 12:tid 140612726286080] [remote 128.211.233.228:45305]   File "/usr/local/lib/python2.7/dist-packages/flask/views.py", line 84, in view
[Sat Dec 03 15:50:59.014364 2016] [wsgi:error] [pid 12:tid 140612726286080] [remote 128.211.233.228:45305]     return self.dispatch_request(*args, **kwargs)
[Sat Dec 03 15:50:59.014429 2016] [wsgi:error] [pid 12:tid 140612726286080] [remote 128.211.233.228:45305]   File "/usr/local/lib/python2.7/dist-packages/flask_restful/__init__.py", line 587, in dispatch_request
[Sat Dec 03 15:50:59.014511 2016] [wsgi:error] [pid 12:tid 140612726286080] [remote 128.211.233.228:45305]     resp = meth(*args, **kwargs)
[Sat Dec 03 15:50:59.014577 2016] [wsgi:error] [pid 12:tid 140612726286080] [remote 128.211.233.228:45305]   File "/srv/www/app/main.py", line 171, in put
[Sat Dec 03 15:50:59.014659 2016] [wsgi:error] [pid 12:tid 140612726286080] [remote 128.211.233.228:45305]     for idx, val in enumerate(dataOld):
[Sat Dec 03 15:50:59.014741 2016] [wsgi:error] [pid 12:tid 140612726286080] [remote 128.211.233.228:45305] TypeError: 'NoneType' object is not iterable
[Wed Dec 07 04:15:43.958383 2016] [wsgi:error] [pid 12:tid 140612625491712] [remote 128.211.233.228:45561] mod_wsgi (pid=12): Exception occurred processing WSGI script '/srv/www/app/apache/apache.wsgi'.
[Wed Dec 07 04:15:43.959588 2016] [wsgi:error] [pid 12:tid 140612625491712] [remote 128.211.233.228:45561] Traceback (most recent call last):
[Wed Dec 07 04:15:43.959703 2016] [wsgi:error] [pid 12:tid 140612625491712] [remote 128.211.233.228:45561]   File "/usr/local/lib/python2.7/dist-packages/flask/app.py", line 2000, in __call__
[Wed Dec 07 04:15:43.960123 2016] [wsgi:error] [pid 12:tid 140612625491712] [remote 128.211.233.228:45561]     return self.wsgi_app(environ, start_response)
[Wed Dec 07 04:15:43.960212 2016] [wsgi:error] [pid 12:tid 140612625491712] [remote 128.211.233.228:45561]   File "/usr/local/lib/python2.7/dist-packages/flask/app.py", line 1991, in wsgi_app
[Wed Dec 07 04:15:43.960321 2016] [wsgi:error] [pid 12:tid 140612625491712] [remote 128.211.233.228:45561]     response = self.make_response(self.handle_exception(e))
[Wed Dec 07 04:15:43.960454 2016] [wsgi:error] [pid 12:tid 140612625491712] [remote 128.211.233.228:45561]   File "/usr/local/lib/python2.7/dist-packages/flask_restful/__init__.py", line 271, in error_router
[Wed Dec 07 04:15:43.960574 2016] [wsgi:error] [pid 12:tid 140612625491712] [remote 128.211.233.228:45561]     return original_handler(e)
[Wed Dec 07 04:15:43.960647 2016] [wsgi:error] [pid 12:tid 140612625491712] [remote 128.211.233.228:45561]   File "/usr/local/lib/python2.7/dist-packages/flask_cors/extension.py", line 161, in wrapped_function
[Wed Dec 07 04:15:43.960767 2016] [wsgi:error] [pid 12:tid 140612625491712] [remote 128.211.233.228:45561]     return cors_after_request(app.make_response(f(*args, **kwargs)))
[Wed Dec 07 04:15:43.960840 2016] [wsgi:error] [pid 12:tid 140612625491712] [remote 128.211.233.228:45561]   File "/usr/local/lib/python2.7/dist-packages/flask/app.py", line 1567, in handle_exception
[Wed Dec 07 04:15:43.960972 2016] [wsgi:error] [pid 12:tid 140612625491712] [remote 128.211.233.228:45561]     reraise(exc_type, exc_value, tb)
[Wed Dec 07 04:15:43.961048 2016] [wsgi:error] [pid 12:tid 140612625491712] [remote 128.211.233.228:45561]   File "/usr/local/lib/python2.7/dist-packages/flask_restful/__init__.py", line 268, in error_router
[Wed Dec 07 04:15:43.961149 2016] [wsgi:error] [pid 12:tid 140612625491712] [remote 128.211.233.228:45561]     return self.handle_error(e)
[Wed Dec 07 04:15:43.961220 2016] [wsgi:error] [pid 12:tid 140612625491712] [remote 128.211.233.228:45561]   File "/usr/local/lib/python2.7/dist-packages/flask/app.py", line 1988, in wsgi_app
[Wed Dec 07 04:15:43.961303 2016] [wsgi:error] [pid 12:tid 140612625491712] [remote 128.211.233.228:45561]     response = self.full_dispatch_request()
[Wed Dec 07 04:15:43.961371 2016] [wsgi:error] [pid 12:tid 140612625491712] [remote 128.211.233.228:45561]   File "/usr/local/lib/python2.7/dist-packages/flask/app.py", line 1641, in full_dispatch_request
[Wed Dec 07 04:15:43.961453 2016] [wsgi:error] [pid 12:tid 140612625491712] [remote 128.211.233.228:45561]     rv = self.handle_user_exception(e)
[Wed Dec 07 04:15:43.961517 2016] [wsgi:error] [pid 12:tid 140612625491712] [remote 128.211.233.228:45561]   File "/usr/local/lib/python2.7/dist-packages/flask_restful/__init__.py", line 271, in error_router
[Wed Dec 07 04:15:43.961599 2016] [wsgi:error] [pid 12:tid 140612625491712] [remote 128.211.233.228:45561]     return original_handler(e)
[Wed Dec 07 04:15:43.961663 2016] [wsgi:error] [pid 12:tid 140612625491712] [remote 128.211.233.228:45561]   File "/usr/local/lib/python2.7/dist-packages/flask_cors/extension.py", line 161, in wrapped_function
[Wed Dec 07 04:15:43.961744 2016] [wsgi:error] [pid 12:tid 140612625491712] [remote 128.211.233.228:45561]     return cors_after_request(app.make_response(f(*args, **kwargs)))
[Wed Dec 07 04:15:43.961809 2016] [wsgi:error] [pid 12:tid 140612625491712] [remote 128.211.233.228:45561]   File "/usr/local/lib/python2.7/dist-packages/flask/app.py", line 1544, in handle_user_exception
[Wed Dec 07 04:15:43.961889 2016] [wsgi:error] [pid 12:tid 140612625491712] [remote 128.211.233.228:45561]     reraise(exc_type, exc_value, tb)
[Wed Dec 07 04:15:43.961953 2016] [wsgi:error] [pid 12:tid 140612625491712] [remote 128.211.233.228:45561]   File "/usr/local/lib/python2.7/dist-packages/flask_restful/__init__.py", line 268, in error_router
[Wed Dec 07 04:15:43.962034 2016] [wsgi:error] [pid 12:tid 140612625491712] [remote 128.211.233.228:45561]     return self.handle_error(e)
[Wed Dec 07 04:15:43.962098 2016] [wsgi:error] [pid 12:tid 140612625491712] [remote 128.211.233.228:45561]   File "/usr/local/lib/python2.7/dist-packages/flask/app.py", line 1639, in full_dispatch_request
[Wed Dec 07 04:15:43.962178 2016] [wsgi:error] [pid 12:tid 140612625491712] [remote 128.211.233.228:45561]     rv = self.dispatch_request()
[Wed Dec 07 04:15:43.962242 2016] [wsgi:error] [pid 12:tid 140612625491712] [remote 128.211.233.228:45561]   File "/usr/local/lib/python2.7/dist-packages/flask/app.py", line 1625, in dispatch_request
[Wed Dec 07 04:15:43.962384 2016] [wsgi:error] [pid 12:tid 140612625491712] [remote 128.211.233.228:45561]     return self.view_functions[rule.endpoint](**req.view_args)
[Wed Dec 07 04:15:43.962457 2016] [wsgi:error] [pid 12:tid 140612625491712] [remote 128.211.233.228:45561]   File "/usr/local/lib/python2.7/dist-packages/flask_restful/__init__.py", line 477, in wrapper
[Wed Dec 07 04:15:43.962560 2016] [wsgi:error] [pid 12:tid 140612625491712] [remote 128.211.233.228:45561]     resp = resource(*args, **kwargs)
[Wed Dec 07 04:15:43.962647 2016] [wsgi:error] [pid 12:tid 140612625491712] [remote 128.211.233.228:45561]   File "/usr/local/lib/python2.7/dist-packages/flask/views.py", line 84, in view
[Wed Dec 07 04:15:43.962766 2016] [wsgi:error] [pid 12:tid 140612625491712] [remote 128.211.233.228:45561]     return self.dispatch_request(*args, **kwargs)
[Wed Dec 07 04:15:43.962838 2016] [wsgi:error] [pid 12:tid 140612625491712] [remote 128.211.233.228:45561]   File "/usr/local/lib/python2.7/dist-packages/flask_restful/__init__.py", line 587, in dispatch_request
[Wed Dec 07 04:15:43.962989 2016] [wsgi:error] [pid 12:tid 140612625491712] [remote 128.211.233.228:45561]     resp = meth(*args, **kwargs)
[Wed Dec 07 04:15:43.963064 2016] [wsgi:error] [pid 12:tid 140612625491712] [remote 128.211.233.228:45561]   File "/srv/www/app/main.py", line 171, in put
[Wed Dec 07 04:15:43.963228 2016] [wsgi:error] [pid 12:tid 140612625491712] [remote 128.211.233.228:45561]     for idx, val in enumerate(dataOld):
[Wed Dec 07 04:15:43.963404 2016] [wsgi:error] [pid 12:tid 140612625491712] [remote 128.211.233.228:45561] TypeError: 'NoneType' object is not iterable
[Wed Dec 07 04:15:44.016534 2016] [wsgi:error] [pid 12:tid 140612726286080] [remote 128.211.233.228:6124] mod_wsgi (pid=12): Exception occurred processing WSGI script '/srv/www/app/apache/apache.wsgi'.
[Wed Dec 07 04:15:44.016747 2016] [wsgi:error] [pid 12:tid 140612726286080] [remote 128.211.233.228:6124] Traceback (most recent call last):
[Wed Dec 07 04:15:44.016845 2016] [wsgi:error] [pid 12:tid 140612726286080] [remote 128.211.233.228:6124]   File "/usr/local/lib/python2.7/dist-packages/flask/app.py", line 2000, in __call__
[Wed Dec 07 04:15:44.016988 2016] [wsgi:error] [pid 12:tid 140612726286080] [remote 128.211.233.228:6124]     return self.wsgi_app(environ, start_response)
[Wed Dec 07 04:15:44.017065 2016] [wsgi:error] [pid 12:tid 140612726286080] [remote 128.211.233.228:6124]   File "/usr/local/lib/python2.7/dist-packages/flask/app.py", line 1991, in wsgi_app
[Wed Dec 07 04:15:44.017153 2016] [wsgi:error] [pid 12:tid 140612726286080] [remote 128.211.233.228:6124]     response = self.make_response(self.handle_exception(e))
[Wed Dec 07 04:15:44.017222 2016] [wsgi:error] [pid 12:tid 140612726286080] [remote 128.211.233.228:6124]   File "/usr/local/lib/python2.7/dist-packages/flask_restful/__init__.py", line 271, in error_router
[Wed Dec 07 04:15:44.017308 2016] [wsgi:error] [pid 12:tid 140612726286080] [remote 128.211.233.228:6124]     return original_handler(e)
[Wed Dec 07 04:15:44.017374 2016] [wsgi:error] [pid 12:tid 140612726286080] [remote 128.211.233.228:6124]   File "/usr/local/lib/python2.7/dist-packages/flask_cors/extension.py", line 161, in wrapped_function
[Wed Dec 07 04:15:44.017457 2016] [wsgi:error] [pid 12:tid 140612726286080] [remote 128.211.233.228:6124]     return cors_after_request(app.make_response(f(*args, **kwargs)))
[Wed Dec 07 04:15:44.017555 2016] [wsgi:error] [pid 12:tid 140612726286080] [remote 128.211.233.228:6124]   File "/usr/local/lib/python2.7/dist-packages/flask/app.py", line 1567, in handle_exception
[Wed Dec 07 04:15:44.017644 2016] [wsgi:error] [pid 12:tid 140612726286080] [remote 128.211.233.228:6124]     reraise(exc_type, exc_value, tb)
[Wed Dec 07 04:15:44.017710 2016] [wsgi:error] [pid 12:tid 140612726286080] [remote 128.211.233.228:6124]   File "/usr/local/lib/python2.7/dist-packages/flask_restful/__init__.py", line 268, in error_router
[Wed Dec 07 04:15:44.017792 2016] [wsgi:error] [pid 12:tid 140612726286080] [remote 128.211.233.228:6124]     return self.handle_error(e)
[Wed Dec 07 04:15:44.017913 2016] [wsgi:error] [pid 12:tid 140612726286080] [remote 128.211.233.228:6124]   File "/usr/local/lib/python2.7/dist-packages/flask/app.py", line 1988, in wsgi_app
[Wed Dec 07 04:15:44.018004 2016] [wsgi:error] [pid 12:tid 140612726286080] [remote 128.211.233.228:6124]     response = self.full_dispatch_request()
[Wed Dec 07 04:15:44.018070 2016] [wsgi:error] [pid 12:tid 140612726286080] [remote 128.211.233.228:6124]   File "/usr/local/lib/python2.7/dist-packages/flask/app.py", line 1641, in full_dispatch_request
[Wed Dec 07 04:15:44.018153 2016] [wsgi:error] [pid 12:tid 140612726286080] [remote 128.211.233.228:6124]     rv = self.handle_user_exception(e)
[Wed Dec 07 04:15:44.018217 2016] [wsgi:error] [pid 12:tid 140612726286080] [remote 128.211.233.228:6124]   File "/usr/local/lib/python2.7/dist-packages/flask_restful/__init__.py", line 271, in error_router
[Wed Dec 07 04:15:44.018298 2016] [wsgi:error] [pid 12:tid 140612726286080] [remote 128.211.233.228:6124]     return original_handler(e)
[Wed Dec 07 04:15:44.018362 2016] [wsgi:error] [pid 12:tid 140612726286080] [remote 128.211.233.228:6124]   File "/usr/local/lib/python2.7/dist-packages/flask_cors/extension.py", line 161, in wrapped_function
[Wed Dec 07 04:15:44.018443 2016] [wsgi:error] [pid 12:tid 140612726286080] [remote 128.211.233.228:6124]     return cors_after_request(app.make_response(f(*args, **kwargs)))
[Wed Dec 07 04:15:44.018508 2016] [wsgi:error] [pid 12:tid 140612726286080] [remote 128.211.233.228:6124]   File "/usr/local/lib/python2.7/dist-packages/flask/app.py", line 1544, in handle_user_exception
[Wed Dec 07 04:15:44.018589 2016] [wsgi:error] [pid 12:tid 140612726286080] [remote 128.211.233.228:6124]     reraise(exc_type, exc_value, tb)
[Wed Dec 07 04:15:44.018653 2016] [wsgi:error] [pid 12:tid 140612726286080] [remote 128.211.233.228:6124]   File "/usr/local/lib/python2.7/dist-packages/flask_restful/__init__.py", line 268, in error_router
[Wed Dec 07 04:15:44.018734 2016] [wsgi:error] [pid 12:tid 140612726286080] [remote 128.211.233.228:6124]     return self.handle_error(e)
[Wed Dec 07 04:15:44.018798 2016] [wsgi:error] [pid 12:tid 140612726286080] [remote 128.211.233.228:6124]   File "/usr/local/lib/python2.7/dist-packages/flask/app.py", line 1639, in full_dispatch_request
[Wed Dec 07 04:15:44.018923 2016] [wsgi:error] [pid 12:tid 140612726286080] [remote 128.211.233.228:6124]     rv = self.dispatch_request()
[Wed Dec 07 04:15:44.019001 2016] [wsgi:error] [pid 12:tid 140612726286080] [remote 128.211.233.228:6124]   File "/usr/local/lib/python2.7/dist-packages/flask/app.py", line 1625, in dispatch_request
[Wed Dec 07 04:15:44.019086 2016] [wsgi:error] [pid 12:tid 140612726286080] [remote 128.211.233.228:6124]     return self.view_functions[rule.endpoint](**req.view_args)
[Wed Dec 07 04:15:44.019152 2016] [wsgi:error] [pid 12:tid 140612726286080] [remote 128.211.233.228:6124]   File "/usr/local/lib/python2.7/dist-packages/flask_restful/__init__.py", line 477, in wrapper
[Wed Dec 07 04:15:44.019233 2016] [wsgi:error] [pid 12:tid 140612726286080] [remote 128.211.233.228:6124]     resp = resource(*args, **kwargs)
[Wed Dec 07 04:15:44.019298 2016] [wsgi:error] [pid 12:tid 140612726286080] [remote 128.211.233.228:6124]   File "/usr/local/lib/python2.7/dist-packages/flask/views.py", line 84, in view
[Wed Dec 07 04:15:44.019381 2016] [wsgi:error] [pid 12:tid 140612726286080] [remote 128.211.233.228:6124]     return self.dispatch_request(*args, **kwargs)
[Wed Dec 07 04:15:44.019446 2016] [wsgi:error] [pid 12:tid 140612726286080] [remote 128.211.233.228:6124]   File "/usr/local/lib/python2.7/dist-packages/flask_restful/__init__.py", line 587, in dispatch_request
[Wed Dec 07 04:15:44.019528 2016] [wsgi:error] [pid 12:tid 140612726286080] [remote 128.211.233.228:6124]     resp = meth(*args, **kwargs)
[Wed Dec 07 04:15:44.019593 2016] [wsgi:error] [pid 12:tid 140612726286080] [remote 128.211.233.228:6124]   File "/srv/www/app/main.py", line 171, in put
[Wed Dec 07 04:15:44.019676 2016] [wsgi:error] [pid 12:tid 140612726286080] [remote 128.211.233.228:6124]     for idx, val in enumerate(dataOld):
[Wed Dec 07 04:15:44.019795 2016] [wsgi:error] [pid 12:tid 140612726286080] [remote 128.211.233.228:6124] TypeError: 'NoneType' object is not iterable
[Wed Dec 07 04:18:31.558787 2016] [wsgi:error] [pid 12:tid 140612625491712] [remote 128.211.233.228:45305] mod_wsgi (pid=12): Exception occurred processing WSGI script '/srv/www/app/apache/apache.wsgi'.
[Wed Dec 07 04:18:31.559199 2016] [wsgi:error] [pid 12:tid 140612625491712] [remote 128.211.233.228:45305] Traceback (most recent call last):
[Wed Dec 07 04:18:31.559321 2016] [wsgi:error] [pid 12:tid 140612625491712] [remote 128.211.233.228:45305]   File "/usr/local/lib/python2.7/dist-packages/flask/app.py", line 2000, in __call__
[Wed Dec 07 04:18:31.559522 2016] [wsgi:error] [pid 12:tid 140612625491712] [remote 128.211.233.228:45305]     return self.wsgi_app(environ, start_response)
[Wed Dec 07 04:18:31.559601 2016] [wsgi:error] [pid 12:tid 140612625491712] [remote 128.211.233.228:45305]   File "/usr/local/lib/python2.7/dist-packages/flask/app.py", line 1991, in wsgi_app
[Wed Dec 07 04:18:31.559707 2016] [wsgi:error] [pid 12:tid 140612625491712] [remote 128.211.233.228:45305]     response = self.make_response(self.handle_exception(e))
[Wed Dec 07 04:18:31.559782 2016] [wsgi:error] [pid 12:tid 140612625491712] [remote 128.211.233.228:45305]   File "/usr/local/lib/python2.7/dist-packages/flask_restful/__init__.py", line 271, in error_router
[Wed Dec 07 04:18:31.559902 2016] [wsgi:error] [pid 12:tid 140612625491712] [remote 128.211.233.228:45305]     return original_handler(e)
[Wed Dec 07 04:18:31.583056 2016] [wsgi:error] [pid 12:tid 140612625491712] [remote 128.211.233.228:45305]   File "/usr/local/lib/python2.7/dist-packages/flask_cors/extension.py", line 161, in wrapped_function
[Wed Dec 07 04:18:31.584043 2016] [wsgi:error] [pid 12:tid 140612625491712] [remote 128.211.233.228:45305]     return cors_after_request(app.make_response(f(*args, **kwargs)))
[Wed Dec 07 04:18:31.584097 2016] [wsgi:error] [pid 12:tid 140612625491712] [remote 128.211.233.228:45305]   File "/usr/local/lib/python2.7/dist-packages/flask/app.py", line 1567, in handle_exception
[Wed Dec 07 04:18:31.584268 2016] [wsgi:error] [pid 12:tid 140612625491712] [remote 128.211.233.228:45305]     reraise(exc_type, exc_value, tb)
[Wed Dec 07 04:18:31.584298 2016] [wsgi:error] [pid 12:tid 140612625491712] [remote 128.211.233.228:45305]   File "/usr/local/lib/python2.7/dist-packages/flask_restful/__init__.py", line 268, in error_router
[Wed Dec 07 04:18:31.584409 2016] [wsgi:error] [pid 12:tid 140612625491712] [remote 128.211.233.228:45305]     return self.handle_error(e)
[Wed Dec 07 04:18:31.584440 2016] [wsgi:error] [pid 12:tid 140612625491712] [remote 128.211.233.228:45305]   File "/usr/local/lib/python2.7/dist-packages/flask/app.py", line 1988, in wsgi_app
[Wed Dec 07 04:18:31.584485 2016] [wsgi:error] [pid 12:tid 140612625491712] [remote 128.211.233.228:45305]     response = self.full_dispatch_request()
[Wed Dec 07 04:18:31.584521 2016] [wsgi:error] [pid 12:tid 140612625491712] [remote 128.211.233.228:45305]   File "/usr/local/lib/python2.7/dist-packages/flask/app.py", line 1641, in full_dispatch_request
[Wed Dec 07 04:18:31.584563 2016] [wsgi:error] [pid 12:tid 140612625491712] [remote 128.211.233.228:45305]     rv = self.handle_user_exception(e)
[Wed Dec 07 04:18:31.584585 2016] [wsgi:error] [pid 12:tid 140612625491712] [remote 128.211.233.228:45305]   File "/usr/local/lib/python2.7/dist-packages/flask_restful/__init__.py", line 271, in error_router
[Wed Dec 07 04:18:31.584620 2016] [wsgi:error] [pid 12:tid 140612625491712] [remote 128.211.233.228:45305]     return original_handler(e)
[Wed Dec 07 04:18:31.584641 2016] [wsgi:error] [pid 12:tid 140612625491712] [remote 128.211.233.228:45305]   File "/usr/local/lib/python2.7/dist-packages/flask_cors/extension.py", line 161, in wrapped_function
[Wed Dec 07 04:18:31.584677 2016] [wsgi:error] [pid 12:tid 140612625491712] [remote 128.211.233.228:45305]     return cors_after_request(app.make_response(f(*args, **kwargs)))
[Wed Dec 07 04:18:31.584698 2016] [wsgi:error] [pid 12:tid 140612625491712] [remote 128.211.233.228:45305]   File "/usr/local/lib/python2.7/dist-packages/flask/app.py", line 1544, in handle_user_exception
[Wed Dec 07 04:18:31.584733 2016] [wsgi:error] [pid 12:tid 140612625491712] [remote 128.211.233.228:45305]     reraise(exc_type, exc_value, tb)
[Wed Dec 07 04:18:31.584753 2016] [wsgi:error] [pid 12:tid 140612625491712] [remote 128.211.233.228:45305]   File "/usr/local/lib/python2.7/dist-packages/flask_restful/__init__.py", line 268, in error_router
[Wed Dec 07 04:18:31.584788 2016] [wsgi:error] [pid 12:tid 140612625491712] [remote 128.211.233.228:45305]     return self.handle_error(e)
[Wed Dec 07 04:18:31.584808 2016] [wsgi:error] [pid 12:tid 140612625491712] [remote 128.211.233.228:45305]   File "/usr/local/lib/python2.7/dist-packages/flask/app.py", line 1639, in full_dispatch_request
[Wed Dec 07 04:18:31.584842 2016] [wsgi:error] [pid 12:tid 140612625491712] [remote 128.211.233.228:45305]     rv = self.dispatch_request()
[Wed Dec 07 04:18:31.584862 2016] [wsgi:error] [pid 12:tid 140612625491712] [remote 128.211.233.228:45305]   File "/usr/local/lib/python2.7/dist-packages/flask/app.py", line 1625, in dispatch_request
[Wed Dec 07 04:18:31.584936 2016] [wsgi:error] [pid 12:tid 140612625491712] [remote 128.211.233.228:45305]     return self.view_functions[rule.endpoint](**req.view_args)
[Wed Dec 07 04:18:31.584964 2016] [wsgi:error] [pid 12:tid 140612625491712] [remote 128.211.233.228:45305]   File "/usr/local/lib/python2.7/dist-packages/flask_restful/__init__.py", line 477, in wrapper
[Wed Dec 07 04:18:31.585054 2016] [wsgi:error] [pid 12:tid 140612625491712] [remote 128.211.233.228:45305]     resp = resource(*args, **kwargs)
[Wed Dec 07 04:18:31.585114 2016] [wsgi:error] [pid 12:tid 140612625491712] [remote 128.211.233.228:45305]   File "/usr/local/lib/python2.7/dist-packages/flask/views.py", line 84, in view
[Wed Dec 07 04:18:31.585256 2016] [wsgi:error] [pid 12:tid 140612625491712] [remote 128.211.233.228:45305]     return self.dispatch_request(*args, **kwargs)
[Wed Dec 07 04:18:31.585289 2016] [wsgi:error] [pid 12:tid 140612625491712] [remote 128.211.233.228:45305]   File "/usr/local/lib/python2.7/dist-packages/flask_restful/__init__.py", line 587, in dispatch_request
[Wed Dec 07 04:18:31.585362 2016] [wsgi:error] [pid 12:tid 140612625491712] [remote 128.211.233.228:45305]     resp = meth(*args, **kwargs)
[Wed Dec 07 04:18:31.585399 2016] [wsgi:error] [pid 12:tid 140612625491712] [remote 128.211.233.228:45305]   File "/srv/www/app/main.py", line 171, in put
[Wed Dec 07 04:18:31.585630 2016] [wsgi:error] [pid 12:tid 140612625491712] [remote 128.211.233.228:45305]     for idx, val in enumerate(dataOld):
[Wed Dec 07 04:18:31.585923 2016] [wsgi:error] [pid 12:tid 140612625491712] [remote 128.211.233.228:45305] TypeError: 'NoneType' object is not iterable
[Wed Dec 07 04:18:41.928939 2016] [wsgi:error] [pid 12:tid 140612726286080] [remote 128.211.233.228:45561] mod_wsgi (pid=12): Exception occurred processing WSGI script '/srv/www/app/apache/apache.wsgi'.
[Wed Dec 07 04:18:41.929144 2016] [wsgi:error] [pid 12:tid 140612726286080] [remote 128.211.233.228:45561] Traceback (most recent call last):
[Wed Dec 07 04:18:41.929305 2016] [wsgi:error] [pid 12:tid 140612726286080] [remote 128.211.233.228:45561]   File "/usr/local/lib/python2.7/dist-packages/flask/app.py", line 2000, in __call__
[Wed Dec 07 04:18:41.929444 2016] [wsgi:error] [pid 12:tid 140612726286080] [remote 128.211.233.228:45561]     return self.wsgi_app(environ, start_response)
[Wed Dec 07 04:18:41.929587 2016] [wsgi:error] [pid 12:tid 140612726286080] [remote 128.211.233.228:45561]   File "/usr/local/lib/python2.7/dist-packages/flask/app.py", line 1991, in wsgi_app
[Wed Dec 07 04:18:41.929730 2016] [wsgi:error] [pid 12:tid 140612726286080] [remote 128.211.233.228:45561]     response = self.make_response(self.handle_exception(e))
[Wed Dec 07 04:18:41.929807 2016] [wsgi:error] [pid 12:tid 140612726286080] [remote 128.211.233.228:45561]   File "/usr/local/lib/python2.7/dist-packages/flask_restful/__init__.py", line 271, in error_router
[Wed Dec 07 04:18:41.929956 2016] [wsgi:error] [pid 12:tid 140612726286080] [remote 128.211.233.228:45561]     return original_handler(e)
[Wed Dec 07 04:18:41.930033 2016] [wsgi:error] [pid 12:tid 140612726286080] [remote 128.211.233.228:45561]   File "/usr/local/lib/python2.7/dist-packages/flask_cors/extension.py", line 161, in wrapped_function
[Wed Dec 07 04:18:41.930123 2016] [wsgi:error] [pid 12:tid 140612726286080] [remote 128.211.233.228:45561]     return cors_after_request(app.make_response(f(*args, **kwargs)))
[Wed Dec 07 04:18:41.930192 2016] [wsgi:error] [pid 12:tid 140612726286080] [remote 128.211.233.228:45561]   File "/usr/local/lib/python2.7/dist-packages/flask/app.py", line 1567, in handle_exception
[Wed Dec 07 04:18:41.930276 2016] [wsgi:error] [pid 12:tid 140612726286080] [remote 128.211.233.228:45561]     reraise(exc_type, exc_value, tb)
[Wed Dec 07 04:18:41.930342 2016] [wsgi:error] [pid 12:tid 140612726286080] [remote 128.211.233.228:45561]   File "/usr/local/lib/python2.7/dist-packages/flask_restful/__init__.py", line 268, in error_router
[Wed Dec 07 04:18:41.930425 2016] [wsgi:error] [pid 12:tid 140612726286080] [remote 128.211.233.228:45561]     return self.handle_error(e)
[Wed Dec 07 04:18:41.930491 2016] [wsgi:error] [pid 12:tid 140612726286080] [remote 128.211.233.228:45561]   File "/usr/local/lib/python2.7/dist-packages/flask/app.py", line 1988, in wsgi_app
[Wed Dec 07 04:18:41.930573 2016] [wsgi:error] [pid 12:tid 140612726286080] [remote 128.211.233.228:45561]     response = self.full_dispatch_request()
[Wed Dec 07 04:18:41.930639 2016] [wsgi:error] [pid 12:tid 140612726286080] [remote 128.211.233.228:45561]   File "/usr/local/lib/python2.7/dist-packages/flask/app.py", line 1641, in full_dispatch_request
[Wed Dec 07 04:18:41.930723 2016] [wsgi:error] [pid 12:tid 140612726286080] [remote 128.211.233.228:45561]     rv = self.handle_user_exception(e)
[Wed Dec 07 04:18:41.930811 2016] [wsgi:error] [pid 12:tid 140612726286080] [remote 128.211.233.228:45561]   File "/usr/local/lib/python2.7/dist-packages/flask_restful/__init__.py", line 271, in error_router
[Wed Dec 07 04:18:41.930961 2016] [wsgi:error] [pid 12:tid 140612726286080] [remote 128.211.233.228:45561]     return original_handler(e)
[Wed Dec 07 04:18:41.931038 2016] [wsgi:error] [pid 12:tid 140612726286080] [remote 128.211.233.228:45561]   File "/usr/local/lib/python2.7/dist-packages/flask_cors/extension.py", line 161, in wrapped_function
[Wed Dec 07 04:18:41.931135 2016] [wsgi:error] [pid 12:tid 140612726286080] [remote 128.211.233.228:45561]     return cors_after_request(app.make_response(f(*args, **kwargs)))
[Wed Dec 07 04:18:41.931243 2016] [wsgi:error] [pid 12:tid 140612726286080] [remote 128.211.233.228:45561]   File "/usr/local/lib/python2.7/dist-packages/flask/app.py", line 1544, in handle_user_exception
[Wed Dec 07 04:18:41.931340 2016] [wsgi:error] [pid 12:tid 140612726286080] [remote 128.211.233.228:45561]     reraise(exc_type, exc_value, tb)
[Wed Dec 07 04:18:41.931417 2016] [wsgi:error] [pid 12:tid 140612726286080] [remote 128.211.233.228:45561]   File "/usr/local/lib/python2.7/dist-packages/flask_restful/__init__.py", line 268, in error_router
[Wed Dec 07 04:18:41.931502 2016] [wsgi:error] [pid 12:tid 140612726286080] [remote 128.211.233.228:45561]     return self.handle_error(e)
[Wed Dec 07 04:18:41.931568 2016] [wsgi:error] [pid 12:tid 140612726286080] [remote 128.211.233.228:45561]   File "/usr/local/lib/python2.7/dist-packages/flask/app.py", line 1639, in full_dispatch_request
[Wed Dec 07 04:18:41.931650 2016] [wsgi:error] [pid 12:tid 140612726286080] [remote 128.211.233.228:45561]     rv = self.dispatch_request()
[Wed Dec 07 04:18:41.931715 2016] [wsgi:error] [pid 12:tid 140612726286080] [remote 128.211.233.228:45561]   File "/usr/local/lib/python2.7/dist-packages/flask/app.py", line 1625, in dispatch_request
[Wed Dec 07 04:18:41.931796 2016] [wsgi:error] [pid 12:tid 140612726286080] [remote 128.211.233.228:45561]     return self.view_functions[rule.endpoint](**req.view_args)
[Wed Dec 07 04:18:41.931879 2016] [wsgi:error] [pid 12:tid 140612726286080] [remote 128.211.233.228:45561]   File "/usr/local/lib/python2.7/dist-packages/flask_restful/__init__.py", line 477, in wrapper
[Wed Dec 07 04:18:41.931965 2016] [wsgi:error] [pid 12:tid 140612726286080] [remote 128.211.233.228:45561]     resp = resource(*args, **kwargs)
[Wed Dec 07 04:18:41.932034 2016] [wsgi:error] [pid 12:tid 140612726286080] [remote 128.211.233.228:45561]   File "/usr/local/lib/python2.7/dist-packages/flask/views.py", line 84, in view
[Wed Dec 07 04:18:41.932119 2016] [wsgi:error] [pid 12:tid 140612726286080] [remote 128.211.233.228:45561]     return self.dispatch_request(*args, **kwargs)
[Wed Dec 07 04:18:41.932185 2016] [wsgi:error] [pid 12:tid 140612726286080] [remote 128.211.233.228:45561]   File "/usr/local/lib/python2.7/dist-packages/flask_restful/__init__.py", line 587, in dispatch_request
[Wed Dec 07 04:18:41.932269 2016] [wsgi:error] [pid 12:tid 140612726286080] [remote 128.211.233.228:45561]     resp = meth(*args, **kwargs)
[Wed Dec 07 04:18:41.932335 2016] [wsgi:error] [pid 12:tid 140612726286080] [remote 128.211.233.228:45561]   File "/srv/www/app/main.py", line 171, in put
[Wed Dec 07 04:18:41.932421 2016] [wsgi:error] [pid 12:tid 140612726286080] [remote 128.211.233.228:45561]     for idx, val in enumerate(dataOld):
[Wed Dec 07 04:18:41.932505 2016] [wsgi:error] [pid 12:tid 140612726286080] [remote 128.211.233.228:45561] TypeError: 'NoneType' object is not iterable
[Wed Dec 07 04:23:32.415924 2016] [wsgi:error] [pid 12:tid 140612625491712] [remote 128.211.233.228:45561] mod_wsgi (pid=12): Exception occurred processing WSGI script '/srv/www/app/apache/apache.wsgi'.
[Wed Dec 07 04:23:32.416294 2016] [wsgi:error] [pid 12:tid 140612625491712] [remote 128.211.233.228:45561] Traceback (most recent call last):
[Wed Dec 07 04:23:32.416433 2016] [wsgi:error] [pid 12:tid 140612625491712] [remote 128.211.233.228:45561]   File "/usr/local/lib/python2.7/dist-packages/flask/app.py", line 2000, in __call__
[Wed Dec 07 04:23:32.416683 2016] [wsgi:error] [pid 12:tid 140612625491712] [remote 128.211.233.228:45561]     return self.wsgi_app(environ, start_response)
[Wed Dec 07 04:23:32.416764 2016] [wsgi:error] [pid 12:tid 140612625491712] [remote 128.211.233.228:45561]   File "/usr/local/lib/python2.7/dist-packages/flask/app.py", line 1991, in wsgi_app
[Wed Dec 07 04:23:32.416871 2016] [wsgi:error] [pid 12:tid 140612625491712] [remote 128.211.233.228:45561]     response = self.make_response(self.handle_exception(e))
[Wed Dec 07 04:23:32.416947 2016] [wsgi:error] [pid 12:tid 140612625491712] [remote 128.211.233.228:45561]   File "/usr/local/lib/python2.7/dist-packages/flask_restful/__init__.py", line 271, in error_router
[Wed Dec 07 04:23:32.417066 2016] [wsgi:error] [pid 12:tid 140612625491712] [remote 128.211.233.228:45561]     return original_handler(e)
[Wed Dec 07 04:23:32.417139 2016] [wsgi:error] [pid 12:tid 140612625491712] [remote 128.211.233.228:45561]   File "/usr/local/lib/python2.7/dist-packages/flask_cors/extension.py", line 161, in wrapped_function
[Wed Dec 07 04:23:32.417255 2016] [wsgi:error] [pid 12:tid 140612625491712] [remote 128.211.233.228:45561]     return cors_after_request(app.make_response(f(*args, **kwargs)))
[Wed Dec 07 04:23:32.417327 2016] [wsgi:error] [pid 12:tid 140612625491712] [remote 128.211.233.228:45561]   File "/usr/local/lib/python2.7/dist-packages/flask/app.py", line 1567, in handle_exception
[Wed Dec 07 04:23:32.417431 2016] [wsgi:error] [pid 12:tid 140612625491712] [remote 128.211.233.228:45561]     reraise(exc_type, exc_value, tb)
[Wed Dec 07 04:23:32.417503 2016] [wsgi:error] [pid 12:tid 140612625491712] [remote 128.211.233.228:45561]   File "/usr/local/lib/python2.7/dist-packages/flask_restful/__init__.py", line 268, in error_router
[Wed Dec 07 04:23:32.417622 2016] [wsgi:error] [pid 12:tid 140612625491712] [remote 128.211.233.228:45561]     return self.handle_error(e)
[Wed Dec 07 04:23:32.417718 2016] [wsgi:error] [pid 12:tid 140612625491712] [remote 128.211.233.228:45561]   File "/usr/local/lib/python2.7/dist-packages/flask/app.py", line 1988, in wsgi_app
[Wed Dec 07 04:23:32.417808 2016] [wsgi:error] [pid 12:tid 140612625491712] [remote 128.211.233.228:45561]     response = self.full_dispatch_request()
[Wed Dec 07 04:23:32.417877 2016] [wsgi:error] [pid 12:tid 140612625491712] [remote 128.211.233.228:45561]   File "/usr/local/lib/python2.7/dist-packages/flask/app.py", line 1641, in full_dispatch_request
[Wed Dec 07 04:23:32.417962 2016] [wsgi:error] [pid 12:tid 140612625491712] [remote 128.211.233.228:45561]     rv = self.handle_user_exception(e)
[Wed Dec 07 04:23:32.418028 2016] [wsgi:error] [pid 12:tid 140612625491712] [remote 128.211.233.228:45561]   File "/usr/local/lib/python2.7/dist-packages/flask_restful/__init__.py", line 271, in error_router
[Wed Dec 07 04:23:32.418111 2016] [wsgi:error] [pid 12:tid 140612625491712] [remote 128.211.233.228:45561]     return original_handler(e)
[Wed Dec 07 04:23:32.418176 2016] [wsgi:error] [pid 12:tid 140612625491712] [remote 128.211.233.228:45561]   File "/usr/local/lib/python2.7/dist-packages/flask_cors/extension.py", line 161, in wrapped_function
[Wed Dec 07 04:23:32.418296 2016] [wsgi:error] [pid 12:tid 140612625491712] [remote 128.211.233.228:45561]     return cors_after_request(app.make_response(f(*args, **kwargs)))
[Wed Dec 07 04:23:32.418370 2016] [wsgi:error] [pid 12:tid 140612625491712] [remote 128.211.233.228:45561]   File "/usr/local/lib/python2.7/dist-packages/flask/app.py", line 1544, in handle_user_exception
[Wed Dec 07 04:23:32.418454 2016] [wsgi:error] [pid 12:tid 140612625491712] [remote 128.211.233.228:45561]     reraise(exc_type, exc_value, tb)
[Wed Dec 07 04:23:32.418519 2016] [wsgi:error] [pid 12:tid 140612625491712] [remote 128.211.233.228:45561]   File "/usr/local/lib/python2.7/dist-packages/flask_restful/__init__.py", line 268, in error_router
[Wed Dec 07 04:23:32.418601 2016] [wsgi:error] [pid 12:tid 140612625491712] [remote 128.211.233.228:45561]     return self.handle_error(e)
[Wed Dec 07 04:23:32.418667 2016] [wsgi:error] [pid 12:tid 140612625491712] [remote 128.211.233.228:45561]   File "/usr/local/lib/python2.7/dist-packages/flask/app.py", line 1639, in full_dispatch_request
[Wed Dec 07 04:23:32.418751 2016] [wsgi:error] [pid 12:tid 140612625491712] [remote 128.211.233.228:45561]     rv = self.dispatch_request()
[Wed Dec 07 04:23:32.418816 2016] [wsgi:error] [pid 12:tid 140612625491712] [remote 128.211.233.228:45561]   File "/usr/local/lib/python2.7/dist-packages/flask/app.py", line 1625, in dispatch_request
[Wed Dec 07 04:23:32.418979 2016] [wsgi:error] [pid 12:tid 140612625491712] [remote 128.211.233.228:45561]     return self.view_functions[rule.endpoint](**req.view_args)
[Wed Dec 07 04:23:32.419059 2016] [wsgi:error] [pid 12:tid 140612625491712] [remote 128.211.233.228:45561]   File "/usr/local/lib/python2.7/dist-packages/flask_restful/__init__.py", line 477, in wrapper
[Wed Dec 07 04:23:32.419146 2016] [wsgi:error] [pid 12:tid 140612625491712] [remote 128.211.233.228:45561]     resp = resource(*args, **kwargs)
[Wed Dec 07 04:23:32.419212 2016] [wsgi:error] [pid 12:tid 140612625491712] [remote 128.211.233.228:45561]   File "/usr/local/lib/python2.7/dist-packages/flask/views.py", line 84, in view
[Wed Dec 07 04:23:32.419321 2016] [wsgi:error] [pid 12:tid 140612625491712] [remote 128.211.233.228:45561]     return self.dispatch_request(*args, **kwargs)
[Wed Dec 07 04:23:32.419392 2016] [wsgi:error] [pid 12:tid 140612625491712] [remote 128.211.233.228:45561]   File "/usr/local/lib/python2.7/dist-packages/flask_restful/__init__.py", line 587, in dispatch_request
[Wed Dec 07 04:23:32.419493 2016] [wsgi:error] [pid 12:tid 140612625491712] [remote 128.211.233.228:45561]     resp = meth(*args, **kwargs)
[Wed Dec 07 04:23:32.419565 2016] [wsgi:error] [pid 12:tid 140612625491712] [remote 128.211.233.228:45561]   File "/srv/www/app/main.py", line 171, in put
[Wed Dec 07 04:23:32.419667 2016] [wsgi:error] [pid 12:tid 140612625491712] [remote 128.211.233.228:45561]     for idx, val in enumerate(dataOld):
[Wed Dec 07 04:23:32.419833 2016] [wsgi:error] [pid 12:tid 140612625491712] [remote 128.211.233.228:45561] TypeError: 'NoneType' object is not iterable
